Workbook

Sheet Base extract
A1: Designation_Complémentaire | B1: Remise | C1: Total_Ligne_HT_Remisé | D1: V_Total_Ligne_TTC | E1: TVA | F1: N__DA | G1: N__Poste_DA | H1: Site_Stock | I1: Code_ss_famille | J1: Saisie_de_réception__ | K1: Code_Direction | L1: Code_complément | M1: SS_compte_anal | N1: Centre_d_Analyse | O1: Accord_Cadre | P1: RAL | Q1: V_Montant_RAL | R1: Code_Société | S1: Avenant | T1: Acheteur | U1: Tot_CA_HT | V1: Tot_CA_TTC | W1: Devise | X1: Etat_Financ_ | Y1: Date_creat | Z1: Date_de_Validation | AA1: Date_Période | AB1: Date_AR | AC1: Objet_CA | AD1: Ctr_Emetteur_entete | AE1: Ctr_Livraison_entete | AF1: Sect_Imputation_entete | AG1: Code_Complémentaire_entete | AH1: Sous_Compte_d_Analyse_entete | AI1: Type_document | AJ1: V_Expédition_soldée | AK1: Code_du_Modèle_de_Cde | AL1: V_Etat_commande_en_tête | AM1: V_Etat_commande_ligne | AN1: Nom_Acheteur | AO1: Raison_sociale_Fournisseur | AP1: Nom_demandeur | AQ1: V_Critère_de_saisie | AR1: Code_Article | AS1: Quantité_comm | AT1: Unité | AU1: Prix_Unitaire | AV1: Design__sommaire | AW1: Section_d_imput | AX1: Code_Fournis | AY1: N__de_Cde | AZ1: N_Poste | BA1: Date_de_livr__prev_
A2: SPOT - RECORD TV - suivant Facture N°TV000000282 | B2: 0 | C2: 549120 | D2: 658 944.00 | E2: 20 | F2: 139303 | G2: 1 | I2: MEDMEDI | J2: True | K2: DCG | L2: E110_MD_DCOM | M2: DCG-COM-MEDIA | N2: NA | P2: 1 | Q2: 549 120.00 | R2: YASMG | T2: FELANA13 | U2: 3 926 784.00 | V2: 4 712 140.80 | W2: MGA | X2: F | Y2: 46237 | Z2: 2026-08-03 | AA2: 46237 | AB2: 0000-00-00 | AC2: SPOT - RECORD TV | AD2: YASSIE | AE2: YASSIE | AF2: C100 | AG2: E110_MD_DCOM | AH2: DCG-COM-MEDIA | AI2: STD | AL2: E | AM2: E | AN2: Felana RARIVOSON | AO2: RTV RECORD | AP2: RAZAFINDRAHAGA Setra | AR2: 1265 | AS2: 1 | AT2: UN | AU2: 549120 | AV2: PUBLICITE ET ANNONCE | AW2: C100 | AX2: 973 | AY2: 136058 | AZ2: 1 | BA2: 2026-07-29
A3: SPOT - RECORD TV - suivant Facture N°RD000000250 | B3: 0 | C3: 403200 | D3: 483 840.00 | E3: 20 | F3: 139303 | G3: 2 | I3: MEDMEDI | J3: True | K3: DCG | L3: E110_MD_DCOM | M3: DCG-COM-MEDIA | N3: NA | P3: 1 | Q3: 403 200.00 | R3: YASMG | T3: FELANA13 | U3: 3 926 784.00 | V3: 4 712 140.80 | W3: MGA | X3: F | Y3: 46237 | Z3: 2026-08-03 | AA3: 46237 | AB3: 0000-00-00 | AC3: SPOT - RECORD TV | AD3: YASSIE | AE3: YASSIE | AF3: C100 | AG3: E110_MD_DCOM | AH3: DCG-COM-MEDIA | AI3: STD | AL3: E | AM3: E | AN3: Felana RARIVOSON | AO3: RTV RECORD | AP3: RAZAFINDRAHAGA Setra | AR3: 1265 | AS3: 1 | AT3: UN | AU3: 403200 | AV3: PUBLICITE ET ANNONCE | AW3: C100 | AX3: 973 | AY3: 136058 | AZ3: 2 | BA3: 2026-07-29
A4: SPOT - RECORD TV - suivant Facture N°RD000000270 | B4: 0 | C4: 82944 | D4: 99 532.80 | E4: 20 | F4: 139303 | G4: 3 | I4: MEDMEDI | J4: True | K4: DCG | L4: E110_MD_DCOM | M4: DCG-COM-MEDIA | N4: NA | P4: 1 | Q4: 82 944.00 | R4: YASMG | T4: FELANA13 | U4: 3 926 784.00 | V4: 4 712 140.80 | W4: MGA | X4: F | Y4: 46237 | Z4: 2026-08-03 | AA4: 46237 | AB4: 0000-00-00 | AC4: SPOT - RECORD TV | AD4: YASSIE | AE4: YASSIE | AF4: C100 | AG4: E110_MD_DCOM | AH4: DCG-COM-MEDIA | AI4: STD | AL4: E | AM4: E | AN4: Felana RARIVOSON | AO4: RTV RECORD | AP4: RAZAFINDRAHAGA Setra | AR4: 1265 | AS4: 1 | AT4: UN | AU4: 82944 | AV4: PUBLICITE ET ANNONCE | AW4: C100 | AX4: 973 | AY4: 136058 | AZ4: 3 | BA4: 2026-07-29
A5: SPOT - RECORD TV - suivant Facture N°RD000000280 | B5: 0 | C5: 403200 | D5: 483 840.00 | E5: 20 | F5: 139303 | G5: 4 | I5: MEDMEDI | J5: True | K5: DCG | L5: E110_MD_DCOM | M5: DCG-COM-MEDIA | N5: NA | P5: 1 | Q5: 403 200.00 | R5: YASMG | T5: FELANA13 | U5: 3 926 784.00 | V5: 4 712 140.80 | W5: MGA | X5: F | Y5: 46237 | Z5: 2026-08-03 | AA5: 46237 | AB5: 0000-00-00 | AC5: SPOT - RECORD TV | AD5: YASSIE | AE5: YASSIE | AF5: C100 | AG5: E110_MD_DCOM | AH5: DCG-COM-MEDIA | AI5: STD | AL5: E | AM5: E | AN5: Felana RARIVOSON | AO5: RTV RECORD | AP5: RAZAFINDRAHAGA Setra | AR5: 1265 | AS5: 1 | AT5: UN | AU5: 403200 | AV5: PUBLICITE ET ANNONCE | AW5: C100 | AX5: 973 | AY5: 136058 | AZ5: 4 | BA5: 2026-07-29
A6: SPOT - RECORD TV - suivant Facture N°RD000000296 | B6: 0 | C6: 829440 | D6: 995 328.00 | E6: 20 | F6: 139303 | G6: 5 | I6: MEDMEDI | J6: True | K6: DCG | L6: E110_MD_DCOM | M6: DCG-COM-MEDIA | N6: NA | P6: 1 | Q6: 829 440.00 | R6: YASMG | T6: FELANA13 | U6: 3 926 784.00 | V6: 4 712 140.80 | W6: MGA | X6: F | Y6: 46237 | Z6: 2026-08-03 | AA6: 46237 | AB6: 0000-00-00 | AC6: SPOT - RECORD TV | AD6: YASSIE | AE6: YASSIE | AF6: C100 | AG6: E110_MD_DCOM | AH6: DCG-COM-MEDIA | AI6: STD | AL6: E | AM6: E | AN6: Felana RARIVOSON | AO6: RTV RECORD | AP6: RAZAFINDRAHAGA Setra | AR6: 1265 | AS6: 1 | AT6: UN | AU6: 829440 | AV6: PUBLICITE ET ANNONCE | AW6: C100 | AX6: 973 | AY6: 136058 | AZ6: 5 | BA6: 2026-07-29
A7: SPOT - RECORD TV - suivant Facture N°RD000000297 | B7: 0 | C7: 829440 | D7: 995 328.00 | E7: 20 | F7: 139303 | G7: 6 | I7: MEDMEDI | J7: True | K7: DCG | L7: E110_MD_DCOM | M7: DCG-COM-MEDIA | N7: NA | P7: 1 | Q7: 829 440.00 | R7: YASMG | T7: FELANA13 | U7: 3 926 784.00 | V7: 4 712 140.80 | W7: MGA | X7: F | Y7: 46237 | Z7: 2026-08-03 | AA7: 46237 | AB7: 0000-00-00 | AC7: SPOT - RECORD TV | AD7: YASSIE | AE7: YASSIE | AF7: C100 | AG7: E110_MD_DCOM | AH7: DCG-COM-MEDIA | AI7: STD | AL7: E | AM7: E | AN7: Felana RARIVOSON | AO7: RTV RECORD | AP7: RAZAFINDRAHAGA Setra | AR7: 1265 | AS7: 1 | AT7: UN | AU7: 829440 | AV7: PUBLICITE ET ANNONCE | AW7: C100 | AX7: 973 | AY7: 136058 | AZ7: 6 | BA7: 2026-07-29
A8: SPOT - RECORD TV - suivant Facture N°RD000000288 | B8: 0 | C8: 829440 | D8: 995 328.00 | E8: 20 | F8: 139303 | G8: 7 | I8: MEDMEDI | J8: True | K8: DCG | L8: E110_MD_DCOM | M8: DCG-COM-MEDIA | N8: NA | P8: 1 | Q8: 829 440.00 | R8: YASMG | T8: FELANA13 | U8: 3 926 784.00 | V8: 4 712 140.80 | W8: MGA | X8: F | Y8: 46237 | Z8: 2026-08-03 | AA8: 46237 | AB8: 0000-00-00 | AC8: SPOT - RECORD TV | AD8: YASSIE | AE8: YASSIE | AF8: C100 | AG8: E110_MD_DCOM | AH8: DCG-COM-MEDIA | AI8: STD | AL8: E | AM8: E | AN8: Felana RARIVOSON | AO8: RTV RECORD | AP8: RAZAFINDRAHAGA Setra | AR8: 1265 | AS8: 1 | AT8: UN | AU8: 829440 | AV8: PUBLICITE ET ANNONCE | AW8: C100 | AX8: 973 | AY8: 136058 | AZ8: 7 | BA8: 2026-07-29
A9: Stickers Home Plus - 7,5 x 6 cm - suivant proforma N° FP05186 | B9: 0 | C9: 5124000 | D9: 6 148 800.00 | E9: 20 | F9: 139299 | G9: 1 | I9: GELACCS | J9: True | K9: DCG | L9: E110_TR_MBLK | M9: DCG-SHS | N9: NA | P9: 30500 | Q9: 5 124 000.00 | R9: YASMG | T9: FELANA13 | U9: 39 000 000.00 | V9: 46 800 000.00 | W9: MGA | Y9: 46237 | Z9: 2026-08-03 | AA9: 46237 | AB9: 0000-00-00 | AC9: STICKERS MBALIK | AD9: YASSIE | AE9: GALE | AF9: C100 | AG9: E110_TR_MBLK | AH9: DCG-SHS | AI9: STD | AL9: E | AM9: E | AN9: Felana RARIVOSON | AO9: SIGN | AP9: RAZAFINDRAHAGA Setra | AR9: 24694 | AS9: 30500 | AT9: UN | AU9: 168 | AV9: STICKERS AUTOCOLLANT - MBALIK - JUILLET 2025 | AW9: C100 | AX9: 1089 | AY9: 136059 | AZ9: 1 | BA9: 2026-07-29
A10: Stickers Home Plus - 13x19 cm (sticker facing) - suivant proforma N° FP05186 | B10: 0 | C10: 19764000 | D10: 23 716 800.00 | E10: 20 | F10: 139299 | G10: 2 | I10: GELACCS | J10: True | K10: DCG | L10: E110_TR_MBLK | M10: DCG-SHS | N10: NA | P10: 30500 | Q10: 19 764 000.00 | R10: YASMG | T10: FELANA13 | U10: 39 000 000.00 | V10: 46 800 000.00 | W10: MGA | Y10: 46237 | Z10: 2026-08-03 | AA10: 46237 | AB10: 0000-00-00 | AC10: STICKERS MBALIK | AD10: YASSIE | AE10: GALE | AF10: C100 | AG10: E110_TR_MBLK | AH10: DCG-SHS | AI10: STD | AL10: E | AM10: E | AN10: Felana RARIVOSON | AO10: SIGN | AP10: RAZAFINDRAHAGA Setra | AR10: 24694 | AS10: 30500 | AT10: UN | AU10: 648 | AV10: STICKERS AUTOCOLLANT - MBALIK - JUILLET 2025 | AW10: C100 | AX10: 1089 | AY10: 136059 | AZ10: 2 | BA10: 2026-07-29
A11: Stickers Home Plus - 2,8x2,8 cm (sticker rond) - suivant proforma N° FP05186 | B11: 0 | C11: 1098000 | D11: 1 317 600.00 | E11: 20 | F11: 139299 | G11: 3 | I11: GELACCS | J11: True | K11: DCG | L11: E110_TR_MBLK | M11: DCG-SHS | N11: NA | P11: 30500 | Q11: 1 098 000.00 | R11: YASMG | T11: FELANA13 | U11: 39 000 000.00 | V11: 46 800 000.00 | W11: MGA | Y11: 46237 | Z11: 2026-08-03 | AA11: 46237 | AB11: 0000-00-00 | AC11: STICKERS MBALIK | AD11: YASSIE | AE11: GALE | AF11: C100 | AG11: E110_TR_MBLK | AH11: DCG-SHS | AI11: STD | AL11: E | AM11: E | AN11: Felana RARIVOSON | AO11: SIGN | AP11: RAZAFINDRAHAGA Setra | AR11: 24694 | AS11: 30500 | AT11: UN | AU11: 36 | AV11: STICKERS AUTOCOLLANT - MBALIK - JUILLET 2025 | AW11: C100 | AX11: 1089 | AY11: 136059 | AZ11: 3 | BA11: 2026-07-29
A12: Stickers Home Plus - 3,5x2 cm (sticker pour cacher logo Sunking sur l'image du boîtier du facing) - suivant proforma N° FP05186 | B12: 0 | C12: 854000 | D12: 1 024 800.00 | E12: 20 | F12: 139299 | G12: 4 | I12: GELACCS | J12: True | K12: DCG | L12: E110_TR_MBLK | M12: DCG-SHS | N12: NA | P12: 30500 | Q12: 854 000.00 | R12: YASMG | T12: FELANA13 | U12: 39 000 000.00 | V12: 46 800 000.00 | W12: MGA | Y12: 46237 | Z12: 2026-08-03 | AA12: 46237 | AB12: 0000-00-00 | AC12: STICKERS MBALIK | AD12: YASSIE | AE12: GALE | AF12: C100 | AG12: E110_TR_MBLK | AH12: DCG-SHS | AI12: STD | AL12: E | AM12: E | AN12: Felana RARIVOSON | AO12: SIGN | AP12: RAZAFINDRAHAGA Setra | AR12: 24694 | AS12: 30500 | AT12: UN | AU12: 28 | AV12: STICKERS AUTOCOLLANT - MBALIK - JUILLET 2025 | AW12: C100 | AX12: 1089 | AY12: 136059 | AZ12: 4 | BA12: 2026-07-29
A13: Stickers Home Plus - 7x2 cm (sticker dos) - suivant proforma N° FP05186 | B13: 0 | C13: 1488400 | D13: 1 786 080.00 | E13: 20 | F13: 139299 | G13: 5 | I13: GELACCS | J13: True | K13: DCG | L13: E110_TR_MBLK | M13: DCG-SHS | N13: NA | P13: 30500 | Q13: 1 488 400.00 | R13: YASMG | T13: FELANA13 | U13: 39 000 000.00 | V13: 46 800 000.00 | W13: MGA | Y13: 46237 | Z13: 2026-08-03 | AA13: 46237 | AB13: 0000-00-00 | AC13: STICKERS MBALIK | AD13: YASSIE | AE13: GALE | AF13: C100 | AG13: E110_TR_MBLK | AH13: DCG-SHS | AI13: STD | AL13: E | AM13: E | AN13: Felana RARIVOSON | AO13: SIGN | AP13: RAZAFINDRAHAGA Setra | AR13: 24694 | AS13: 30500 | AT13: UN | AU13: 48.8 | AV13: STICKERS AUTOCOLLANT - MBALIK - JUILLET 2025 | AW13: C100 | AX13: 1089 | AY13: 136059 | AZ13: 5 | BA13: 2026-07-29
A14: Stickers Home Plus - 11x5,3 cm sticker côté jaune - suivant proforma N° FP05186 | B14: 0 | C14: 9333000 | D14: 11 199 600.00 | E14: 20 | F14: 139299 | G14: 6 | I14: GELACCS | J14: True | K14: DCG | L14: E110_TR_MBLK | M14: DCG-SHS | N14: NA | P14: 61000 | Q14: 9 333 000.00 | R14: YASMG | T14: FELANA13 | U14: 39 000 000.00 | V14: 46 800 000.00 | W14: MGA | Y14: 46237 | Z14: 2026-08-03 | AA14: 46237 | AB14: 0000-00-00 | AC14: STICKERS MBALIK | AD14: YASSIE | AE14: GALE | AF14: C100 | AG14: E110_TR_MBLK | AH14: DCG-SHS | AI14: STD | AL14: E | AM14: E | AN14: Felana RARIVOSON | AO14: SIGN | AP14: RAZAFINDRAHAGA Setra | AR14: 24694 | AS14: 61000 | AT14: UN | AU14: 153 | AV14: STICKERS AUTOCOLLANT - MBALIK - JUILLET 2025 | AW14: C100 | AX14: 1089 | AY14: 136059 | AZ14: 6 | BA14: 2026-07-29
A15: POSE A ANDRAHARO | B15: 0 | C15: 1338600 | D15: 1 606 320.00 | E15: 20 | F15: 139299 | G15: 7 | I15: ELEMCEL | J15: True | K15: DCG | L15: E110_TR_MBLK | M15: DCG-SHS | N15: NA | P15: 1 | Q15: 1 338 600.00 | R15: YASMG | T15: FELANA13 | U15: 39 000 000.00 | V15: 46 800 000.00 | W15: MGA | Y15: 46237 | Z15: 2026-08-03 | AA15: 46237 | AB15: 0000-00-00 | AC15: STICKERS MBALIK | AD15: YASSIE | AE15: GALE | AF15: C100 | AG15: E110_TR_MBLK | AH15: DCG-SHS | AI15: STD | AL15: E | AM15: E | AN15: Felana RARIVOSON | AO15: SIGN | AP15: RAZAFINDRAHAGA Setra | AR15: 2061 | AS15: 1 | AT15: UN | AU15: 1338600 | AV15: FRAIS DE POSE | AW15: C100 | AX15: 1089 | AY15: 136059 | AZ15: 7 | BA15: 2026-07-29
A16: TRAVAUX DE COULLAGE DALLE EN BETON YAS STORE AMBOHIPO - suivant Devis N° 206/2026 INDICE 0 | B16: 0 | C16: 782000 | D16: 782 000.00 | E16: 0 | F16: 139284 | G16: 1 | I16: INFPYLX | J16: True | K16: DCG | L16: E250_DRB | M16: DCG-DRB | N16: NA | P16: 1 | Q16: 782 000.00 | R16: YASMG | T16: FELANA13 | U16: 782 000.00 | V16: 782 000.00 | W16: MGA | X16: F | Y16: 46237 | Z16: 2026-08-03 | AA16: 46237 | AB16: 0000-00-00 | AC16: YS AMBOHIPO | AD16: YASSIE | AE16: YASSIE | AF16: C102 | AG16: E250_DRB | AH16: DCG-DRB | AI16: STD | AL16: E | AM16: E | AN16: Felana RARIVOSON | AO16: AVRA BTP | AP16: RAZAFINDRAHAGA Setra | AR16: 1526 | AS16: 1 | AT16: UN | AU16: 782000 | AV16: TRAVAUX SUPPLEMENTAIRES | AW16: C102 | AX16: 4038 | AY16: 136060 | AZ16: 1 | BA16: 2026-07-28
A17: TRAVAUX DE POSE CARREAUX MURAUX - suivant devis N° 205/2026 INDICE 0 | B17: 0 | C17: 824000 | D17: 824 000.00 | E17: 0 | F17: 139283 | G17: 1 | I17: INFPYLX | J17: True | K17: DCG | L17: E250_DRB | M17: DCG-DRB | N17: NA | P17: 1 | Q17: 824 000.00 | R17: YASMG | T17: FELANA13 | U17: 824 000.00 | V17: 824 000.00 | W17: MGA | Y17: 46237 | Z17: 2026-08-03 | AA17: 46237 | AB17: 0000-00-00 | AC17: YS ITAOSY | AD17: YASSIE | AE17: YASSIE | AF17: C102 | AG17: E250_DRB | AH17: DCG-DRB | AI17: STD | AL17: E | AM17: E | AN17: Felana RARIVOSON | AO17: AVRA BTP | AP17: RAZAFINDRAHAGA Setra | AR17: 1526 | AS17: 1 | AT17: UN | AU17: 824000 | AV17: TRAVAUX SUPPLEMENTAIRES | AW17: C102 | AX17: 4038 | AY17: 136061 | AZ17: 1 | BA17: 2026-07-28
A18: REMBOURSEMENT FRAIS BAC CDZ S14 - PROFORMA N°192-A/FP/TELMA/2026 | B18: 0 | C18: 1480000 | D18: 1 480 000.00 | E18: 0 | F18: 139333 | G18: 1 | I18: PRICTRL | J18: False | K18: DCG | L18: E214_DCG | M18: DCG-DVIR | N18: NA | P18: 0 | Q18: 0.00 | R18: YASMG | T18: FELANA13 | U18: 11 417 000.00 | V18: 11 417 000.00 | W18: MGA | X18: F | Y18: 46237 | Z18: 2026-08-03 | AA18: 46237 | AB18: 0000-00-00 | AC18: REMBOURSEMENT FRAIS BAC CDZ | AD18: YASSIE | AE18: YASSIE | AF18: C104 | AG18: E214_DCG | AH18: DCG-DVIR | AI18: STD | AL18: S | AM18: S | AN18: Felana RARIVOSON | AO18: LCS CONSULTING | AP18: RAZAFINDRAHAGA Setra | AR18: 11533 | AS18: 1 | AT18: PIE | AU18: 1480000 | AV18: PRESTATION DIVERS | AW18: C104 | AX18: 2490 | AY18: 136062 | AZ18: 1 | BA18: 2026-07-30
A19: REMBOURSEMENT FRAIS BAC CDZ S15 - PROFORMA N°194-A/FP/TELMA/2026 | B19: 0 | C19: 1483000 | D19: 1 483 000.00 | E19: 0 | F19: 139333 | G19: 2 | I19: PRICTRL | J19: False | K19: DCG | L19: E214_DCG | M19: DCG-DVIR | N19: NA | P19: 0 | Q19: 0.00 | R19: YASMG | T19: FELANA13 | U19: 11 417 000.00 | V19: 11 417 000.00 | W19: MGA | X19: F | Y19: 46237 | Z19: 2026-08-03 | AA19: 46237 | AB19: 0000-00-00 | AC19: REMBOURSEMENT FRAIS BAC CDZ | AD19: YASSIE | AE19: YASSIE | AF19: C104 | AG19: E214_DCG | AH19: DCG-DVIR | AI19: STD | AL19: S | AM19: S | AN19: Felana RARIVOSON | AO19: LCS CONSULTING | AP19: RAZAFINDRAHAGA Setra | AR19: 11533 | AS19: 1 | AT19: PIE | AU19: 1483000 | AV19: PRESTATION DIVERS | AW19: C104 | AX19: 2490 | AY19: 136062 | AZ19: 2 | BA19: 2026-07-30
A20: REMBOURSEMENT FRAIS BAC CDZ S16 - PROFORMA N°212-A/FP/TELMA/2026 | B20: 0 | C20: 1717000 | D20: 1 717 000.00 | E20: 0 | F20: 139333 | G20: 3 | I20: PRICTRL | J20: False | K20: DCG | L20: E214_DCG | M20: DCG-DVIR | N20: NA | P20: 0 | Q20: 0.00 | R20: YASMG | T20: FELANA13 | U20: 11 417 000.00 | V20: 11 417 000.00 | W20: MGA | X20: F | Y20: 46237 | Z20: 2026-08-03 | AA20: 46237 | AB20: 0000-00-00 | AC20: REMBOURSEMENT FRAIS BAC CDZ | AD20: YASSIE | AE20: YASSIE | AF20: C104 | AG20: E214_DCG | AH20: DCG-DVIR | AI20: STD | AL20: S | AM20: S | AN20: Felana RARIVOSON | AO20: LCS CONSULTING | AP20: RAZAFINDRAHAGA Setra | AR20: 11533 | AS20: 1 | AT20: PIE | AU20: 1717000 | AV20: PRESTATION DIVERS | AW20: C104 | AX20: 2490 | AY20: 136062 | AZ20: 3 | BA20: 2026-07-30
A21: REMBOURSEMENT FRAIS BAC CDZ S17 - PROFORMA N°214-A/FP/TELMA/2026 | B21: 0 | C21: 1593000 | D21: 1 593 000.00 | E21: 0 | F21: 139333 | G21: 4 | I21: PRICTRL | J21: False | K21: DCG | L21: E214_DCG | M21: DCG-DVIR | N21: NA | P21: 0 | Q21: 0.00 | R21: YASMG | T21: FELANA13 | U21: 11 417 000.00 | V21: 11 417 000.00 | W21: MGA | X21: F | Y21: 46237 | Z21: 2026-08-03 | AA21: 46237 | AB21: 0000-00-00 | AC21: REMBOURSEMENT FRAIS BAC CDZ | AD21: YASSIE | AE21: YASSIE | AF21: C104 | AG21: E214_DCG | AH21: DCG-DVIR | AI21: STD | AL21: S | AM21: S | AN21: Felana RARIVOSON | AO21: LCS CONSULTING | AP21: RAZAFINDRAHAGA Setra | AR21: 11533 | AS21: 1 | AT21: PIE | AU21: 1593000 | AV21: PRESTATION DIVERS | AW21: C104 | AX21: 2490 | AY21: 136062 | AZ21: 4 | BA21: 2026-07-30
A22: REMBOURSEMENT FRAIS BAC CDZ S20 - PROFORMA N°243-A/FP/TELMA/2026 | B22: 0 | C22: 1247000 | D22: 1 247 000.00 | E22: 0 | F22: 139333 | G22: 5 | I22: PRICTRL | J22: False | K22: DCG | L22: E214_DCG | M22: DCG-DVIR | N22: NA | P22: 0 | Q22: 0.00 | R22: YASMG | T22: FELANA13 | U22: 11 417 000.00 | V22: 11 417 000.00 | W22: MGA | X22: F | Y22: 46237 | Z22: 2026-08-03 | AA22: 46237 | AB22: 0000-00-00 | AC22: REMBOURSEMENT FRAIS BAC CDZ | AD22: YASSIE | AE22: YASSIE | AF22: C104 | AG22: E214_DCG | AH22: DCG-DVIR | AI22: STD | AL22: S | AM22: S | AN22: Felana RARIVOSON | AO22: LCS CONSULTING | AP22: RAZAFINDRAHAGA Setra | AR22: 11533 | AS22: 1 | AT22: PIE | AU22: 1247000 | AV22: PRESTATION DIVERS | AW22: C104 | AX22: 2490 | AY22: 136062 | AZ22: 5 | BA22: 2026-07-30
A23: REMBOURSEMENT FRAIS BAC CDZ S22 - PROFORMA N°283-A/FP/TELMA/2026 | B23: 0 | C23: 2046000 | D23: 2 046 000.00 | E23: 0 | F23: 139333 | G23: 6 | I23: PRICTRL | J23: False | K23: DCG | L23: E214_DCG | M23: DCG-DVIR | N23: NA | P23: 0 | Q23: 0.00 | R23: YASMG | T23: FELANA13 | U23: 11 417 000.00 | V23: 11 417 000.00 | W23: MGA | X23: F | Y23: 46237 | Z23: 2026-08-03 | AA23: 46237 | AB23: 0000-00-00 | AC23: REMBOURSEMENT FRAIS BAC CDZ | AD23: YASSIE | AE23: YASSIE | AF23: C104 | AG23: E214_DCG | AH23: DCG-DVIR | AI23: STD | AL23: S | AM23: S | AN23: Felana RARIVOSON | AO23: LCS CONSULTING | AP23: RAZAFINDRAHAGA Setra | AR23: 11533 | AS23: 1 | AT23: PIE | AU23: 2046000 | AV23: PRESTATION DIVERS | AW23: C104 | AX23: 2490 | AY23: 136062 | AZ23: 6 | BA23: 2026-07-30
A24: REMBOURSEMENT FRAIS BAC CDZ S21 - PROFORMA N°285-A/FP/TELMA/2026 | B24: 0 | C24: 1851000 | D24: 1 851 000.00 | E24: 0 | F24: 139333 | G24: 7 | I24: PRICTRL | J24: False | K24: DCG | L24: E214_DCG | M24: DCG-DVIR | N24: NA | P24: 0 | Q24: 0.00 | R24: YASMG | T24: FELANA13 | U24: 11 417 000.00 | V24: 11 417 000.00 | W24: MGA | X24: F | Y24: 46237 | Z24: 2026-08-03 | AA24: 46237 | AB24: 0000-00-00 | AC24: REMBOURSEMENT FRAIS BAC CDZ | AD24: YASSIE | AE24: YASSIE | AF24: C104 | AG24: E214_DCG | AH24: DCG-DVIR | AI24: STD | AL24: S | AM24: S | AN24: Felana RARIVOSON | AO24: LCS CONSULTING | AP24: RAZAFINDRAHAGA Setra | AR24: 11533 | AS24: 1 | AT24: PIE | AU24: 1851000 | AV24: PRESTATION DIVERS | AW24: C104 | AX24: 2490 | AY24: 136062 | AZ24: 7 | BA24: 2026-07-30
A25: Rajout de 150 ARS dans la région du Grand Axe Nord pour une durée de 5 mois - août 2026 à décembre 2026 - suivant proforma N° 402-A/FP/TELMA /2026 | B25: 0 | C25: 302775000 | D25: 363 330 000.00 | E25: 20 | F25: 139331 | G25: 1 | I25: PRICTRL | J25: True | K25: DCG | L25: E214_DCG | M25: DCG-DVIR | N25: NA | P25: 1 | Q25: 302 775 000.00 | R25: YASMG | T25: FELANA13 | U25: 302 775 000.00 | V25: 363 330 000.00 | W25: MGA | Y25: 46237 | Z25: 2026-08-03 | AA25: 46237 | AB25: 0000-00-00 | AC25: RAJOUT ARS DANS LA ZONE NORD | AD25: YASSIE | AE25: YASSIE | AF25: C104 | AG25: E214_DCG | AH25: DCG-DVIR | AI25: STD | AL25: E | AM25: E | AN25: Felana RARIVOSON | AO25: LCS CONSULTING | AP25: RAZAFINDRAHAGA Setra | AR25: 1264 | AS25: 1 | AT25: UN | AU25: 302775000 | AV25: PRESTATION EXTERNE | AW25: C104 | AX25: 2490 | AY25: 136063 | AZ25: 1 | BA25: 2026-07-30
A26: Prestation intérimaire Telma 265 VAD dont 166 Tàna et 99 Région mois d'août 2026 - suivant proforma N°400-A/FP/TELMA/2026 | B26: 0 | C26: 119162000 | D26: 142 994 400.00 | E26: 20 | F26: 139328 | G26: 1 | I26: PRICTRL | J26: True | K26: DCG | L26: E214_DCG | M26: DCG-DRB | N26: NA | P26: 1 | Q26: 119 162 000.00 | R26: YASMG | T26: FELANA13 | U26: 238 324 000.00 | V26: 285 988 800.00 | W26: MGA | X26: F | Y26: 46237 | Z26: 2026-08-03 | AA26: 46237 | AB26: 0000-00-00 | AC26: Salaire VAD AOUT et SEPTEMBRE 2026 | AD26: YASSIE | AE26: YASSIE | AF26: C102 | AG26: E214_DCG | AH26: DCG-DRB | AI26: STD | AL26: E | AM26: E | AN26: Felana RARIVOSON | AO26: LCS CONSULTING | AP26: RAZAFINDRAHAGA Setra | AR26: 1264 | AS26: 1 | AT26: UN | AU26: 119162000 | AV26: PRESTATION EXTERNE | AW26: C102 | AX26: 2490 | AY26: 136064 | AZ26: 1 | BA26: 2026-07-30
A27: Prestation intérimaire Telma 265 VAD dont 166 Tàna et 99 Région mois de septembre 2026 - suivant proforma N°401-A/FP/TELMA/2026 | B27: 0 | C27: 119162000 | D27: 142 994 400.00 | E27: 20 | F27: 139328 | G27: 2 | I27: PRICTRL | J27: True | K27: DCG | L27: E214_DCG | M27: DCG-DRB | N27: NA | P27: 1 | Q27: 119 162 000.00 | R27: YASMG | T27: FELANA13 | U27: 238 324 000.00 | V27: 285 988 800.00 | W27: MGA | X27: F | Y27: 46237 | Z27: 2026-08-03 | AA27: 46237 | AB27: 0000-00-00 | AC27: Salaire VAD AOUT et SEPTEMBRE 2026 | AD27: YASSIE | AE27: YASSIE | AF27: C102 | AG27: E214_DCG | AH27: DCG-DRB | AI27: STD | AL27: E | AM27: E | AN27: Felana RARIVOSON | AO27: LCS CONSULTING | AP27: RAZAFINDRAHAGA Setra | AR27: 1264 | AS27: 1 | AT27: UN | AU27: 119162000 | AV27: PRESTATION EXTERNE | AW27: C102 | AX27: 2490 | AY27: 136064 | AZ27: 2 | BA27: 2026-07-30
A28: Prestation de défilé africain ( Danse africaine / DJ ambiance africaine /Maquillage / Transport) # PROFORMA NO 001 | B28: 0 | C28: 7000000 | D28: 7 000 000.00 | E28: 0 | F28: 139315 | G28: 1 | I28: PRICTRL | J28: False | K28: DCG | L28: E110_AP_DCOM | M28: DCG-COM | N28: NA | P28: 1 | Q28: 7 000 000.00 | R28: YASMG | T28: FELANA13 | U28: 7 000 000.00 | V28: 7 000 000.00 | W28: MGA | Y28: 46237 | Z28: 2026-08-03 | AA28: 46237 | AB28: 0000-00-00 | AC28: AFRICA DAY | AD28: YASSIE | AE28: YASSIE | AF28: C100 | AG28: E110_AP_DCOM | AH28: DCG-COM | AI28: STD | AL28: E | AM28: E | AN28: Felana RARIVOSON | AO28: ROOTS CONSEILS | AP28: RAZAFINDRAHAGA Setra | AR28: 11533 | AS28: 1 | AT28: PIE | AU28: 7000000 | AV28: PRESTATION DIVERS | AW28: C100 | AX28: 7090 | AY28: 136065 | AZ28: 1 | BA28: 2026-07-29
A29: ENTRETIEN MOTO - 15556WWT - MORONDAVA - PROFORMA N°111 | B29: 0 | C29: 817000 | D29: 817 000.00 | E29: 0 | F29: 139310 | G29: 1 | I29: PRMVEHI | J29: True | K29: DCG | L29: E222_DCG | M29: DCG-SHS | N29: NA | P29: 1 | Q29: 817 000.00 | R29: YASMG | T29: FELANA13 | U29: 817 000.00 | V29: 817 000.00 | W29: MGA | Y29: 46237 | Z29: 2026-08-03 | AA29: 46237 | AB29: 0000-00-00 | AC29: ENTRETIEN MOTO - MORONDAVA | AD29: YASSIE | AE29: YASSIE | AF29: C100 | AG29: E222_DCG | AH29: DCG-SHS | AI29: STD | AL29: E | AM29: E | AN29: Felana RARIVOSON | AO29: RAMANAMBONONA LALANIRIANA HANITRINIAINA | AP29: RAZAFINDRAHAGA Setra | AR29: 1185 | AS29: 1 | AT29: UN | AU29: 817000 | AV29: ENTRETIEN ET REPARATION VEHICULE Y COMPRIS PIECES DE RECHAN | AW29: C100 | AX29: 6740 | AY29: 136066 | AZ29: 1 | BA29: 2026-07-29
A30: ENTRETIEN MOTO - 46608WWT - TANA - devis 1de2478442 du 13/07/2026 | B30: 0 | C30: 90500 | D30: 108 600.00 | E30: 20 | F30: 139309 | G30: 1 | I30: PRMVEHI | J30: True | K30: DCG | L30: E222_DCG | M30: DCG-SHS | N30: NA | P30: 1 | Q30: 90 500.00 | R30: YASMG | T30: FELANA13 | U30: 90 500.00 | V30: 108 600.00 | W30: MGA | Y30: 46237 | Z30: 2026-08-03 | AA30: 46237 | AB30: 0000-00-00 | AC30: ENTRETIEN MOTO - MBALIK | AD30: YASSIE | AE30: YASSIE | AF30: C100 | AG30: E222_DCG | AH30: DCG-SHS | AI30: STD | AL30: E | AM30: E | AN30: Felana RARIVOSON | AO30: MADAGASCAR AUTOMOBILE | AP30: RAZAFINDRAHAGA Setra | AR30: 1185 | AS30: 1 | AT30: UN | AU30: 90500 | AV30: ENTRETIEN ET REPARATION VEHICULE Y COMPRIS PIECES DE RECHAN | AW30: C100 | AX30: 1184 | AY30: 136067 | AZ30: 1 | BA30: 2026-07-29
A31: Apport Numéraire FESTIVAL DONA BE - FACTURE N°12 | B31: 0 | C31: 40000000 | D31: 40 000 000.00 | E31: 0 | F31: 139337 | G31: 1 | I31: MECSPDC | J31: True | K31: DCG | L31: E110_AC_DCOM | M31: DCG-COM-PART | N31: NA | P31: 1 | Q31: 40 000 000.00 | R31: YASMG | T31: FELANA13 | U31: 40 000 000.00 | V31: 40 000 000.00 | W31: MGA | X31: F | Y31: 46237 | Z31: 2026-08-12 | AA31: 46237 | AB31: 0000-00-00 | AC31: FESTIVAL DONA BE | AD31: YASSIE | AE31: YASSIE | AF31: C100 | AG31: E110_AC_DCOM | AH31: DCG-COM-PART | AI31: STD | AL31: E | AM31: E | AN31: Felana RARIVOSON | AO31: JUMELLES PRODUCTION | AP31: RAZAFINDRAHAGA Setra | AR31: 1267 | AS31: 1 | AT31: UN | AU31: 40000000 | AV31: SPONSORING | AW31: C100 | AX31: 4323 | AY31: 136068 | AZ31: 1 | BA31: 2026-07-30
A32: Gazetiko 1/8 page Quadrichromie - FA N° FAC/2026/2997 | B32: 0 | C32: 6234785.4 | D32: 7 481 742.48 | E32: 20 | F32: 139307 | G32: 1 | I32: MEDMEDI | J32: True | K32: DCG | L32: E110_MD_DCOM | M32: DCG-COM-MEDIA | N32: NA | P32: 1 | Q32: 6 234 785.40 | R32: YASMG | T32: FELANA13 | U32: 29 855 556.88 | V32: 35 826 668.26 | W32: MGA | X32: F | Y32: 46237 | Z32: 2026-08-03 | AA32: 46237 | AB32: 0000-00-00 | AC32: ANNULE ET REMPLACE DA 139119 | AD32: YASSIE | AE32: YASSIE | AF32: C100 | AG32: E110_MD_DCOM | AH32: DCG-COM-MEDIA | AI32: STD | AL32: E | AM32: E | AN32: Felana RARIVOSON | AO32: MIDI PUBLICITE | AP32: RAZAFINDRAHAGA Setra | AR32: 1265 | AS32: 1 | AT32: UN | AU32: 6234785.4 | AV32: PUBLICITE ET ANNONCE | AW32: C100 | AX32: 2566 | AY32: 136069 | AZ32: 1 | BA32: 2026-07-29
A33: Midi 1/8 page Quadrichromie - FA N° FAC/2026/2996 | B33: 0 | C33: 8314553.6 | D33: 9 977 464.32 | E33: 20 | F33: 139307 | G33: 2 | I33: MEDMEDI | J33: True | K33: DCG | L33: E110_MD_DCOM | M33: DCG-COM-MEDIA | N33: NA | P33: 1 | Q33: 8 314 553.60 | R33: YASMG | T33: FELANA13 | U33: 29 855 556.88 | V33: 35 826 668.26 | W33: MGA | X33: F | Y33: 46237 | Z33: 2026-08-03 | AA33: 46237 | AB33: 0000-00-00 | AC33: ANNULE ET REMPLACE DA 139119 | AD33: YASSIE | AE33: YASSIE | AF33: C100 | AG33: E110_MD_DCOM | AH33: DCG-COM-MEDIA | AI33: STD | AL33: E | AM33: E | AN33: Felana RARIVOSON | AO33: MIDI PUBLICITE | AP33: RAZAFINDRAHAGA Setra | AR33: 1265 | AS33: 1 | AT33: UN | AU33: 8314553.6 | AV33: PUBLICITE ET ANNONCE | AW33: C100 | AX33: 2566 | AY33: 136069 | AZ33: 2 | BA33: 2026-07-29
A34: Gazetiko 1/8 page Quadrichromie - FA N° FAC/2026/3004 | B34: 0 | C34: 6607983 | D34: 7 929 579.60 | E34: 20 | F34: 139307 | G34: 3 | I34: MEDMEDI | J34: True | K34: DCG | L34: E110_MD_DCOM | M34: DCG-COM-MEDIA | N34: NA | P34: 1 | Q34: 6 607 983.00 | R34: YASMG | T34: FELANA13 | U34: 29 855 556.88 | V34: 35 826 668.26 | W34: MGA | X34: F | Y34: 46237 | Z34: 2026-08-03 | AA34: 46237 | AB34: 0000-00-00 | AC34: ANNULE ET REMPLACE DA 139119 | AD34: YASSIE | AE34: YASSIE | AF34: C100 | AG34: E110_MD_DCOM | AH34: DCG-COM-MEDIA | AI34: STD | AL34: E | AM34: E | AN34: Felana RARIVOSON | AO34: MIDI PUBLICITE | AP34: RAZAFINDRAHAGA Setra | AR34: 1265 | AS34: 1 | AT34: UN | AU34: 6607983 | AV34: PUBLICITE ET ANNONCE | AW34: C100 | AX34: 2566 | AY34: 136069 | AZ34: 3 | BA34: 2026-07-29
A35: Midi 1/8 page Quadrichromie - FA N° FAC/2026/3003 | B35: 0 | C35: 8698234.9 | D35: 10 437 881.86 | E35: 20 | F35: 139307 | G35: 4 | I35: MEDMEDI | J35: True | K35: DCG | L35: E110_MD_DCOM | M35: DCG-COM-MEDIA | N35: NA | P35: 1 | Q35: 8 698 234.88 | R35: YASMG | T35: FELANA13 | U35: 29 855 556.88 | V35: 35 826 668.26 | W35: MGA | X35: F | Y35: 46237 | Z35: 2026-08-03 | AA35: 46237 | AB35: 0000-00-00 | AC35: ANNULE ET REMPLACE DA 139119 | AD35: YASSIE | AE35: YASSIE | AF35: C100 | AG35: E110_MD_DCOM | AH35: DCG-COM-MEDIA | AI35: STD | AL35: E | AM35: E | AN35: Felana RARIVOSON | AO35: MIDI PUBLICITE | AP35: RAZAFINDRAHAGA Setra | AR35: 1265 | AS35: 1 | AT35: UN | AU35: 8698234.9 | AV35: PUBLICITE ET ANNONCE | AW35: C100 | AX35: 2566 | AY35: 136069 | AZ35: 4 | BA35: 2026-07-29
A36: Gazetiko 1/8 page Quadrichromie - FA N° FAC/2026/2332 | B36: 0 | C36: 3109980 | D36: 3 731 976.00 | E36: 20 | F36: 139305 | G36: 1 | I36: MEDMEDI | J36: True | K36: DCG | L36: E110_MD_DCOM | M36: DCG-COM-MEDIA | N36: NA | P36: 1 | Q36: 3 109 980.00 | R36: YASMG | T36: FELANA13 | U36: 20 941 238.56 | V36: 25 129 486.28 | W36: MGA | X36: F | Y36: 46237 | Z36: 2026-08-03 | AA36: 46237 | AB36: 0000-00-00 | AC36: ANNULE ET REMPLACE DA 139119 | AD36: YASSIE | AE36: YASSIE | AF36: C100 | AG36: E110_MD_DCOM | AH36: DCG-COM-MEDIA | AI36: STD | AL36: E | AM36: E | AN36: Felana RARIVOSON | AO36: MIDI PUBLICITE | AP36: RAZAFINDRAHAGA Setra | AR36: 1265 | AS36: 1 | AT36: UN | AU36: 3109980 | AV36: PUBLICITE ET ANNONCE | AW36: C100 | AX36: 2566 | AY36: 136070 | AZ36: 1 | BA36: 2026-07-29
A37: Midi 1/8 page Quadrichromie - FA N° FAC/2026/1810 | B37: 0 | C37: 4136906.9 | D37: 4 964 288.26 | E37: 20 | F37: 139305 | G37: 2 | I37: MEDMEDI | J37: True | K37: DCG | L37: E110_MD_DCOM | M37: DCG-COM-MEDIA | N37: NA | P37: 1 | Q37: 4 136 906.88 | R37: YASMG | T37: FELANA13 | U37: 20 941 238.56 | V37: 25 129 486.28 | W37: MGA | X37: F | Y37: 46237 | Z37: 2026-08-03 | AA37: 46237 | AB37: 0000-00-00 | AC37: ANNULE ET REMPLACE DA 139119 | AD37: YASSIE | AE37: YASSIE | AF37: C100 | AG37: E110_MD_DCOM | AH37: DCG-COM-MEDIA | AI37: STD | AL37: E | AM37: E | AN37: Felana RARIVOSON | AO37: MIDI PUBLICITE | AP37: RAZAFINDRAHAGA Setra | AR37: 1265 | AS37: 1 | AT37: UN | AU37: 4136906.9 | AV37: PUBLICITE ET ANNONCE | AW37: C100 | AX37: 2566 | AY37: 136070 | AZ37: 2 | BA37: 2026-07-29
A38: Midi 1/8 page Quadrichromie - FA N° FAC/2026/2993 | B38: 0 | C38: 7785969.3 | D38: 9 343 163.14 | E38: 20 | F38: 139305 | G38: 3 | I38: MEDMEDI | J38: True | K38: DCG | L38: E110_MD_DCOM | M38: DCG-COM-MEDIA | N38: NA | P38: 1 | Q38: 7 785 969.28 | R38: YASMG | T38: FELANA13 | U38: 20 941 238.56 | V38: 25 129 486.28 | W38: MGA | X38: F | Y38: 46237 | Z38: 2026-08-03 | AA38: 46237 | AB38: 0000-00-00 | AC38: ANNULE ET REMPLACE DA 139119 | AD38: YASSIE | AE38: YASSIE | AF38: C100 | AG38: E110_MD_DCOM | AH38: DCG-COM-MEDIA | AI38: STD | AL38: E | AM38: E | AN38: Felana RARIVOSON | AO38: MIDI PUBLICITE | AP38: RAZAFINDRAHAGA Setra | AR38: 1265 | AS38: 1 | AT38: UN | AU38: 7785969.3 | AV38: PUBLICITE ET ANNONCE | AW38: C100 | AX38: 2566 | AY38: 136070 | AZ38: 3 | BA38: 2026-07-29
A39: Gazetiko 1/8 page Quadrichromie - FA N° FAC/2026/2994 | B39: 0 | C39: 5908382.4 | D39: 7 090 058.88 | E39: 20 | F39: 139305 | G39: 4 | I39: MEDMEDI | J39: True | K39: DCG | L39: E110_MD_DCOM | M39: DCG-COM-MEDIA | N39: NA | P39: 1 | Q39: 5 908 382.40 | R39: YASMG | T39: FELANA13 | U39: 20 941 238.56 | V39: 25 129 486.28 | W39: MGA | X39: F | Y39: 46237 | Z39: 2026-08-03 | AA39: 46237 | AB39: 0000-00-00 | AC39: ANNULE ET REMPLACE DA 139119 | AD39: YASSIE | AE39: YASSIE | AF39: C100 | AG39: E110_MD_DCOM | AH39: DCG-COM-MEDIA | AI39: STD | AL39: E | AM39: E | AN39: Felana RARIVOSON | AO39: MIDI PUBLICITE | AP39: RAZAFINDRAHAGA Setra | AR39: 1265 | AS39: 1 | AT39: UN | AU39: 5908382.4 | AV39: PUBLICITE ET ANNONCE | AW39: C100 | AX39: 2566 | AY39: 136070 | AZ39: 4 | BA39: 2026-07-29
A40: Gazetiko 1/8 page Quadrichromie - FA N° FAC/2026/2333 | B40: 0 | C40: 5084382.6 | D40: 6 101 259.12 | E40: 20 | F40: 139304 | G40: 1 | I40: MEDMEDI | J40: True | K40: DCG | L40: E110_MD_DCOM | M40: DCG-COM-MEDIA | N40: NA | P40: 1 | Q40: 5 084 382.60 | R40: YASMG | T40: FELANA13 | U40: 21 710 626.88 | V40: 26 052 752.26 | W40: MGA | X40: F | Y40: 46237 | Z40: 2026-08-03 | AA40: 46237 | AB40: 0000-00-00 | AC40: ANNULE ET REMPLACE DA 139119 | AD40: YASSIE | AE40: YASSIE | AF40: C100 | AG40: E110_MD_DCOM | AH40: DCG-COM-MEDIA | AI40: STD | AL40: E | AM40: E | AN40: Felana RARIVOSON | AO40: MIDI PUBLICITE | AP40: RAZAFINDRAHAGA Setra | AR40: 1265 | AS40: 1 | AT40: UN | AU40: 5084382.6 | AV40: PUBLICITE ET ANNONCE | AW40: C100 | AX40: 2566 | AY40: 136071 | AZ40: 1 | BA40: 2026-07-29
...

Sheet Base Traitement
A1: N__de_Cde | B1: Raison_sociale_Fournisseur | C1: Design__sommaire | D1: Designation_Complémentaire | E1: Quantité_comm | F1: Unité | G1: Prix_Unitaire | H1: PU USD | I1: Total HT | J1: Total HT USD | K1: Devise | L1: Remise | M1: Date_creat | N1: Date_de_Validation | O1: N__DA | P1: Date_creat | Q1: Date_de_Validation | R1: V_Total_Ligne_TTC | S1: TVA | T1: N__Poste_DA | U1: Site_Stock | V1: Code_ss_famille | W1: Saisie_de_réception__ | X1: Code_Direction | Y1: Code_complément | Z1: SS_compte_anal | AA1: Centre_d_Analyse | AB1: Accord_Cadre | AC1: RAL | AD1: V_Montant_RAL | AE1: Code_Société | AF1: Avenant | AG1: Acheteur | AH1: Tot_CA_HT | AI1: Tot_CA_TTC | AJ1: Etat_Financ_ | AK1: Date_Période | AL1: Date_AR | AM1: Objet_CA | AN1: Ctr_Emetteur_entete | AO1: Ctr_Livraison_entete | AP1: Sect_Imputation_entete | AQ1: Code_Complémentaire_entete | AR1: Sous_Compte_d_Analyse_entete | AS1: Type_document | AT1: V_Expédition_soldée | AU1: Code_du_Modèle_de_Cde | AV1: V_Etat_commande_en_tête | AW1: V_Etat_commande_ligne | AX1: Nom_Acheteur | AY1: Nom_demandeur | AZ1: V_Critère_de_saisie | BA1: Code_Article | BB1: Section_d_imput | BC1: Code_Fournis | BD1: N_Poste | BE1: Date_de_livr__prev_
A2: 136058 | B2: RTV RECORD | C2: PUBLICITE ET ANNONCE | D2: SPOT - RECORD TV - suivant Facture N°TV000000282 | E2: 1 | F2: UN | G2: 549120 | I2: =E2*G2 -> 549120 | K2: MGA | L2: 0 | M2: 46237 | N2: 2026-08-03 | O2: 139303 | R2: 658 944.00 | S2: 20 | T2: 1 | V2: MEDMEDI | W2: True | X2: DCG | Y2: E110_MD_DCOM | Z2: DCG-COM-MEDIA | AA2: NA | AC2: 1 | AD2: 549 120.00 | AE2: YASMG | AG2: FELANA13 | AH2: 3 926 784.00 | AI2: 4 712 140.80 | AJ2: F | AK2: 46237 | AL2: 0000-00-00 | AM2: SPOT - RECORD TV | AN2: YASSIE | AO2: YASSIE | AP2: C100 | AQ2: E110_MD_DCOM | AR2: DCG-COM-MEDIA | AS2: STD | AV2: E | AW2: E | AX2: Felana RARIVOSON | AY2: RAZAFINDRAHAGA Setra | BA2: 1265 | BB2: C100 | BC2: 973 | BD2: 1 | BE2: 2026-07-29
A3: 136058 | B3: RTV RECORD | C3: PUBLICITE ET ANNONCE | D3: SPOT - RECORD TV - suivant Facture N°RD000000250 | E3: 1 | F3: UN | G3: 403200 | I3: =E3*G3 -> 403200 | K3: MGA | L3: 0 | M3: 46237 | N3: 2026-08-03 | O3: 139303 | R3: 483 840.00 | S3: 20 | T3: 2 | V3: MEDMEDI | W3: True | X3: DCG | Y3: E110_MD_DCOM | Z3: DCG-COM-MEDIA | AA3: NA | AC3: 1 | AD3: 403 200.00 | AE3: YASMG | AG3: FELANA13 | AH3: 3 926 784.00 | AI3: 4 712 140.80 | AJ3: F | AK3: 46237 | AL3: 0000-00-00 | AM3: SPOT - RECORD TV | AN3: YASSIE | AO3: YASSIE | AP3: C100 | AQ3: E110_MD_DCOM | AR3: DCG-COM-MEDIA | AS3: STD | AV3: E | AW3: E | AX3: Felana RARIVOSON | AY3: RAZAFINDRAHAGA Setra | BA3: 1265 | BB3: C100 | BC3: 973 | BD3: 2 | BE3: 2026-07-29
A4: 136058 | B4: RTV RECORD | C4: PUBLICITE ET ANNONCE | D4: SPOT - RECORD TV - suivant Facture N°RD000000270 | E4: 1 | F4: UN | G4: 82944 | I4: =E4*G4 -> 82944 | K4: MGA | L4: 0 | M4: 46237 | N4: 2026-08-03 | O4: 139303 | R4: 99 532.80 | S4: 20 | T4: 3 | V4: MEDMEDI | W4: True | X4: DCG | Y4: E110_MD_DCOM | Z4: DCG-COM-MEDIA | AA4: NA | AC4: 1 | AD4: 82 944.00 | AE4: YASMG | AG4: FELANA13 | AH4: 3 926 784.00 | AI4: 4 712 140.80 | AJ4: F | AK4: 46237 | AL4: 0000-00-00 | AM4: SPOT - RECORD TV | AN4: YASSIE | AO4: YASSIE | AP4: C100 | AQ4: E110_MD_DCOM | AR4: DCG-COM-MEDIA | AS4: STD | AV4: E | AW4: E | AX4: Felana RARIVOSON | AY4: RAZAFINDRAHAGA Setra | BA4: 1265 | BB4: C100 | BC4: 973 | BD4: 3 | BE4: 2026-07-29
A5: 136058 | B5: RTV RECORD | C5: PUBLICITE ET ANNONCE | D5: SPOT - RECORD TV - suivant Facture N°RD000000280 | E5: 1 | F5: UN | G5: 403200 | I5: =E5*G5 -> 403200 | K5: MGA | L5: 0 | M5: 46237 | N5: 2026-08-03 | O5: 139303 | R5: 483 840.00 | S5: 20 | T5: 4 | V5: MEDMEDI | W5: True | X5: DCG | Y5: E110_MD_DCOM | Z5: DCG-COM-MEDIA | AA5: NA | AC5: 1 | AD5: 403 200.00 | AE5: YASMG | AG5: FELANA13 | AH5: 3 926 784.00 | AI5: 4 712 140.80 | AJ5: F | AK5: 46237 | AL5: 0000-00-00 | AM5: SPOT - RECORD TV | AN5: YASSIE | AO5: YASSIE | AP5: C100 | AQ5: E110_MD_DCOM | AR5: DCG-COM-MEDIA | AS5: STD | AV5: E | AW5: E | AX5: Felana RARIVOSON | AY5: RAZAFINDRAHAGA Setra | BA5: 1265 | BB5: C100 | BC5: 973 | BD5: 4 | BE5: 2026-07-29
A6: 136058 | B6: RTV RECORD | C6: PUBLICITE ET ANNONCE | D6: SPOT - RECORD TV - suivant Facture N°RD000000296 | E6: 1 | F6: UN | G6: 829440 | I6: =E6*G6 -> 829440 | K6: MGA | L6: 0 | M6: 46237 | N6: 2026-08-03 | O6: 139303 | R6: 995 328.00 | S6: 20 | T6: 5 | V6: MEDMEDI | W6: True | X6: DCG | Y6: E110_MD_DCOM | Z6: DCG-COM-MEDIA | AA6: NA | AC6: 1 | AD6: 829 440.00 | AE6: YASMG | AG6: FELANA13 | AH6: 3 926 784.00 | AI6: 4 712 140.80 | AJ6: F | AK6: 46237 | AL6: 0000-00-00 | AM6: SPOT - RECORD TV | AN6: YASSIE | AO6: YASSIE | AP6: C100 | AQ6: E110_MD_DCOM | AR6: DCG-COM-MEDIA | AS6: STD | AV6: E | AW6: E | AX6: Felana RARIVOSON | AY6: RAZAFINDRAHAGA Setra | BA6: 1265 | BB6: C100 | BC6: 973 | BD6: 5 | BE6: 2026-07-29
A7: 136058 | B7: RTV RECORD | C7: PUBLICITE ET ANNONCE | D7: SPOT - RECORD TV - suivant Facture N°RD000000297 | E7: 1 | F7: UN | G7: 829440 | I7: =E7*G7 -> 829440 | K7: MGA | L7: 0 | M7: 46237 | N7: 2026-08-03 | O7: 139303 | R7: 995 328.00 | S7: 20 | T7: 6 | V7: MEDMEDI | W7: True | X7: DCG | Y7: E110_MD_DCOM | Z7: DCG-COM-MEDIA | AA7: NA | AC7: 1 | AD7: 829 440.00 | AE7: YASMG | AG7: FELANA13 | AH7: 3 926 784.00 | AI7: 4 712 140.80 | AJ7: F | AK7: 46237 | AL7: 0000-00-00 | AM7: SPOT - RECORD TV | AN7: YASSIE | AO7: YASSIE | AP7: C100 | AQ7: E110_MD_DCOM | AR7: DCG-COM-MEDIA | AS7: STD | AV7: E | AW7: E | AX7: Felana RARIVOSON | AY7: RAZAFINDRAHAGA Setra | BA7: 1265 | BB7: C100 | BC7: 973 | BD7: 6 | BE7: 2026-07-29
A8: 136058 | B8: RTV RECORD | C8: PUBLICITE ET ANNONCE | D8: SPOT - RECORD TV - suivant Facture N°RD000000288 | E8: 1 | F8: UN | G8: 829440 | I8: =E8*G8 -> 829440 | K8: MGA | L8: 0 | M8: 46237 | N8: 2026-08-03 | O8: 139303 | R8: 995 328.00 | S8: 20 | T8: 7 | V8: MEDMEDI | W8: True | X8: DCG | Y8: E110_MD_DCOM | Z8: DCG-COM-MEDIA | AA8: NA | AC8: 1 | AD8: 829 440.00 | AE8: YASMG | AG8: FELANA13 | AH8: 3 926 784.00 | AI8: 4 712 140.80 | AJ8: F | AK8: 46237 | AL8: 0000-00-00 | AM8: SPOT - RECORD TV | AN8: YASSIE | AO8: YASSIE | AP8: C100 | AQ8: E110_MD_DCOM | AR8: DCG-COM-MEDIA | AS8: STD | AV8: E | AW8: E | AX8: Felana RARIVOSON | AY8: RAZAFINDRAHAGA Setra | BA8: 1265 | BB8: C100 | BC8: 973 | BD8: 7 | BE8: 2026-07-29
A9: 136059 | B9: SIGN | C9: STICKERS AUTOCOLLANT - MBALIK - JUILLET 2025 | D9: Stickers Home Plus - 7,5 x 6 cm - suivant proforma N° FP05186 | E9: 30500 | F9: UN | G9: 168 | I9: =E9*G9 -> 5124000 | K9: MGA | L9: 0 | M9: 46237 | N9: 2026-08-03 | O9: 139299 | R9: 6 148 800.00 | S9: 20 | T9: 1 | V9: GELACCS | W9: True | X9: DCG | Y9: E110_TR_MBLK | Z9: DCG-SHS | AA9: NA | AC9: 30500 | AD9: 5 124 000.00 | AE9: YASMG | AG9: FELANA13 | AH9: 39 000 000.00 | AI9: 46 800 000.00 | AK9: 46237 | AL9: 0000-00-00 | AM9: STICKERS MBALIK | AN9: YASSIE | AO9: GALE | AP9: C100 | AQ9: E110_TR_MBLK | AR9: DCG-SHS | AS9: STD | AV9: E | AW9: E | AX9: Felana RARIVOSON | AY9: RAZAFINDRAHAGA Setra | BA9: 24694 | BB9: C100 | BC9: 1089 | BD9: 1 | BE9: 2026-07-29
A10: 136059 | B10: SIGN | C10: STICKERS AUTOCOLLANT - MBALIK - JUILLET 2025 | D10: Stickers Home Plus - 13x19 cm (sticker facing) - suivant proforma N° FP05186 | E10: 30500 | F10: UN | G10: 648 | I10: =E10*G10 -> 19764000 | K10: MGA | L10: 0 | M10: 46237 | N10: 2026-08-03 | O10: 139299 | R10: 23 716 800.00 | S10: 20 | T10: 2 | V10: GELACCS | W10: True | X10: DCG | Y10: E110_TR_MBLK | Z10: DCG-SHS | AA10: NA | AC10: 30500 | AD10: 19 764 000.00 | AE10: YASMG | AG10: FELANA13 | AH10: 39 000 000.00 | AI10: 46 800 000.00 | AK10: 46237 | AL10: 0000-00-00 | AM10: STICKERS MBALIK | AN10: YASSIE | AO10: GALE | AP10: C100 | AQ10: E110_TR_MBLK | AR10: DCG-SHS | AS10: STD | AV10: E | AW10: E | AX10: Felana RARIVOSON | AY10: RAZAFINDRAHAGA Setra | BA10: 24694 | BB10: C100 | BC10: 1089 | BD10: 2 | BE10: 2026-07-29
A11: 136059 | B11: SIGN | C11: STICKERS AUTOCOLLANT - MBALIK - JUILLET 2025 | D11: Stickers Home Plus - 2,8x2,8 cm (sticker rond) - suivant proforma N° FP05186 | E11: 30500 | F11: UN | G11: 36 | I11: =E11*G11 -> 1098000 | K11: MGA | L11: 0 | M11: 46237 | N11: 2026-08-03 | O11: 139299 | R11: 1 317 600.00 | S11: 20 | T11: 3 | V11: GELACCS | W11: True | X11: DCG | Y11: E110_TR_MBLK | Z11: DCG-SHS | AA11: NA | AC11: 30500 | AD11: 1 098 000.00 | AE11: YASMG | AG11: FELANA13 | AH11: 39 000 000.00 | AI11: 46 800 000.00 | AK11: 46237 | AL11: 0000-00-00 | AM11: STICKERS MBALIK | AN11: YASSIE | AO11: GALE | AP11: C100 | AQ11: E110_TR_MBLK | AR11: DCG-SHS | AS11: STD | AV11: E | AW11: E | AX11: Felana RARIVOSON | AY11: RAZAFINDRAHAGA Setra | BA11: 24694 | BB11: C100 | BC11: 1089 | BD11: 3 | BE11: 2026-07-29
A12: 136059 | B12: SIGN | C12: STICKERS AUTOCOLLANT - MBALIK - JUILLET 2025 | D12: Stickers Home Plus - 3,5x2 cm (sticker pour cacher logo Sunking sur l'image du boîtier du facing) - suivant proforma N° FP05186 | E12: 30500 | F12: UN | G12: 28 | I12: =E12*G12 -> 854000 | K12: MGA | L12: 0 | M12: 46237 | N12: 2026-08-03 | O12: 139299 | R12: 1 024 800.00 | S12: 20 | T12: 4 | V12: GELACCS | W12: True | X12: DCG | Y12: E110_TR_MBLK | Z12: DCG-SHS | AA12: NA | AC12: 30500 | AD12: 854 000.00 | AE12: YASMG | AG12: FELANA13 | AH12: 39 000 000.00 | AI12: 46 800 000.00 | AK12: 46237 | AL12: 0000-00-00 | AM12: STICKERS MBALIK | AN12: YASSIE | AO12: GALE | AP12: C100 | AQ12: E110_TR_MBLK | AR12: DCG-SHS | AS12: STD | AV12: E | AW12: E | AX12: Felana RARIVOSON | AY12: RAZAFINDRAHAGA Setra | BA12: 24694 | BB12: C100 | BC12: 1089 | BD12: 4 | BE12: 2026-07-29
A13: 136059 | B13: SIGN | C13: STICKERS AUTOCOLLANT - MBALIK - JUILLET 2025 | D13: Stickers Home Plus - 7x2 cm (sticker dos) - suivant proforma N° FP05186 | E13: 30500 | F13: UN | G13: 48.8 | I13: =E13*G13 -> 1488400 | K13: MGA | L13: 0 | M13: 46237 | N13: 2026-08-03 | O13: 139299 | R13: 1 786 080.00 | S13: 20 | T13: 5 | V13: GELACCS | W13: True | X13: DCG | Y13: E110_TR_MBLK | Z13: DCG-SHS | AA13: NA | AC13: 30500 | AD13: 1 488 400.00 | AE13: YASMG | AG13: FELANA13 | AH13: 39 000 000.00 | AI13: 46 800 000.00 | AK13: 46237 | AL13: 0000-00-00 | AM13: STICKERS MBALIK | AN13: YASSIE | AO13: GALE | AP13: C100 | AQ13: E110_TR_MBLK | AR13: DCG-SHS | AS13: STD | AV13: E | AW13: E | AX13: Felana RARIVOSON | AY13: RAZAFINDRAHAGA Setra | BA13: 24694 | BB13: C100 | BC13: 1089 | BD13: 5 | BE13: 2026-07-29
A14: 136059 | B14: SIGN | C14: STICKERS AUTOCOLLANT - MBALIK - JUILLET 2025 | D14: Stickers Home Plus - 11x5,3 cm sticker côté jaune - suivant proforma N° FP05186 | E14: 61000 | F14: UN | G14: 153 | I14: =E14*G14 -> 9333000 | K14: MGA | L14: 0 | M14: 46237 | N14: 2026-08-03 | O14: 139299 | R14: 11 199 600.00 | S14: 20 | T14: 6 | V14: GELACCS | W14: True | X14: DCG | Y14: E110_TR_MBLK | Z14: DCG-SHS | AA14: NA | AC14: 61000 | AD14: 9 333 000.00 | AE14: YASMG | AG14: FELANA13 | AH14: 39 000 000.00 | AI14: 46 800 000.00 | AK14: 46237 | AL14: 0000-00-00 | AM14: STICKERS MBALIK | AN14: YASSIE | AO14: GALE | AP14: C100 | AQ14: E110_TR_MBLK | AR14: DCG-SHS | AS14: STD | AV14: E | AW14: E | AX14: Felana RARIVOSON | AY14: RAZAFINDRAHAGA Setra | BA14: 24694 | BB14: C100 | BC14: 1089 | BD14: 6 | BE14: 2026-07-29
A15: 136059 | B15: SIGN | C15: FRAIS DE POSE | D15: POSE A ANDRAHARO | E15: 1 | F15: UN | G15: 1338600 | I15: =E15*G15 -> 1338600 | K15: MGA | L15: 0 | M15: 46237 | N15: 2026-08-03 | O15: 139299 | R15: 1 606 320.00 | S15: 20 | T15: 7 | V15: ELEMCEL | W15: True | X15: DCG | Y15: E110_TR_MBLK | Z15: DCG-SHS | AA15: NA | AC15: 1 | AD15: 1 338 600.00 | AE15: YASMG | AG15: FELANA13 | AH15: 39 000 000.00 | AI15: 46 800 000.00 | AK15: 46237 | AL15: 0000-00-00 | AM15: STICKERS MBALIK | AN15: YASSIE | AO15: GALE | AP15: C100 | AQ15: E110_TR_MBLK | AR15: DCG-SHS | AS15: STD | AV15: E | AW15: E | AX15: Felana RARIVOSON | AY15: RAZAFINDRAHAGA Setra | BA15: 2061 | BB15: C100 | BC15: 1089 | BD15: 7 | BE15: 2026-07-29
A16: 136060 | B16: AVRA BTP | C16: TRAVAUX SUPPLEMENTAIRES | D16: TRAVAUX DE COULLAGE DALLE EN BETON YAS STORE AMBOHIPO - suivant Devis N° 206/2026 INDICE 0 | E16: 1 | F16: UN | G16: 782000 | I16: =E16*G16 -> 782000 | K16: MGA | L16: 0 | M16: 46237 | N16: 2026-08-03 | O16: 139284 | R16: 782 000.00 | S16: 0 | T16: 1 | V16: INFPYLX | W16: True | X16: DCG | Y16: E250_DRB | Z16: DCG-DRB | AA16: NA | AC16: 1 | AD16: 782 000.00 | AE16: YASMG | AG16: FELANA13 | AH16: 782 000.00 | AI16: 782 000.00 | AJ16: F | AK16: 46237 | AL16: 0000-00-00 | AM16: YS AMBOHIPO | AN16: YASSIE | AO16: YASSIE | AP16: C102 | AQ16: E250_DRB | AR16: DCG-DRB | AS16: STD | AV16: E | AW16: E | AX16: Felana RARIVOSON | AY16: RAZAFINDRAHAGA Setra | BA16: 1526 | BB16: C102 | BC16: 4038 | BD16: 1 | BE16: 2026-07-28
A17: 136061 | B17: AVRA BTP | C17: TRAVAUX SUPPLEMENTAIRES | D17: TRAVAUX DE POSE CARREAUX MURAUX - suivant devis N° 205/2026 INDICE 0 | E17: 1 | F17: UN | G17: 824000 | I17: =E17*G17 -> 824000 | K17: MGA | L17: 0 | M17: 46237 | N17: 2026-08-03 | O17: 139283 | R17: 824 000.00 | S17: 0 | T17: 1 | V17: INFPYLX | W17: True | X17: DCG | Y17: E250_DRB | Z17: DCG-DRB | AA17: NA | AC17: 1 | AD17: 824 000.00 | AE17: YASMG | AG17: FELANA13 | AH17: 824 000.00 | AI17: 824 000.00 | AK17: 46237 | AL17: 0000-00-00 | AM17: YS ITAOSY | AN17: YASSIE | AO17: YASSIE | AP17: C102 | AQ17: E250_DRB | AR17: DCG-DRB | AS17: STD | AV17: E | AW17: E | AX17: Felana RARIVOSON | AY17: RAZAFINDRAHAGA Setra | BA17: 1526 | BB17: C102 | BC17: 4038 | BD17: 1 | BE17: 2026-07-28
A18: 136062 | B18: LCS CONSULTING | C18: PRESTATION DIVERS | D18: REMBOURSEMENT FRAIS BAC CDZ S14 - PROFORMA N°192-A/FP/TELMA/2026 | E18: 1 | F18: PIE | G18: 1480000 | I18: =E18*G18 -> 1480000 | K18: MGA | L18: 0 | M18: 46237 | N18: 2026-08-03 | O18: 139333 | R18: 1 480 000.00 | S18: 0 | T18: 1 | V18: PRICTRL | W18: False | X18: DCG | Y18: E214_DCG | Z18: DCG-DVIR | AA18: NA | AC18: 0 | AD18: 0.00 | AE18: YASMG | AG18: FELANA13 | AH18: 11 417 000.00 | AI18: 11 417 000.00 | AJ18: F | AK18: 46237 | AL18: 0000-00-00 | AM18: REMBOURSEMENT FRAIS BAC CDZ | AN18: YASSIE | AO18: YASSIE | AP18: C104 | AQ18: E214_DCG | AR18: DCG-DVIR | AS18: STD | AV18: S | AW18: S | AX18: Felana RARIVOSON | AY18: RAZAFINDRAHAGA Setra | BA18: 11533 | BB18: C104 | BC18: 2490 | BD18: 1 | BE18: 2026-07-30
A19: 136062 | B19: LCS CONSULTING | C19: PRESTATION DIVERS | D19: REMBOURSEMENT FRAIS BAC CDZ S15 - PROFORMA N°194-A/FP/TELMA/2026 | E19: 1 | F19: PIE | G19: 1483000 | I19: =E19*G19 -> 1483000 | K19: MGA | L19: 0 | M19: 46237 | N19: 2026-08-03 | O19: 139333 | R19: 1 483 000.00 | S19: 0 | T19: 2 | V19: PRICTRL | W19: False | X19: DCG | Y19: E214_DCG | Z19: DCG-DVIR | AA19: NA | AC19: 0 | AD19: 0.00 | AE19: YASMG | AG19: FELANA13 | AH19: 11 417 000.00 | AI19: 11 417 000.00 | AJ19: F | AK19: 46237 | AL19: 0000-00-00 | AM19: REMBOURSEMENT FRAIS BAC CDZ | AN19: YASSIE | AO19: YASSIE | AP19: C104 | AQ19: E214_DCG | AR19: DCG-DVIR | AS19: STD | AV19: S | AW19: S | AX19: Felana RARIVOSON | AY19: RAZAFINDRAHAGA Setra | BA19: 11533 | BB19: C104 | BC19: 2490 | BD19: 2 | BE19: 2026-07-30
A20: 136062 | B20: LCS CONSULTING | C20: PRESTATION DIVERS | D20: REMBOURSEMENT FRAIS BAC CDZ S16 - PROFORMA N°212-A/FP/TELMA/2026 | E20: 1 | F20: PIE | G20: 1717000 | I20: =E20*G20 -> 1717000 | K20: MGA | L20: 0 | M20: 46237 | N20: 2026-08-03 | O20: 139333 | R20: 1 717 000.00 | S20: 0 | T20: 3 | V20: PRICTRL | W20: False | X20: DCG | Y20: E214_DCG | Z20: DCG-DVIR | AA20: NA | AC20: 0 | AD20: 0.00 | AE20: YASMG | AG20: FELANA13 | AH20: 11 417 000.00 | AI20: 11 417 000.00 | AJ20: F | AK20: 46237 | AL20: 0000-00-00 | AM20: REMBOURSEMENT FRAIS BAC CDZ | AN20: YASSIE | AO20: YASSIE | AP20: C104 | AQ20: E214_DCG | AR20: DCG-DVIR | AS20: STD | AV20: S | AW20: S | AX20: Felana RARIVOSON | AY20: RAZAFINDRAHAGA Setra | BA20: 11533 | BB20: C104 | BC20: 2490 | BD20: 3 | BE20: 2026-07-30
A21: 136062 | B21: LCS CONSULTING | C21: PRESTATION DIVERS | D21: REMBOURSEMENT FRAIS BAC CDZ S17 - PROFORMA N°214-A/FP/TELMA/2026 | E21: 1 | F21: PIE | G21: 1593000 | I21: =E21*G21 -> 1593000 | K21: MGA | L21: 0 | M21: 46237 | N21: 2026-08-03 | O21: 139333 | R21: 1 593 000.00 | S21: 0 | T21: 4 | V21: PRICTRL | W21: False | X21: DCG | Y21: E214_DCG | Z21: DCG-DVIR | AA21: NA | AC21: 0 | AD21: 0.00 | AE21: YASMG | AG21: FELANA13 | AH21: 11 417 000.00 | AI21: 11 417 000.00 | AJ21: F | AK21: 46237 | AL21: 0000-00-00 | AM21: REMBOURSEMENT FRAIS BAC CDZ | AN21: YASSIE | AO21: YASSIE | AP21: C104 | AQ21: E214_DCG | AR21: DCG-DVIR | AS21: STD | AV21: S | AW21: S | AX21: Felana RARIVOSON | AY21: RAZAFINDRAHAGA Setra | BA21: 11533 | BB21: C104 | BC21: 2490 | BD21: 4 | BE21: 2026-07-30
A22: 136062 | B22: LCS CONSULTING | C22: PRESTATION DIVERS | D22: REMBOURSEMENT FRAIS BAC CDZ S20 - PROFORMA N°243-A/FP/TELMA/2026 | E22: 1 | F22: PIE | G22: 1247000 | I22: =E22*G22 -> 1247000 | K22: MGA | L22: 0 | M22: 46237 | N22: 2026-08-03 | O22: 139333 | R22: 1 247 000.00 | S22: 0 | T22: 5 | V22: PRICTRL | W22: False | X22: DCG | Y22: E214_DCG | Z22: DCG-DVIR | AA22: NA | AC22: 0 | AD22: 0.00 | AE22: YASMG | AG22: FELANA13 | AH22: 11 417 000.00 | AI22: 11 417 000.00 | AJ22: F | AK22: 46237 | AL22: 0000-00-00 | AM22: REMBOURSEMENT FRAIS BAC CDZ | AN22: YASSIE | AO22: YASSIE | AP22: C104 | AQ22: E214_DCG | AR22: DCG-DVIR | AS22: STD | AV22: S | AW22: S | AX22: Felana RARIVOSON | AY22: RAZAFINDRAHAGA Setra | BA22: 11533 | BB22: C104 | BC22: 2490 | BD22: 5 | BE22: 2026-07-30
A23: 136062 | B23: LCS CONSULTING | C23: PRESTATION DIVERS | D23: REMBOURSEMENT FRAIS BAC CDZ S22 - PROFORMA N°283-A/FP/TELMA/2026 | E23: 1 | F23: PIE | G23: 2046000 | I23: =E23*G23 -> 2046000 | K23: MGA | L23: 0 | M23: 46237 | N23: 2026-08-03 | O23: 139333 | R23: 2 046 000.00 | S23: 0 | T23: 6 | V23: PRICTRL | W23: False | X23: DCG | Y23: E214_DCG | Z23: DCG-DVIR | AA23: NA | AC23: 0 | AD23: 0.00 | AE23: YASMG | AG23: FELANA13 | AH23: 11 417 000.00 | AI23: 11 417 000.00 | AJ23: F | AK23: 46237 | AL23: 0000-00-00 | AM23: REMBOURSEMENT FRAIS BAC CDZ | AN23: YASSIE | AO23: YASSIE | AP23: C104 | AQ23: E214_DCG | AR23: DCG-DVIR | AS23: STD | AV23: S | AW23: S | AX23: Felana RARIVOSON | AY23: RAZAFINDRAHAGA Setra | BA23: 11533 | BB23: C104 | BC23: 2490 | BD23: 6 | BE23: 2026-07-30
A24: 136062 | B24: LCS CONSULTING | C24: PRESTATION DIVERS | D24: REMBOURSEMENT FRAIS BAC CDZ S21 - PROFORMA N°285-A/FP/TELMA/2026 | E24: 1 | F24: PIE | G24: 1851000 | I24: =E24*G24 -> 1851000 | K24: MGA | L24: 0 | M24: 46237 | N24: 2026-08-03 | O24: 139333 | R24: 1 851 000.00 | S24: 0 | T24: 7 | V24: PRICTRL | W24: False | X24: DCG | Y24: E214_DCG | Z24: DCG-DVIR | AA24: NA | AC24: 0 | AD24: 0.00 | AE24: YASMG | AG24: FELANA13 | AH24: 11 417 000.00 | AI24: 11 417 000.00 | AJ24: F | AK24: 46237 | AL24: 0000-00-00 | AM24: REMBOURSEMENT FRAIS BAC CDZ | AN24: YASSIE | AO24: YASSIE | AP24: C104 | AQ24: E214_DCG | AR24: DCG-DVIR | AS24: STD | AV24: S | AW24: S | AX24: Felana RARIVOSON | AY24: RAZAFINDRAHAGA Setra | BA24: 11533 | BB24: C104 | BC24: 2490 | BD24: 7 | BE24: 2026-07-30
A25: 136063 | B25: LCS CONSULTING | C25: PRESTATION EXTERNE | D25: Rajout de 150 ARS dans la région du Grand Axe Nord pour une durée de 5 mois - août 2026 à décembre 2026 - suivant proforma N° 402-A/FP/TELMA /2026 | E25: 1 | F25: UN | G25: 302775000 | I25: =E25*G25 -> 302775000 | K25: MGA | L25: 0 | M25: 46237 | N25: 2026-08-03 | O25: 139331 | R25: 363 330 000.00 | S25: 20 | T25: 1 | V25: PRICTRL | W25: True | X25: DCG | Y25: E214_DCG | Z25: DCG-DVIR | AA25: NA | AC25: 1 | AD25: 302 775 000.00 | AE25: YASMG | AG25: FELANA13 | AH25: 302 775 000.00 | AI25: 363 330 000.00 | AK25: 46237 | AL25: 0000-00-00 | AM25: RAJOUT ARS DANS LA ZONE NORD | AN25: YASSIE | AO25: YASSIE | AP25: C104 | AQ25: E214_DCG | AR25: DCG-DVIR | AS25: STD | AV25: E | AW25: E | AX25: Felana RARIVOSON | AY25: RAZAFINDRAHAGA Setra | BA25: 1264 | BB25: C104 | BC25: 2490 | BD25: 1 | BE25: 2026-07-30
A26: 136064 | B26: LCS CONSULTING | C26: PRESTATION EXTERNE | D26: Prestation intérimaire Telma 265 VAD dont 166 Tàna et 99 Région mois d'août 2026 - suivant proforma N°400-A/FP/TELMA/2026 | E26: 1 | F26: UN | G26: 119162000 | I26: =E26*G26 -> 119162000 | K26: MGA | L26: 0 | M26: 46237 | N26: 2026-08-03 | O26: 139328 | R26: 142 994 400.00 | S26: 20 | T26: 1 | V26: PRICTRL | W26: True | X26: DCG | Y26: E214_DCG | Z26: DCG-DRB | AA26: NA | AC26: 1 | AD26: 119 162 000.00 | AE26: YASMG | AG26: FELANA13 | AH26: 238 324 000.00 | AI26: 285 988 800.00 | AJ26: F | AK26: 46237 | AL26: 0000-00-00 | AM26: Salaire VAD AOUT et SEPTEMBRE 2026 | AN26: YASSIE | AO26: YASSIE | AP26: C102 | AQ26: E214_DCG | AR26: DCG-DRB | AS26: STD | AV26: E | AW26: E | AX26: Felana RARIVOSON | AY26: RAZAFINDRAHAGA Setra | BA26: 1264 | BB26: C102 | BC26: 2490 | BD26: 1 | BE26: 2026-07-30
A27: 136064 | B27: LCS CONSULTING | C27: PRESTATION EXTERNE | D27: Prestation intérimaire Telma 265 VAD dont 166 Tàna et 99 Région mois de septembre 2026 - suivant proforma N°401-A/FP/TELMA/2026 | E27: 1 | F27: UN | G27: 119162000 | I27: =E27*G27 -> 119162000 | K27: MGA | L27: 0 | M27: 46237 | N27: 2026-08-03 | O27: 139328 | R27: 142 994 400.00 | S27: 20 | T27: 2 | V27: PRICTRL | W27: True | X27: DCG | Y27: E214_DCG | Z27: DCG-DRB | AA27: NA | AC27: 1 | AD27: 119 162 000.00 | AE27: YASMG | AG27: FELANA13 | AH27: 238 324 000.00 | AI27: 285 988 800.00 | AJ27: F | AK27: 46237 | AL27: 0000-00-00 | AM27: Salaire VAD AOUT et SEPTEMBRE 2026 | AN27: YASSIE | AO27: YASSIE | AP27: C102 | AQ27: E214_DCG | AR27: DCG-DRB | AS27: STD | AV27: E | AW27: E | AX27: Felana RARIVOSON | AY27: RAZAFINDRAHAGA Setra | BA27: 1264 | BB27: C102 | BC27: 2490 | BD27: 2 | BE27: 2026-07-30
A28: 136065 | B28: ROOTS CONSEILS | C28: PRESTATION DIVERS | D28: Prestation de défilé africain ( Danse africaine / DJ ambiance africaine /Maquillage / Transport) # PROFORMA NO 001 | E28: 1 | F28: PIE | G28: 7000000 | I28: =E28*G28 -> 7000000 | K28: MGA | L28: 0 | M28: 46237 | N28: 2026-08-03 | O28: 139315 | R28: 7 000 000.00 | S28: 0 | T28: 1 | V28: PRICTRL | W28: False | X28: DCG | Y28: E110_AP_DCOM | Z28: DCG-COM | AA28: NA | AC28: 1 | AD28: 7 000 000.00 | AE28: YASMG | AG28: FELANA13 | AH28: 7 000 000.00 | AI28: 7 000 000.00 | AK28: 46237 | AL28: 0000-00-00 | AM28: AFRICA DAY | AN28: YASSIE | AO28: YASSIE | AP28: C100 | AQ28: E110_AP_DCOM | AR28: DCG-COM | AS28: STD | AV28: E | AW28: E | AX28: Felana RARIVOSON | AY28: RAZAFINDRAHAGA Setra | BA28: 11533 | BB28: C100 | BC28: 7090 | BD28: 1 | BE28: 2026-07-29
A29: 136066 | B29: RAMANAMBONONA LALANIRIANA HANITRINIAINA | C29: ENTRETIEN ET REPARATION VEHICULE Y COMPRIS PIECES DE RECHAN | D29: ENTRETIEN MOTO - 15556WWT - MORONDAVA - PROFORMA N°111 | E29: 1 | F29: UN | G29: 817000 | I29: =E29*G29 -> 817000 | K29: MGA | L29: 0 | M29: 46237 | N29: 2026-08-03 | O29: 139310 | R29: 817 000.00 | S29: 0 | T29: 1 | V29: PRMVEHI | W29: True | X29: DCG | Y29: E222_DCG | Z29: DCG-SHS | AA29: NA | AC29: 1 | AD29: 817 000.00 | AE29: YASMG | AG29: FELANA13 | AH29: 817 000.00 | AI29: 817 000.00 | AK29: 46237 | AL29: 0000-00-00 | AM29: ENTRETIEN MOTO - MORONDAVA | AN29: YASSIE | AO29: YASSIE | AP29: C100 | AQ29: E222_DCG | AR29: DCG-SHS | AS29: STD | AV29: E | AW29: E | AX29: Felana RARIVOSON | AY29: RAZAFINDRAHAGA Setra | BA29: 1185 | BB29: C100 | BC29: 6740 | BD29: 1 | BE29: 2026-07-29
A30: 136067 | B30: MADAGASCAR AUTOMOBILE | C30: ENTRETIEN ET REPARATION VEHICULE Y COMPRIS PIECES DE RECHAN | D30: ENTRETIEN MOTO - 46608WWT - TANA - devis 1de2478442 du 13/07/2026 | E30: 1 | F30: UN | G30: 90500 | I30: =E30*G30 -> 90500 | K30: MGA | L30: 0 | M30: 46237 | N30: 2026-08-03 | O30: 139309 | R30: 108 600.00 | S30: 20 | T30: 1 | V30: PRMVEHI | W30: True | X30: DCG | Y30: E222_DCG | Z30: DCG-SHS | AA30: NA | AC30: 1 | AD30: 90 500.00 | AE30: YASMG | AG30: FELANA13 | AH30: 90 500.00 | AI30: 108 600.00 | AK30: 46237 | AL30: 0000-00-00 | AM30: ENTRETIEN MOTO - MBALIK | AN30: YASSIE | AO30: YASSIE | AP30: C100 | AQ30: E222_DCG | AR30: DCG-SHS | AS30: STD | AV30: E | AW30: E | AX30: Felana RARIVOSON | AY30: RAZAFINDRAHAGA Setra | BA30: 1185 | BB30: C100 | BC30: 1184 | BD30: 1 | BE30: 2026-07-29
A31: 136068 | B31: JUMELLES PRODUCTION | C31: SPONSORING | D31: Apport Numéraire FESTIVAL DONA BE - FACTURE N°12 | E31: 1 | F31: UN | G31: 40000000 | I31: =E31*G31 -> 40000000 | K31: MGA | L31: 0 | M31: 46237 | N31: 2026-08-12 | O31: 139337 | R31: 40 000 000.00 | S31: 0 | T31: 1 | V31: MECSPDC | W31: True | X31: DCG | Y31: E110_AC_DCOM | Z31: DCG-COM-PART | AA31: NA | AC31: 1 | AD31: 40 000 000.00 | AE31: YASMG | AG31: FELANA13 | AH31: 40 000 000.00 | AI31: 40 000 000.00 | AJ31: F | AK31: 46237 | AL31: 0000-00-00 | AM31: FESTIVAL DONA BE | AN31: YASSIE | AO31: YASSIE | AP31: C100 | AQ31: E110_AC_DCOM | AR31: DCG-COM-PART | AS31: STD | AV31: E | AW31: E | AX31: Felana RARIVOSON | AY31: RAZAFINDRAHAGA Setra | BA31: 1267 | BB31: C100 | BC31: 4323 | BD31: 1 | BE31: 2026-07-30
A32: 136069 | B32: MIDI PUBLICITE | C32: PUBLICITE ET ANNONCE | D32: Gazetiko 1/8 page Quadrichromie - FA N° FAC/2026/2997 | E32: 1 | F32: UN | G32: 6234785.4 | I32: =E32*G32 -> 6234785.4 | K32: MGA | L32: 0 | M32: 46237 | N32: 2026-08-03 | O32: 139307 | R32: 7 481 742.48 | S32: 20 | T32: 1 | V32: MEDMEDI | W32: True | X32: DCG | Y32: E110_MD_DCOM | Z32: DCG-COM-MEDIA | AA32: NA | AC32: 1 | AD32: 6 234 785.40 | AE32: YASMG | AG32: FELANA13 | AH32: 29 855 556.88 | AI32: 35 826 668.26 | AJ32: F | AK32: 46237 | AL32: 0000-00-00 | AM32: ANNULE ET REMPLACE DA 139119 | AN32: YASSIE | AO32: YASSIE | AP32: C100 | AQ32: E110_MD_DCOM | AR32: DCG-COM-MEDIA | AS32: STD | AV32: E | AW32: E | AX32: Felana RARIVOSON | AY32: RAZAFINDRAHAGA Setra | BA32: 1265 | BB32: C100 | BC32: 2566 | BD32: 1 | BE32: 2026-07-29
A33: 136069 | B33: MIDI PUBLICITE | C33: PUBLICITE ET ANNONCE | D33: Midi 1/8 page Quadrichromie - FA N° FAC/2026/2996 | E33: 1 | F33: UN | G33: 8314553.6 | I33: =E33*G33 -> 8314553.6 | K33: MGA | L33: 0 | M33: 46237 | N33: 2026-08-03 | O33: 139307 | R33: 9 977 464.32 | S33: 20 | T33: 2 | V33: MEDMEDI | W33: True | X33: DCG | Y33: E110_MD_DCOM | Z33: DCG-COM-MEDIA | AA33: NA | AC33: 1 | AD33: 8 314 553.60 | AE33: YASMG | AG33: FELANA13 | AH33: 29 855 556.88 | AI33: 35 826 668.26 | AJ33: F | AK33: 46237 | AL33: 0000-00-00 | AM33: ANNULE ET REMPLACE DA 139119 | AN33: YASSIE | AO33: YASSIE | AP33: C100 | AQ33: E110_MD_DCOM | AR33: DCG-COM-MEDIA | AS33: STD | AV33: E | AW33: E | AX33: Felana RARIVOSON | AY33: RAZAFINDRAHAGA Setra | BA33: 1265 | BB33: C100 | BC33: 2566 | BD33: 2 | BE33: 2026-07-29
A34: 136069 | B34: MIDI PUBLICITE | C34: PUBLICITE ET ANNONCE | D34: Gazetiko 1/8 page Quadrichromie - FA N° FAC/2026/3004 | E34: 1 | F34: UN | G34: 6607983 | I34: =E34*G34 -> 6607983 | K34: MGA | L34: 0 | M34: 46237 | N34: 2026-08-03 | O34: 139307 | R34: 7 929 579.60 | S34: 20 | T34: 3 | V34: MEDMEDI | W34: True | X34: DCG | Y34: E110_MD_DCOM | Z34: DCG-COM-MEDIA | AA34: NA | AC34: 1 | AD34: 6 607 983.00 | AE34: YASMG | AG34: FELANA13 | AH34: 29 855 556.88 | AI34: 35 826 668.26 | AJ34: F | AK34: 46237 | AL34: 0000-00-00 | AM34: ANNULE ET REMPLACE DA 139119 | AN34: YASSIE | AO34: YASSIE | AP34: C100 | AQ34: E110_MD_DCOM | AR34: DCG-COM-MEDIA | AS34: STD | AV34: E | AW34: E | AX34: Felana RARIVOSON | AY34: RAZAFINDRAHAGA Setra | BA34: 1265 | BB34: C100 | BC34: 2566 | BD34: 3 | BE34: 2026-07-29
A35: 136069 | B35: MIDI PUBLICITE | C35: PUBLICITE ET ANNONCE | D35: Midi 1/8 page Quadrichromie - FA N° FAC/2026/3003 | E35: 1 | F35: UN | G35: 8698234.9 | I35: =E35*G35 -> 8698234.9 | K35: MGA | L35: 0 | M35: 46237 | N35: 2026-08-03 | O35: 139307 | R35: 10 437 881.86 | S35: 20 | T35: 4 | V35: MEDMEDI | W35: True | X35: DCG | Y35: E110_MD_DCOM | Z35: DCG-COM-MEDIA | AA35: NA | AC35: 1 | AD35: 8 698 234.88 | AE35: YASMG | AG35: FELANA13 | AH35: 29 855 556.88 | AI35: 35 826 668.26 | AJ35: F | AK35: 46237 | AL35: 0000-00-00 | AM35: ANNULE ET REMPLACE DA 139119 | AN35: YASSIE | AO35: YASSIE | AP35: C100 | AQ35: E110_MD_DCOM | AR35: DCG-COM-MEDIA | AS35: STD | AV35: E | AW35: E | AX35: Felana RARIVOSON | AY35: RAZAFINDRAHAGA Setra | BA35: 1265 | BB35: C100 | BC35: 2566 | BD35: 4 | BE35: 2026-07-29
