Workbook

Sheet Base extract
A1: Designation_Complémentaire | B1: Remise | C1: Total_Ligne_HT_Remisé | D1: V_Total_Ligne_TTC | E1: TVA | F1: N__DA | G1: N__Poste_DA | H1: Site_Stock | I1: Code_ss_famille | J1: Saisie_de_réception__ | K1: Code_Direction | L1: Code_complément | M1: SS_compte_anal | N1: Centre_d_Analyse | O1: Accord_Cadre | P1: RAL | Q1: V_Montant_RAL | R1: Code_Société | S1: Avenant | T1: Acheteur | U1: Tot_CA_HT | V1: Tot_CA_TTC | W1: Devise | X1: Etat_Financ_ | Y1: Date_creat | Z1: Date_de_Validation | AA1: Date_Période | AB1: Date_AR | AC1: Objet_CA | AD1: Ctr_Emetteur_entete | AE1: Ctr_Livraison_entete | AF1: Sect_Imputation_entete | AG1: Code_Complémentaire_entete | AH1: Sous_Compte_d_Analyse_entete | AI1: Type_document | AJ1: V_Expédition_soldée | AK1: Code_du_Modèle_de_Cde | AL1: V_Etat_commande_en_tête | AM1: V_Etat_commande_ligne | AN1: Nom_Acheteur | AO1: Raison_sociale_Fournisseur | AP1: Nom_demandeur | AQ1: V_Critère_de_saisie | AR1: Code_Article | AS1: Quantité_comm | AT1: Unité | AU1: Prix_Unitaire | AV1: Design__sommaire | AW1: Section_d_imput | AX1: Code_Fournis | AY1: N__de_Cde | AZ1: N_Poste | BA1: Date_de_livr__prev_
A2: E-gaming stand fibre Tuléar - Référence n°016/2026/MFE | B2: 0 | C2: 8878000 | D2: 8 878 000.00 | E2: 0 | F2: 138683 | G2: 1 | I2: MECSPDC | J2: True | K2: DCG | L2: E250_DRB | M2: DCG-DRB | N2: NA | P2: 1 | Q2: 8 878 000.00 | R2: YASMG | T2: FELANA13 | U2: 8 878 000.00 | V2: 8 878 000.00 | W2: MGA | X2: F | Y2: 46204 | Z2: 2026-07-01 | AA2: 46204 | AB2: 0000-00-00 | AC2: E-gaming stand fibre  Tuléar | AD2: YASSIE | AE2: YASSIE | AF2: C102 | AG2: E250_DRB | AH2: DCG-DRB | AI2: STD | AL2: E | AM2: E | AN2: Felana RARIVOSON | AO2: MALAGASY FEDERATION OF ESPORTS | AP2: ANDRIAMIRIJA Luca | AR2: 1267 | AS2: 1 | AT2: UN | AU2: 8878000 | AV2: SPONSORING | AW2: C102 | AX2: 6306 | AY2: 135491 | AZ2: 1 | BA2: 2026-06-25
A3: CLIMATISATION SALLE SUPERVISION METIS BAZARY BE FORT DAUPHIN # Proforma MG-YAS-26-A3537-D0001 | B3: 0 | C3: 11716818 | D3: 14 060 181.56 | E3: 20 | F3: 138672 | G3: 1 | I3: PRICTRL | J3: True | K3: DTG | L3: 2026-DT-061005 | M3: DTG-DOM-NRJ | N3: NA | P3: 1 | Q3: 11 716 817.97 | R3: YASMG | T3: ELIE3 | U3: 11 716 817.97 | V3: 14 060 181.56 | W3: MGA | Y3: 46204 | Z3: 2026-07-01 | AA3: 46204 | AB3: 0000-00-00 | AC3: CLIMATISATION SALLE SUPERVISION METIS BAZARY BE FORT DAUPHIN | AD3: YASSIE | AE3: YASSIE | AF3: C500 | AG3: 2026-DT-061005 | AH3: DTG-DOM-NRJ | AI3: STD | AL3: E | AM3: E | AN3: ANDRIAMANANTSOA Elie | AO3: NEA MADAGASCAR SA | AP3: RAKOTOMALALA Tahiana Nalaina | AR3: 10668 | AS3: 1 | AT3: UN | AU3: 11716818 | AV3: MAINTENANCE ENERGIE | AW3: C500 | AX3: 36 | AY3: 135492 | AZ3: 1 | BA3: 0000-00-00
A4: Couverture de 11 mois (de février à décembre 2026) Désinsectisation, Dératisation et Désinfection) pour les 33 stores de TANA | B4: 0 | C4: 27225000 | D4: 27 225 000.00 | E4: 0 | F4: 138776 | G4: 1 | I4: PRMBATX | J4: True | K4: DFG | L4: E218_DAF | M4: DFGA-LOG | N4: NA | P4: 11 | Q4: 27 225 000.00 | R4: YASMG | T4: NADIA7 | U4: 27 225 000.00 | V4: 27 225 000.00 | W4: MGA | Y4: 46204 | Z4: 2026-07-01 | AA4: 46204 | AB4: 0000-00-00 | AC4: Prestations d'interventions 3D couverture 11 mois 2026 | AD4: YASSIE | AE4: YASSIE | AF4: C700 | AG4: E218_DAF | AH4: DFGA-LOG | AI4: STD | AL4: E | AM4: E | AN4: RAVONINJATOVO Nadia | AO4: RAMANOARY NY ANDO LALAINA | AP4: RAKOTOMALALA Manambina Tafitasoa | AR4: 22111 | AS4: 11 | AT4: UN | AU4: 2475000 | AV4: DESINFECTION SITE | AW4: C700 | AX4: 6147 | AY4: 135493 | AZ4: 1 | BA4: 2026-07-02
A5: Prestation Logistique Evènementielle - Foire de la Fibre Tuléar - devis n°519D/TELMA S.A (YAS)/26 du 29/06/2026 | B5: 0 | C5: 24470000 | D5: 24 470 000.00 | E5: 0 | F5: 138766 | G5: 1 | I5: PRICTRL | J5: True | K5: DCG | L5: E250_DRB | M5: DCG-DRB | N5: NA | P5: 1 | Q5: 24 470 000.00 | R5: YASMG | T5: FELANA13 | U5: 24 470 000.00 | V5: 24 470 000.00 | W5: MGA | X5: F | Y5: 46204 | Z5: 2026-07-06 | AA5: 46204 | AB5: 0000-00-00 | AC5: Sandix Sono - Foire de la Fibre Tulear | AD5: YASSIE | AE5: YASSIE | AF5: C102 | AG5: E250_DRB | AH5: DCG-DRB | AI5: STD | AL5: E | AM5: E | AN5: Felana RARIVOSON | AO5: RAJAOFETRA ANDRIANAINA Sandy (SANDIX) | AP5: ANDRIAMIRIJA Luca | AR5: 14862 | AS5: 1 | AT5: UN | AU5: 24470000 | AV5: PRESTATION DE SERVICE | AW5: C102 | AX5: 3968 | AY5: 135494 | AZ5: 1 | BA5: 2026-07-01
A6: EAU VIVE Eau De Source Naturelle 50 cl - Pack de 12 # DEVIS N° B-PR0626-0097 DU 24/06/2026 - Contact livraison 0340036090 | B6: 0 | C6: 203000 | D6: 243 600.00 | E6: 20 | F6: 138380 | G6: 1 | I6: PRICTRL | J6: True | K6: DCG | L6: E219_DCG | M6: DCG-SHS | N6: NA | P6: 0 | Q6: 0.00 | R6: YASMG | T6: NADIA7 | U6: 990 916.67 | V6: 1 189 100.00 | W6: MGA | X6: F | Y6: 46205 | Z6: 2026-07-02 | AA6: 46205 | AB6: 0000-00-00 | AC6: MBALIK COLLATION Q2 2026 | AD6: YASSIE | AE6: YASSIE | AF6: C100 | AG6: E219_DCG | AH6: DCG-SHS | AI6: STD | AL6: L | AM6: S | AN6: RAVONINJATOVO Nadia | AO6: MORA MARKET | AP6: RAZAFINDRAHAGA Setra | AR6: 16984 | AS6: 12 | AT6: UN | AU6: 16916.667 | AV6: EAU | AW6: C100 | AX6: 4245 | AY6: 135495 | AZ6: 1 | BA6: 0000-00-00
A7: EAU VIVE Eau de source naturelle 1,5 L - Pack de 6 | B7: 0 | C7: 290416.67 | D7: 348 500.00 | E7: 20 | F7: 138380 | G7: 2 | I7: PRICTRL | J7: True | K7: DCG | L7: E219_DCG | M7: DCG-SHS | N7: NA | P7: 0 | Q7: 0.00 | R7: YASMG | T7: NADIA7 | U7: 990 916.67 | V7: 1 189 100.00 | W7: MGA | X7: F | Y7: 46205 | Z7: 2026-07-02 | AA7: 46205 | AB7: 0000-00-00 | AC7: MBALIK COLLATION Q2 2026 | AD7: YASSIE | AE7: YASSIE | AF7: C100 | AG7: E219_DCG | AH7: DCG-SHS | AI7: STD | AL7: L | AM7: S | AN7: RAVONINJATOVO Nadia | AO7: MORA MARKET | AP7: RAZAFINDRAHAGA Setra | AR7: 16984 | AS7: 17 | AT7: UN | AU7: 17083.333 | AV7: EAU | AW7: C100 | AX7: 4245 | AY7: 135495 | AZ7: 2 | BA7: 0000-00-00
A8: TAF Thé Vert Nature Sahambavy 100 Infusettes | B8: 0 | C8: 106000 | D8: 127 200.00 | E8: 20 | F8: 138380 | G8: 3 | I8: FRNCALM | J8: True | K8: DCG | L8: E219_DCG | M8: DCG-SHS | N8: NA | P8: 4 | Q8: 106 000.00 | R8: YASMG | T8: NADIA7 | U8: 990 916.67 | V8: 1 189 100.00 | W8: MGA | X8: F | Y8: 46205 | Z8: 2026-07-02 | AA8: 46205 | AB8: 0000-00-00 | AC8: MBALIK COLLATION Q2 2026 | AD8: YASSIE | AE8: YASSIE | AF8: C100 | AG8: E219_DCG | AH8: DCG-SHS | AI8: STD | AL8: L | AM8: E | AN8: RAVONINJATOVO Nadia | AO8: MORA MARKET | AP8: RAZAFINDRAHAGA Setra | AR8: 3818 | AS8: 4 | AT8: UN | AU8: 26500 | AV8: THE | AW8: C100 | AX8: 4245 | AY8: 135495 | AZ8: 3 | BA8: 2026-06-11
A9: CHOCOLATERIE ROBERT Cacao en Poudre 100% 225 G | B9: 0 | C9: 30000 | D9: 36 000.00 | E9: 20 | F9: 138380 | G9: 4 | I9: FRNCALM | J9: True | K9: DCG | L9: E219_DCG | M9: DCG-SHS | N9: NA | P9: 2 | Q9: 30 000.00 | R9: YASMG | T9: NADIA7 | U9: 990 916.67 | V9: 1 189 100.00 | W9: MGA | X9: F | Y9: 46205 | Z9: 2026-07-02 | AA9: 46205 | AB9: 0000-00-00 | AC9: MBALIK COLLATION Q2 2026 | AD9: YASSIE | AE9: YASSIE | AF9: C100 | AG9: E219_DCG | AH9: DCG-SHS | AI9: STD | AL9: L | AM9: E | AN9: RAVONINJATOVO Nadia | AO9: MORA MARKET | AP9: RAZAFINDRAHAGA Setra | AR9: 3820 | AS9: 2 | AT9: UN | AU9: 15000 | AV9: CACAO | AW9: C100 | AX9: 4245 | AY9: 135495 | AZ9: 4 | BA9: 2026-06-11
A10: COMPAGNIE LE CAFÉ Café Classic 100% Pure 50?G | B10: 0 | C10: 245333.33 | D10: 294 400.00 | E10: 20 | F10: 138380 | G10: 5 | I10: FRNCALM | J10: True | K10: DCG | L10: E219_DCG | M10: DCG-SHS | N10: NA | P10: 16 | Q10: 245 333.33 | R10: YASMG | T10: NADIA7 | U10: 990 916.67 | V10: 1 189 100.00 | W10: MGA | X10: F | Y10: 46205 | Z10: 2026-07-02 | AA10: 46205 | AB10: 0000-00-00 | AC10: MBALIK COLLATION Q2 2026 | AD10: YASSIE | AE10: YASSIE | AF10: C100 | AG10: E219_DCG | AH10: DCG-SHS | AI10: STD | AL10: L | AM10: E | AN10: RAVONINJATOVO Nadia | AO10: MORA MARKET | AP10: RAZAFINDRAHAGA Setra | AR10: 3816 | AS10: 16 | AT10: UN | AU10: 15333.333 | AV10: CAFE | AW10: C100 | AX10: 4245 | AY10: 135495 | AZ10: 5 | BA10: 2026-06-11
A11: Sucre Roux Brésilien 1 KG | B11: 0 | C11: 11166.67 | D11: 13 400.00 | E11: 20 | F11: 138380 | G11: 6 | I11: FRNCALM | J11: True | K11: DCG | L11: E219_DCG | M11: DCG-SHS | N11: NA | P11: 2 | Q11: 11 166.67 | R11: YASMG | T11: NADIA7 | U11: 990 916.67 | V11: 1 189 100.00 | W11: MGA | X11: F | Y11: 46205 | Z11: 2026-07-02 | AA11: 46205 | AB11: 0000-00-00 | AC11: MBALIK COLLATION Q2 2026 | AD11: YASSIE | AE11: YASSIE | AF11: C100 | AG11: E219_DCG | AH11: DCG-SHS | AI11: STD | AL11: L | AM11: E | AN11: RAVONINJATOVO Nadia | AO11: MORA MARKET | AP11: RAZAFINDRAHAGA Setra | AR11: 1168 | AS11: 2 | AT11: PCE | AU11: 5583.3333 | AV11: SUCRE | AW11: C100 | AX11: 4245 | AY11: 135495 | AZ11: 6 | BA11: 2026-06-11
A12: DELICE Lait en poudre 1 kg | B12: 0 | C12: 105000 | D12: 126 000.00 | E12: 20 | F12: 138380 | G12: 7 | I12: FRNCALM | J12: True | K12: DCG | L12: E219_DCG | M12: DCG-SHS | N12: NA | P12: 3 | Q12: 105 000.00 | R12: YASMG | T12: NADIA7 | U12: 990 916.67 | V12: 1 189 100.00 | W12: MGA | X12: F | Y12: 46205 | Z12: 2026-07-02 | AA12: 46205 | AB12: 0000-00-00 | AC12: MBALIK COLLATION Q2 2026 | AD12: YASSIE | AE12: YASSIE | AF12: C100 | AG12: E219_DCG | AH12: DCG-SHS | AI12: STD | AL12: L | AM12: E | AN12: RAVONINJATOVO Nadia | AO12: MORA MARKET | AP12: RAZAFINDRAHAGA Setra | AR12: 1166 | AS12: 3 | AT12: PCE | AU12: 35000 | AV12: LAIT | AW12: C100 | AX12: 4245 | AY12: 135495 | AZ12: 7 | BA12: 2026-06-11
A13: LOCATION IMPRIMANTE Consommation RICOH et Loyer mensuel TELMA SA, mois de Mai2026# FACTURE N°F850913 DU 02/06/2026 | B13: 0 | C13: 24937884 | D13: 29 925 460.80 | E13: 20 | F13: 138757 | G13: 1 | I13: LOCLOCT | J13: True | K13: DSI | L13: E250_DSI | M13: DSI | N13: NA | P13: 1 | Q13: 24 937 884.00 | R13: YASMG | T13: NADIA7 | U13: 24 937 884.00 | V13: 29 925 460.80 | W13: MGA | X13: F | Y13: 46205 | Z13: 2026-07-03 | AA13: 46205 | AB13: 0000-00-00 | AC13: Consommation RICOH et Loyer mensuel TELMA SA - Mai2026 | AD13: YASSIE | AE13: YASSIE | AF13: C800 | AG13: E250_DSI | AH13: DSI | AI13: STD | AL13: E | AM13: E | AN13: RAVONINJATOVO Nadia | AO13: SOCIETE DE DISTRIBUTION DE MAD (SODIM SARLU) | AP13: NJIVA Mbolatiana | AR13: 6991 | AS13: 1 | AT13: UN | AU13: 24937884 | AV13: LOCATION IMPRIMANTE | AW13: C800 | AX13: 127 | AY13: 135496 | AZ13: 1 | BA13: 2026-06-30
A14: COLLATION LE 02 JUILLET 2026 - Assortiments 2 pièces salées et 1 pièce sucré avec jus de fruits# DEVIS DU 29/06/2026 | B14: 0 | C14: 2100000 | D14: 2 520 000.00 | E14: 20 | F14: 138760 | G14: 1 | I14: PRICTRL | J14: True | K14: DSI | L14: E219_DSI | M14: DSI | N14: NA | P14: 70 | Q14: 2 100 000.00 | R14: YASMG | T14: NADIA7 | U14: 2 100 000.00 | V14: 2 520 000.00 | W14: MGA | X14: F | Y14: 46205 | Z14: 2026-07-02 | AA14: 46205 | AB14: 0000-00-00 | AC14: Collation Conférence Data Protection et AI_02Juillet2026 | AD14: YASSIE | AE14: YASSIE | AF14: C800 | AG14: E219_DSI | AH14: DSI | AI14: STD | AL14: E | AM14: E | AN14: RAVONINJATOVO Nadia | AO14: SOCIETE DE GESTION ET EXPLOITATION DE M/CAR | AP14: NJIVA Mbolatiana | AR14: 6965 | AS14: 70 | AT14: UN | AU14: 30000 | AV14: PRESTATION DE SERVICES EXTERNE | AW14: C800 | AX14: 119 | AY14: 135497 | AZ14: 1 | BA14: 2026-06-30
A15: Location de véhicule{s ) avec carburant 03 Juillet 2026 - Galaxy/Analakely - Ambohimalaza - Remisage# DEVIS N°PROFORMA 017-2026 DU 01/07/2026 | B15: 0 | C15: 2100000 | D15: 2 100 000.00 | E15: 0 | F15: 138780 | G15: 1 | I15: LOCLOCT | J15: True | K15: DSI | L15: E222_DSI | M15: DSI | N15: NA | P15: 7 | Q15: 2 100 000.00 | R15: YASMG | T15: NADIA7 | U15: 2 120 000.00 | V15: 2 120 000.00 | W15: MGA | X15: F | Y15: 46205 | Z15: 2026-07-02 | AA15: 46205 | AB15: 0000-00-00 | AC15: Location Car pour TB DSI_03 Juillet 2026 | AD15: YASSIE | AE15: YASSIE | AF15: C800 | AG15: E222_DSI | AH15: DSI | AI15: STD | AL15: E | AM15: E | AN15: RAVONINJATOVO Nadia | AO15: EXCEL TRANSPORT et TRAVEL | AP15: NJIVA Mbolatiana | AR15: 10626 | AS15: 7 | AT15: PIE | AU15: 300000 | AV15: LOCATION DE VOITURE COURTE DUREE | AW15: C800 | AX15: 6060 | AY15: 135498 | AZ15: 1 | BA15: 2026-07-01
A16: Frais de retrait | B16: 0 | C16: 20000 | D16: 20 000.00 | E16: 0 | F16: 138780 | G16: 2 | I16: EVROEVR | J16: True | K16: DSI | L16: E222_DSI | M16: DSI | N16: NA | P16: 1 | Q16: 20 000.00 | R16: YASMG | T16: NADIA7 | U16: 2 120 000.00 | V16: 2 120 000.00 | W16: MGA | X16: F | Y16: 46205 | Z16: 2026-07-02 | AA16: 46205 | AB16: 0000-00-00 | AC16: Location Car pour TB DSI_03 Juillet 2026 | AD16: YASSIE | AE16: YASSIE | AF16: C800 | AG16: E222_DSI | AH16: DSI | AI16: STD | AL16: E | AM16: E | AN16: RAVONINJATOVO Nadia | AO16: EXCEL TRANSPORT et TRAVEL | AP16: NJIVA Mbolatiana | AR16: 4213 | AS16: 1 | AT16: UN | AU16: 20000 | AV16: FRAIS DIVERS | AW16: C800 | AX16: 6060 | AY16: 135498 | AZ16: 2 | BA16: 2026-07-01
... A20: Système de sonorisation pour interprétariat sonorisation | B20: 0 | C20: 700000 | D20: 700 000.00 | E20: 0 | F20: 138762 | G20: 4 | I20: PRICTRL | J20: True | K20: DSI | L20: 2026-CP-SECU-D | M20: DSI | N20: NA | P20: 1 | Q20: 700 000.00 | R20: YASMG | T20: NADIA7 | U20: 4 225 000.00 | V20: 4 225 000.00 | W20: MGA | X20: F | Y20: 46205 | Z20: 2026-07-02 | AA20: 46205 | AB20: 0000-00-00 | AC20: Conférence Data Protection et AI_02Juillet2026 | AD20: YASSIE | AE20: YASSIE | AF20: C800 | AG20: 2026-CP-SECU-D | AH20: DSI | AI20: STD | AL20: E | AM20: E | AN20: RAVONINJATOVO Nadia | AO20: ANDRIANARY VERO HAINGO TIANA | AP20: NJIVA Mbolatiana | AR20: 6965 | AS20: 1 | AT20: UN | AU20: 700000 | AV20: PRESTATION DE SERVICES EXTERNE | AW20: C800 | AX20: 4371 | AY20: 135499 | AZ20: 4 | BA20: 2026-06-30
A21: DA Erick ANDRINIRINA Develppeur fullstack SOKA juin 2026# FACTURE N° F2600006 DU 16/06/2026 | B21: 0 | C21: 7646040 | D21: 7 646 040.00 | E21: 0 | F21: 138740 | G21: 1 | I21: PRICTRL | J21: True | K21: DG | L21: E250_DJU | M21: DG-DJUR | N21: NA | P21: 1 | Q21: 7 646 040.00 | R21: YASMG | T21: NADIA7 | U21: 7 646 040.00 | V21: 7 646 040.00 | W21: MGA | X21: F | Y21: 46205 | Z21: 2026-07-02 | AA21: 46205 | AB21: 0000-00-00 | AD21: YASSIE | AE21: YASSIE | AF21: C400 | AG21: E250_DJU | AH21: DG-DJUR | AI21: STD | AL21: E | AM21: E | AN21: RAVONINJATOVO Nadia | AO21: ANDRINIRINA ERICK | AP21: RAKOTONIRINA Hasy | AR21: 14862 | AS21: 1 | AT21: UN | AU21: 7646040 | AV21: PRESTATION DE SERVICE | AW21: C400 | AX21: 6519 | AY21: 135500 | AZ21: 1 | BA21: 2026-06-30
A22: Pour engagement du devis pour la LLD Mr Ando RATSIRAHONANA# DEVIS N° V.26.21100 DU 11/06/2026 | B22: 0 | C22: 179400000 | D22: 215 280 000.00 | E22: 20 | F22: 138775 | G22: 1 | I22: LVHLLDX | J22: True | K22: DG | L22: LLD_DJU | M22: DG-DJUR | N22: NA | P22: 60 | Q22: 179 400 000.00 | R22: YASMG | T22: NADIA7 | U22: 179 400 000.00 | V22: 215 280 000.00 | W22: MGA | X22: F | Y22: 46205 | Z22: 2026-07-02 | AA22: 46205 | AB22: 0000-00-00 | AD22: YASSIE | AE22: YASSIE | AF22: C400 | AG22: LLD_DJU | AH22: DG-DJUR | AI22: STD | AL22: E | AM22: E | AN22: RAVONINJATOVO Nadia | AO22: OCEAN TRADE CO | AP22: RAKOTONIRINA Hasy | AR22: 1247 | AS22: 60 | AT22: UN | AU22: 2990000 | AV22: LOCATION VEHICULE LLD | AW22: C400 | AX22: 102 | AY22: 135501 | AZ22: 1 | BA22: 2026-07-01
A23: Billet d'avion - TNR/WMN/TNR - RAMAHEFARISOA HAJANIRINA | B23: 0 | C23: 1672100 | D23: 1 672 100.00 | E23: 0 | F23: 138720 | G23: 1 | I23: PRMEQUI | J23: False | K23: DCG | L23: E215_DCG | M23: DCG-BEF | N23: NA | P23: 0 | Q23: 0.00 | R23: YASMG | T23: FELANA13 | U23: 1 672 100.00 | V23: 1 672 100.00 | W23: MGA | X23: F | Y23: 46205 | Z23: 2026-07-02 | AA23: 46205 | AB23: 0000-00-00 | AC23: Billet d'avion - RAMAHEFARISOA HAJANIRINA | AD23: YASSIE | AE23: YASSIE | AF23: C100 | AG23: E215_DCG | AH23: DCG-BEF | AI23: VOLINT | AL23: S | AM23: S | AN23: Felana RARIVOSON | AO23: VOYAGES BOURDON | AP23: ANDRIAMIRIJA Luca | AR23: 17513 | AS23: 1 | AT23: PIE | AU23: 1672100 | AV23: BILLET D'AVION | AW23: C100 | AX23: 2886 | AY23: 135502 | AZ23: 1 | BA23: 2026-06-29
A24: Billet d'Avion - David Randriamialy - TNR/NOS/TNR | B24: 0 | C24: 2542500 | D24: 2 542 500.00 | E24: 0 | F24: 138782 | G24: 1 | I24: PRMEQUI | J24: False | K24: DCG | L24: E215_DCG | M24: DCG-COM | N24: NA | P24: 0 | Q24: 0.00 | R24: YASMG | T24: FELANA13 | U24: 2 542 500.00 | V24: 2 542 500.00 | W24: MGA | X24: F | Y24: 46205 | Z24: 2026-07-02 | AA24: 46205 | AB24: 0000-00-00 | AC24: Billet d'Avion - David Randriamialy | AD24: YASSIE | AE24: YASSIE | AF24: C100 | AG24: E215_DCG | AH24: DCG-COM | AI24: VOLINT | AL24: S | AM24: S | AN24: Felana RARIVOSON | AO24: VOYAGES BOURDON | AP24: ANDRIAMIRIJA Luca | AR24: 17513 | AS24: 1 | AT24: PIE | AU24: 2542500 | AV24: BILLET D'AVION | AW24: C100 | AX24: 2886 | AY24: 135503 | AZ24: 1 | BA24: 2026-07-01
A25: Achat billet d'avion Fenotiana Patrick suite affectation | B25: 0 | C25: 949300 | D25: 949 300.00 | E25: 0 | F25: 138790 | G25: 1 | I25: PRMEQUI | J25: False | K25: DTG | L25: E215_DTG | M25: DRH-ADMIN | N25: NA | P25: 0 | Q25: 0.00 | R25: YASMG | T25: NADIA7 | U25: 2 847 900.00 | V25: 2 847 900.00 | W25: MGA | X25: F | Y25: 46205 | Z25: 2026-07-02 | AA25: 46205 | AB25: 0000-00-00 | AD25: YASSIE | AE25: YASSIE | AF25: C500 | AG25: E215_DTG | AH25: DRH-ADMIN | AI25: VOLINT | AL25: S | AM25: S | AN25: RAVONINJATOVO Nadia | AO25: VOYAGES BOURDON | AP25: ANDRIANINA Rebecca | AR25: 17513 | AS25: 1 | AT25: PIE | AU25: 949300 | AV25: BILLET D'AVION | AW25: C500 | AX25: 2886 | AY25: 135504 | AZ25: 1 | BA25: 2026-07-02
A26: Achat billet d'avion Christin suite affectation | B26: 0 | C26: 949300 | D26: 949 300.00 | E26: 0 | F26: 138790 | G26: 2 | I26: PRMEQUI | J26: False | K26: DTG | L26: E215_DTG | M26: DRH-ADMIN | N26: NA | P26: 0 | Q26: 0.00 | R26: YASMG | T26: NADIA7 | U26: 2 847 900.00 | V26: 2 847 900.00 | W26: MGA | X26: F | Y26: 46205 | Z26: 2026-07-02 | AA26: 46205 | AB26: 0000-00-00 | AD26: YASSIE | AE26: YASSIE | AF26: C500 | AG26: E215_DTG | AH26: DRH-ADMIN | AI26: VOLINT | AL26: S | AM26: S | AN26: RAVONINJATOVO Nadia | AO26: VOYAGES BOURDON | AP26: ANDRIANINA Rebecca | AR26: 17513 | AS26: 1 | AT26: PIE | AU26: 949300 | AV26: BILLET D'AVION | AW26: C500 | AX26: 2886 | AY26: 135504 | AZ26: 2 | BA26: 2026-07-02
A27: Achat billet d'avion Fitoa Emmanuel suite affectation | B27: 0 | C27: 949300 | D27: 949 300.00 | E27: 0 | F27: 138790 | G27: 3 | I27: PRMEQUI | J27: False | K27: DTG | L27: E215_DTG | M27: DRH-ADMIN | N27: NA | P27: 0 | Q27: 0.00 | R27: YASMG | T27: NADIA7 | U27: 2 847 900.00 | V27: 2 847 900.00 | W27: MGA | X27: F | Y27: 46205 | Z27: 2026-07-02 | AA27: 46205 | AB27: 0000-00-00 | AD27: YASSIE | AE27: YASSIE | AF27: C500 | AG27: E215_DTG | AH27: DRH-ADMIN | AI27: VOLINT | AL27: S | AM27: S | AN27: RAVONINJATOVO Nadia | AO27: VOYAGES BOURDON | AP27: ANDRIANINA Rebecca | AR27: 17513 | AS27: 1 | AT27: PIE | AU27: 949300 | AV27: BILLET D'AVION | AW27: C500 | AX27: 2886 | AY27: 135504 | AZ27: 3 | BA27: 2026-07-02
A28: Sponsoring - IOAI Summit 2026 - FA n°EDS-2026-0604 | B28: 0 | C28: 5000000 | D28: 5 000 000.00 | E28: 0 | F28: 138700 | G28: 1 | I28: MECSPDC | J28: True | K28: DCG | L28: E110_PS_DCOM | M28: DCG-COM-PART | N28: NA | P28: 1 | Q28: 5 000 000.00 | R28: YASMG | T28: FELANA13 | U28: 5 000 000.00 | V28: 5 000 000.00 | W28: MGA | X28: F | Y28: 46205 | Z28: 2026-07-02 | AA28: 46205 | AB28: 0000-00-00 | AC28: Sponsoring - IOAI Summit 2026 | AD28: YASSIE | AE28: YASSIE | AF28: C100 | AG28: E110_PS_DCOM | AH28: DCG-COM-PART | AI28: STD | AL28: E | AM28: E | AN28: Felana RARIVOSON | AO28: EDS GROUP | AP28: ANDRIAMIRIJA Luca | AR28: 1267 | AS28: 1 | AT28: UN | AU28: 5000000 | AV28: SPONSORING | AW28: C100 | AX28: 7133 | AY28: 135505 | AZ28: 1 | BA28: 2026-06-29
A29: Prestation de sécurité Nuit - Foire de la Fibre à Tuléar le 05 au 08 juillet 2026 - Proforma N° 0232562512/26 | B29: 0 | C29: 900000 | D29: 1 080 000.00 | E29: 20 | F29: 138781 | G29: 1 | I29: PRICTRL | J29: True | K29: DCG | L29: E259_DRB | M29: DCG-DRB | N29: NA | P29: 20 | Q29: 900 000.00 | R29: YASMG | T29: FELANA13 | U29: 900 000.00 | V29: 1 080 000.00 | W29: MGA | Y29: 46205 | Z29: 2026-07-02 | AA29: 46205 | AB29: 0000-00-00 | AC29: Sécurisation Nuit - Foire de la Fibre | AD29: YASSIE | AE29: YASSIE | AF29: C102 | AG29: E259_DRB | AH29: DCG-DRB | AI29: STD | AL29: E | AM29: E | AN29: Felana RARIVOSON | AO29: SECUR PRO | AP29: ANDRIAMIRIJA Luca | AR29: 14862 | AS29: 20 | AT29: UN | AU29: 45000 | AV29: PRESTATION DE SERVICE | AW29: C102 | AX29: 2145 | AY29: 135506 | AZ29: 1 | BA29: 2026-07-01
A30: Cafe Nespresso - Collation Q2 - Proforma n°B-PR0626-0258 | B30: 0 | C30: 1944000 | D30: 2 332 800.00 | E30: 20 | F30: 138708 | G30: 1 | I30: FRNCALM | J30: True | K30: DCG | L30: E219_DCG | M30: DCG-PS | N30: NA | P30: 35 | Q30: 1 944 000.00 | R30: YASMG | T30: FELANA13 | U30: 1 944 000.00 | V30: 2 332 800.00 | W30: MGA | X30: F | Y30: 46205 | Z30: 2026-07-02 | AA30: 46205 | AB30: 0000-00-00 | AC30: Café Collation Q2 - MKT | AD30: YASSIE | AE30: YASSIE | AF30: C100 | AG30: E219_DCG | AH30: DCG-PS | AI30: STD | AL30: E | AM30: E | AN30: Felana RARIVOSON | AO30: MORA MARKET | AP30: ANDRIAMIRIJA Luca | AR30: 3653 | AS30: 35 | AT30: UN | AU30: 55542.857 | AV30: CAFE NESPRESSO | AW30: C100 | AX30: 4245 | AY30: 135507 | AZ30: 1 | BA30: 2026-06-29
A31: Devis acompte validé pour la LLD de Mr Gary CHEUK Location pour 60 mois# DEVIS N° PF24062026-009 EV DU 24/06/2026 | B31: 0 | C31: 42000000 | D31: 50 400 000.00 | E31: 20 | F31: 138807 | G31: 1 | I31: LVHLLDX | J31: True | K31: DG | L31: LLD_DJU | M31: DG-DJUR | N31: NA | P31: 1 | Q31: 42 000 000.00 | R31: YASMG | T31: NADIA7 | U31: 42 000 000.00 | V31: 50 400 000.00 | W31: MGA | Y31: 46205 | Z31: 2026-07-02 | AA31: 46205 | AB31: 0000-00-00 | AD31: YASSIE | AE31: YASSIE | AF31: C400 | AG31: LLD_DJU | AH31: DG-DJUR | AI31: STD | AL31: E | AM31: E | AN31: RAVONINJATOVO Nadia | AO31: LOXEA MADAGASCAR | AP31: RAKOTONIRINA Hasy | AR31: 1247 | AS31: 1 | AT31: UN | AU31: 42000000 | AV31: LOCATION VEHICULE LLD | AW31: C400 | AX31: 629 | AY31: 135508 | AZ31: 1 | BA31: 2026-07-02
A32: Devis N° V.26.16817 DU 11/05/2026 | B32: 0 | C32: 261000000 | D32: 313 200 000.00 | E32: 20 | F32: 138806 | G32: 1 | I32: LVHLLDX | J32: True | K32: DG | L32: LLD_DG | M32: DG | N32: NA | P32: 60 | Q32: 261 000 000.00 | R32: YASMG | T32: NADIA7 | U32: 261 000 000.00 | V32: 313 200 000.00 | W32: MGA | X32: F | Y32: 46206 | Z32: 2026-07-03 | AA32: 46206 | AB32: 0000-00-00 | AC32: LLD Richard FIENENA-OCEANTRADE | AD32: YASSIE | AE32: YASSIE | AF32: C900 | AG32: LLD_DG | AH32: DG | AI32: STD | AL32: E | AM32: E | AN32: RAVONINJATOVO Nadia | AO32: OCEAN TRADE CO | AP32: RASOLOJAONA Miora | AR32: 1247 | AS32: 60 | AT32: UN | AU32: 4350000 | AV32: LOCATION VEHICULE LLD | AW32: C900 | AX32: 102 | AY32: 135509 | AZ32: 1 | BA32: 2026-07-02
A33: Gestion Warehouse AGL Phoenix Février à septembre 2026 (8 mois) | B33: 0 | C33: 195471360 | D33: 234 565 632.00 | E33: 20 | F33: 138787 | G33: 1 | I33: PRICTRL | J33: True | K33: DFG | L33: E250_DAF | M33: DFGA-LOG | N33: NA | P33: 8 | Q33: 195 471 360.00 | R33: YASMG | T33: NADIA7 | U33: 781 885 440.00 | V33: 938 262 528.00 | W33: MGA | Y33: 46206 | Z33: 2026-07-03 | AA33: 46206 | AB33: 0000-00-00 | AC33: Gestion Warehouse AGL Phoenix | AD33: YASSIE | AE33: YASSIE | AF33: C700 | AG33: E250_DAF | AH33: DFGA-LOG | AI33: STD | AL33: E | AM33: E | AN33: RAVONINJATOVO Nadia | AO33: AFRICA GLOBAL LOGISTICS | AP33: RAKOTOMALALA Manambina Tafitasoa | AR33: 6965 | AS33: 8 | AT33: UN | AU33: 24433920 | AV33: PRESTATION DE SERVICES EXTERNE | AW33: C700 | AX33: 713 | AY33: 135510 | AZ33: 1 | BA33: 2026-07-31
A34: Gestion Warehouse AGL Phoenix Février 26 à février 27 (12 mois) | B34: 0 | C34: 586414080 | D34: 703 696 896.00 | E34: 20 | F34: 138787 | G34: 2 | I34: PRICTRL | J34: True | K34: DFG | L34: E250_DAF | M34: DFGA-LOG | N34: NA | P34: 12 | Q34: 586 414 080.00 | R34: YASMG | T34: NADIA7 | U34: 781 885 440.00 | V34: 938 262 528.00 | W34: MGA | Y34: 46206 | Z34: 2026-07-03 | AA34: 46206 | AB34: 0000-00-00 | AC34: Gestion Warehouse AGL Phoenix | AD34: YASSIE | AE34: YASSIE | AF34: C700 | AG34: E250_DAF | AH34: DFGA-LOG | AI34: STD | AL34: E | AM34: E | AN34: RAVONINJATOVO Nadia | AO34: AFRICA GLOBAL LOGISTICS | AP34: RAKOTOMALALA Manambina Tafitasoa | AR34: 6965 | AS34: 12 | AT34: UN | AU34: 48867840 | AV34: PRESTATION DE SERVICES EXTERNE | AW34: C700 | AX34: 713 | AY34: 135510 | AZ34: 2 | BA34: 2026-07-31
A35: CARREFOUR SENSATION Infusion Thé Noir Saveur Fruits Rouges x25# DEVIS N° B-PR0626-0098 DU 08/06/2026 | B35: 0 | C35: 174000 | D35: 208 800.00 | E35: 20 | F35: 138388 | G35: 1 | I35: FRNCALM | J35: True | K35: DCG | L35: E219_DCG | M35: DCG-COM | N35: NA | P35: 12 | Q35: 174 000.00 | R35: YASMG | T35: NADIA7 | U35: 1 665 166.67 | V35: 1 998 200.00 | W35: MGA | X35: F | Y35: 46206 | Z35: 2026-07-03 | AA35: 46206 | AB35: 0000-00-00 | AC35: ADN COLLATION Q2 2026 | AD35: YASSIE | AE35: YASSIE | AF35: C100 | AG35: E219_DCG | AH35: DCG-COM | AI35: STD | AL35: E | AM35: E | AN35: RAVONINJATOVO Nadia | AO35: MORA MARKET | AP35: RAZAFINDRAHAGA Setra | AR35: 3818 | AS35: 12 | AT35: UN | AU35: 14500 | AV35: THE | AW35: C100 | AX35: 4245 | AY35: 135511 | AZ35: 1 | BA35: 2026-06-11
A36: COTTERLEY Thé Vert Agrumes 25 Sachets | B36: 0 | C36: 57000 | D36: 68 400.00 | E36: 20 | F36: 138388 | G36: 2 | I36: FRNCALM | J36: True | K36: DCG | L36: E219_DCG | M36: DCG-COM | N36: NA | P36: 6 | Q36: 57 000.00 | R36: YASMG | T36: NADIA7 | U36: 1 665 166.67 | V36: 1 998 200.00 | W36: MGA | X36: F | Y36: 46206 | Z36: 2026-07-03 | AA36: 46206 | AB36: 0000-00-00 | AC36: ADN COLLATION Q2 2026 | AD36: YASSIE | AE36: YASSIE | AF36: C100 | AG36: E219_DCG | AH36: DCG-COM | AI36: STD | AL36: E | AM36: E | AN36: RAVONINJATOVO Nadia | AO36: MORA MARKET | AP36: RAZAFINDRAHAGA Setra | AR36: 3818 | AS36: 6 | AT36: UN | AU36: 9500 | AV36: THE | AW36: C100 | AX36: 4245 | AY36: 135511 | AZ36: 2 | BA36: 2026-06-11
A37: COTTERLEY Thé Vert Subtilement Aromatisé 32,5?g X25 Sachets | B37: 0 | C37: 59500 | D37: 71 400.00 | E37: 20 | F37: 138388 | G37: 3 | I37: FRNCALM | J37: True | K37: DCG | L37: E219_DCG | M37: DCG-COM | N37: NA | P37: 6 | Q37: 59 500.00 | R37: YASMG | T37: NADIA7 | U37: 1 665 166.67 | V37: 1 998 200.00 | W37: MGA | X37: F | Y37: 46206 | Z37: 2026-07-03 | AA37: 46206 | AB37: 0000-00-00 | AC37: ADN COLLATION Q2 2026 | AD37: YASSIE | AE37: YASSIE | AF37: C100 | AG37: E219_DCG | AH37: DCG-COM | AI37: STD | AL37: E | AM37: E | AN37: RAVONINJATOVO Nadia | AO37: MORA MARKET | AP37: RAZAFINDRAHAGA Setra | AR37: 3818 | AS37: 6 | AT37: UN | AU37: 9916.6667 | AV37: THE | AW37: C100 | AX37: 4245 | AY37: 135511 | AZ37: 3 | BA37: 2026-06-11
A38: CHOCOLATERIE ROBERT Cacao en Poudre 100% 225 G | B38: 0 | C38: 195000 | D38: 234 000.00 | E38: 20 | F38: 138388 | G38: 4 | I38: FRNCALM | J38: True | K38: DCG | L38: E219_DCG | M38: DCG-COM | N38: NA | P38: 13 | Q38: 195 000.00 | R38: YASMG | T38: NADIA7 | U38: 1 665 166.67 | V38: 1 998 200.00 | W38: MGA | X38: F | Y38: 46206 | Z38: 2026-07-03 | AA38: 46206 | AB38: 0000-00-00 | AC38: ADN COLLATION Q2 2026 | AD38: YASSIE | AE38: YASSIE | AF38: C100 | AG38: E219_DCG | AH38: DCG-COM | AI38: STD | AL38: E | AM38: E | AN38: RAVONINJATOVO Nadia | AO38: MORA MARKET | AP38: RAZAFINDRAHAGA Setra | AR38: 3820 | AS38: 13 | AT38: UN | AU38: 15000 | AV38: CACAO | AW38: C100 | AX38: 4245 | AY38: 135511 | AZ38: 4 | BA38: 2026-06-11
A39: COMPAGNIE LE CAFÉ Café Classic 100% Pure 50G | B39: 0 | C39: 368000 | D39: 441 600.00 | E39: 20 | F39: 138388 | G39: 5 | I39: FRNCALM | J39: True | K39: DCG | L39: E219_DCG | M39: DCG-COM | N39: NA | P39: 24 | Q39: 368 000.00 | R39: YASMG | T39: NADIA7 | U39: 1 665 166.67 | V39: 1 998 200.00 | W39: MGA | X39: F | Y39: 46206 | Z39: 2026-07-03 | AA39: 46206 | AB39: 0000-00-00 | AC39: ADN COLLATION Q2 2026 | AD39: YASSIE | AE39: YASSIE | AF39: C100 | AG39: E219_DCG | AH39: DCG-COM | AI39: STD | AL39: E | AM39: E | AN39: RAVONINJATOVO Nadia | AO39: MORA MARKET | AP39: RAZAFINDRAHAGA Setra | AR39: 3816 | AS39: 24 | AT39: UN | AU39: 15333.333 | AV39: CAFE | AW39: C100 | AX39: 4245 | AY39: 135511 | AZ39: 5 | BA39: 2026-06-11
A40: Sucre Roux Brésilien 1 KG | B40: 0 | C40: 111666.67 | D40: 134 000.00 | E40: 20 | F40: 138388 | G40: 6 | I40: FRNCALM | J40: True | K40: DCG | L40: E219_DCG | M40: DCG-COM | N40: NA | P40: 20 | Q40: 111 666.67 | R40: YASMG | T40: NADIA7 | U40: 1 665 166.67 | V40: 1 998 200.00 | W40: MGA | X40: F | Y40: 46206 | Z40: 2026-07-03 | AA40: 46206 | AB40: 0000-00-00 | AC40: ADN COLLATION Q2 2026 | AD40: YASSIE | AE40: YASSIE | AF40: C100 | AG40: E219_DCG | AH40: DCG-COM | AI40: STD | AL40: E | AM40: E | AN40: RAVONINJATOVO Nadia | AO40: MORA MARKET | AP40: RAZAFINDRAHAGA Setra | AR40: 1168 | AS40: 20 | AT40: PCE | AU40: 5583.3333 | AV40: SUCRE | AW40: C100 | AX40: 4245 | AY40: 135511 | AZ40: 6 | BA40: 2026-06-11
A41: DELICE Lait en poudre 1 kg | B41: 0 | C41: 700000 | D41: 840 000.00 | E41: 20 | F41: 138388 | G41: 7 | I41: FRNCALM | J41: True | K41: DCG | L41: E219_DCG | M41: DCG-COM | N41: NA | P41: 20 | Q41: 700 000.00 | R41: YASMG | T41: NADIA7 | U41: 1 665 166.67 | V41: 1 998 200.00 | W41: MGA | X41: F | Y41: 46206 | Z41: 2026-07-03 | AA41: 46206 | AB41: 0000-00-00 | AC41: ADN COLLATION Q2 2026 | AD41: YASSIE | AE41: YASSIE | AF41: C100 | AG41: E219_DCG | AH41: DCG-COM | AI41: STD | AL41: E | AM41: E | AN41: RAVONINJATOVO Nadia | AO41: MORA MARKET | AP41: RAZAFINDRAHAGA Setra | AR41: 1166 | AS41: 20 | AT41: PCE | AU41: 35000 | AV41: LAIT | AW41: C100 | AX41: 4245 | AY41: 135511 | AZ41: 7 | BA41: 2026-06-11
A42: Billet d'avion - RAKOTOMIHAMINA ANDO - TNR/TLE/TNR | B42: 0 | C42: 2258500 | D42: 2 258 500.00 | E42: 0 | F42: 138813 | G42: 1 | I42: PRMEQUI | J42: False | K42: DCG | L42: E215_DCG | M42: DCG-PS | N42: NA | P42: 1 | Q42: 2 258 500.00 | R42: YASMG | T42: FELANA13 | U42: 2 258 500.00 | V42: 2 258 500.00 | W42: MGA | X42: F | Y42: 46206 | Z42: 2026-07-03 | AA42: 46206 | AB42: 0000-00-00 | AC42: Billet d'Avion - RAKOTOMIHAMINA ANDO | AD42: YASSIE | AE42: YASSIE | AF42: C100 | AG42: E215_DCG | AH42: DCG-PS | AI42: VOLINT | AL42: Z | AM42: Z | AN42: Felana RARIVOSON | AO42: VOYAGES BOURDON | AP42: ANDRIAMIRIJA Luca | AR42: 17513 | AS42: 1 | AT42: PIE | AU42: 2258500 | AV42: BILLET D'AVION | AW42: C100 | AX42: 2886 | AY42: 135512 | AZ42: 1 | BA42: 2026-07-03
A43: COFI 2026 - PIAGGIO APE 3 WHEELER MODEL - GRS RISE SERVICES - DEVIS DVISIE0226-002019 DU 13/06/2026 | B43: 0 | C43: 13250000 | D43: 15 900 000.00 | E43: 20 | F43: 138617 | G43: 1 | I43: PRMVEHI | J43: True | K43: DCG | L43: 2026-COFI | M43: DCG-DVI | N43: NA | P43: 1 | Q43: 13 250 000.00 | R43: YASMG | T43: FELANA13 | U43: 13 250 000.00 | V43: 15 900 000.00 | W43: MGA | X43: F | Y43: 46206 | Z43: 2026-07-06 | AA43: 46206 | AB43: 0000-00-00 | AC43: COFI 2026 - GRS RISE SERVICES | AD43: YASSIE | AE43: GALE | AF43: C104 | AG43: 2026-COFI | AH43: DCG-DVI | AI43: STD | AL43: E | AM43: E | AN43: Felana RARIVOSON | AO43: CT MOTORS | AP43: RAZAFINDRAHAGA Setra | AR43: 4155 | AS43: 1 | AT43: UN | AU43: 13250000 | AV43: MOTO | AW43: C104 | AX43: 664 | AY43: 135513 | AZ43: 1 | BA43: 2026-06-22
...

Sheet Base traitement
A1: N__de_Cde | B1: Raison_sociale_Fournisseur | C1: Design__sommaire | D1: Designation_Complémentaire | E1: Quantité_comm | F1: Unité | G1: Prix_Unitaire | H1: PU_USD | I1: Total_HT_USD_Neg | J1: Total_HT_USD | K1: Valeur_remise_USD | L1: %remise | M1: Remise | N1: Devise | O1: Date_creat_BC | P1: Date_de_Validation_BC | Q1: V_Etat_commande_en_tête | R1: V_Etat_commande_ligne | S1: Nom_demandeur | T1: N__DA | U1: Date_creation_DA | V1: Date_Validation_DA | W1: Code_Direction | X1: Acheteur | Y1: Nom_Acheteur | Z1: V_Total_Ligne_TTC | AA1: TVA | AB1: N__Poste_DA | AC1: Site_Stock | AD1: Code_ss_famille | AE1: Saisie_de_réception__ | AF1: Code_complément | AG1: SS_compte_anal | AH1: Centre_d_Analyse | AI1: Accord_Cadre | AJ1: RAL | AK1: V_Montant_RAL | AL1: Code_Société | AM1: Avenant | AN1: Tot_CA_HT | AO1: Tot_CA_TTC | AP1: Etat_Financ_ | AQ1: Date_Période | AR1: Date_AR | AS1: Objet_CA | AT1: Ctr_Emetteur_entete | AU1: Ctr_Livraison_entete | AV1: Sect_Imputation_entete | AW1: Code_Complémentaire_entete | AX1: Sous_Compte_d_Analyse_entete | AY1: Type_document | AZ1: V_Expédition_soldée | BA1: Code_du_Modèle_de_Cde | BB1: V_Critère_de_saisie | BC1: Code_Article | BD1: Section_d_imput | BE1: Code_Fournis | BF1: N_Poste | BG1: Date_de_livr__prev_
A2: 135730 | B2: SANIFER | C2: REMISE | D2: REMISE | E2: 1 | F2: UN | G2: -45000 | H2: =IF(N2="USD",G2,IF(N2="MGA",G2/4600,IF(N2="EUR",G2*1.17,IF(N2="GBP",G2*1.35,"")))) -> -9.7826087 | I2: =H2*E2 -> -9.7826087 | J2: 9.7826087 | K2: =I2*(-1) -> 9.7826087 | M2: 0 | N2: MGA | O2: 46217 | P2: 2026-07-14 | Q2: E | R2: E | S2: RABIANOAVY Nasandratra Henintsoa | T2: 138912 | W2: DTG | X2: ELIE3 | Y2: ANDRIAMANANTSOA Elie | Z2: -54 000.00 | AA2: 20 | AB2: 0 | AD2: GELACCS | AE2: True | AF2: 2026-DT-103002 | AG2: DTG-DSTC-INTER | AH2: NA | AJ2: 1 | AK2: -45 000.00 | AL2: YASMG | AN2: 405 000.00 | AO2: 486 000.00 | AP2: F | AQ2: 46217 | AR2: 0000-00-00 | AS2: DSTC-SEI: Achat Urgente PRISE RJ45 CAT6 mosaïque | AT2: YASSIE | AU2: GALE | AV2: C500 | AW2: 2026-DT-103002 | AX2: DTG-DSTC-INTER | AY2: STD | BC2: 2057 | BD2: C500 | BE2: 116 | BF2: 2 | BG2: 2026-07-15
A3: 136018 | B3: PELCOM INTERNATIONAL SARL (OXEO) | C3: REMISE | E3: 1 | F3: UN | G3: -56000 | H3: =IF(N3="USD",G3,IF(N3="MGA",G3/4600,IF(N3="EUR",G3*1.17,IF(N3="GBP",G3*1.35,"")))) -> -12.173913 | I3: =H3*E3 -> -12.173913 | J3: 12.173913 | K3: =I3*(-1) -> 12.173913 | M3: 0 | N3: MGA | O3: 46233 | P3: 2026-07-30 | Q3: E | R3: E | T3: 0 | W3: DFG | X3: NADIA7 | Y3: RAVONINJATOVO Nadia | Z3: -67 200.00 | AA3: 20 | AB3: 0 | AD3: GELACCS | AE3: True | AF3: E218_DAF | AG3: DFG-DAF | AH3: NA | AJ3: 1 | AK3: -56 000.00 | AL3: YASMG | AN3: 1 060 000.00 | AO3: 1 272 000.00 | AP3: F | AQ3: 46233 | AR3: 0000-00-00 | AS3: DEVIS MICRO CASQUE_TEAM RECOUVREMENT_JUILLET 2026 | AT3: YASSIE | AU3: YASSIE | AV3: C700 | AW3: E218_DAF | AX3: DFG-DAF | AY3: STD | BC3: 2057 | BD3: C700 | BE3: 2079 | BF3: 2 | BG3: 2026-08-03
A4: 135643 | B4: PRIMA CE SARLU | C4: REMISE | D4: Remise 7% | E4: 1 | F4: UN | G4: -59500 | H4: =IF(N4="USD",G4,IF(N4="MGA",G4/4600,IF(N4="EUR",G4*1.17,IF(N4="GBP",G4*1.35,"")))) -> -12.934783 | I4: =H4*E4 -> -12.934783 | J4: 12.934783 | K4: =I4*(-1) -> 12.934783 | M4: 0 | N4: MGA | O4: 46210 | P4: 2026-07-07 | Q4: S | R4: S | S4: RASAMOELINA Haritsoa Oliva | T4: 138675 | W4: DTG | X4: ELIE3 | Y4: ANDRIAMANANTSOA Elie | Z4: -71 400.00 | AA4: 20 | AB4: 2 | AD4: GELACCS | AE4: True | AF4: 2026-DT-022001 | AG4: DTG-PROJETS | AH4: NA | AJ4: 0 | AK4: 0.00 | AL4: YASMG | AN4: 790 500.00 | AO4: 948 600.00 | AQ4: 46210 | AR4: 0000-00-00 | AS4: Tirage FO entre RDC et salle trans 2ème Etages | AT4: YASSIE | AU4: YASSIE | AV4: C500 | AW4: 2026-DT-022001 | AX4: DTG-PROJETS | AY4: STD | BC4: 2057 | BD4: C500 | BE4: 2633 | BF4: 2 | BG4: 0000-00-00
A5: 136016 | B5: CT MOTORS | C5: REMISE | D5: Remise 5% | E5: 1 | F5: UN | G5: -73333.337 | H5: =IF(N5="USD",G5,IF(N5="MGA",G5/4600,IF(N5="EUR",G5*1.17,IF(N5="GBP",G5*1.35,"")))) -> -15.94203 | I5: =H5*E5 -> -15.94203 | J5: 15.94203 | K5: =I5*(-1) -> 15.94203 | M5: 0 | N5: MGA | O5: 46232 | P5: 2026-07-29 | Q5: E | R5: E | S5: RASAMOELINA Haritsoa Oliva | T5: 139280 | W5: DTG | X5: ELIE3 | Y5: ANDRIAMANANTSOA Elie | Z5: -88 000.00 | AA5: 20 | AB5: 2 | AD5: GELACCS | AE5: True | AF5: E218_DTG | AG5: DTG | AH5: NA | AJ5: 1 | AK5: -73 333.34 | AL5: YASMG | AN5: 1 393 333.40 | AO5: 1 672 000.09 | AP5: F | AQ5: 46232 | AR5: 0000-00-00 | AS5: Achat Gant Street Black (22 paires)-motards Tanà | AT5: YASSIE | AU5: GALE | AV5: C500 | AW5: E218_DTG | AX5: DTG | AY5: STD | BC5: 2057 | BD5: C500 | BE5: 664 | BF5: 2 | BG5: 2026-08-04
A6: 135649 | B6: UNITE DE DISTRIBUTION TECHNOLOGIQUE - UDITEC | C6: REMISE | D6: Remise | E6: 1 | F6: UN | G6: -134750 | H6: =IF(N6="USD",G6,IF(N6="MGA",G6/4600,IF(N6="EUR",G6*1.17,IF(N6="GBP",G6*1.35,"")))) -> -29.293478 | I6: =H6*E6 -> -29.293478 | J6: 29.293478 | K6: =I6*(-1) -> 29.293478 | M6: 0 | N6: MGA | O6: 46211 | P6: 2026-07-08 | Q6: E | R6: E | S6: RASAMOELINA Haritsoa Oliva | T6: 138778 | W6: DTG | X6: ELIE3 | Y6: ANDRIAMANANTSOA Elie | Z6: -161 700.00 | AA6: 20 | AB6: 2 | AD6: GELACCS | AE6: True | AF6: 2026-DT-061003 | AG6: DTG-DOM | AH6: NA | AJ6: 1 | AK6: -134 750.00 | AL6: YASMG | AN6: 1 212 749.98 | AO6: 1 455 299.98 | AP6: F | AQ6: 46211 | AR6: 0000-00-00 | AS6: Achat 03 armoire basse PM -DOM Diégo&Ambilobe | AT6: YASSIE | AU6: GALE | AV6: C500 | AW6: 2026-DT-061003 | AX6: DTG-DOM | AY6: STD | BC6: 2057 | BD6: C500 | BE6: 717 | BF6: 2 | BG6: 2026-07-10
A7: 136000 | B7: UNITE DE DISTRIBUTION TECHNOLOGIQUE - UDITEC | C7: REMISE | D7: Remise | E7: 1 | F7: UN | G7: -154000 | H7: =IF(N7="USD",G7,IF(N7="MGA",G7/4600,IF(N7="EUR",G7*1.17,IF(N7="GBP",G7*1.35,"")))) -> -33.478261 | I7: =H7*E7 -> -33.478261 | J7: 33.478261 | K7: =I7*(-1) -> 33.478261 | M7: 0 | N7: MGA | O7: 46232 | P7: 2026-07-29 | Q7: E | R7: E | S7: RASAMOELINA Haritsoa Oliva | T7: 139275 | W7: DTG | X7: ELIE3 | Y7: ANDRIAMANANTSOA Elie | Z7: -184 800.00 | AA7: 20 | AB7: 2 | AD7: GELACCS | AE7: True | AF7: 2026-DT-061003 | AG7: DTG-DOM | AH7: NA | AJ7: 1 | AK7: -154 000.00 | AL7: YASMG | AN7: 1 386 000.00 | AO7: 1 663 200.00 | AP7: F | AQ7: 46232 | AR7: 0000-00-00 | AS7: Achat 4 onduleurs pour Data Center Nosy Be | AT7: YASSIE | AU7: GALE | AV7: C500 | AW7: 2026-DT-061003 | AX7: DTG-DOM | AY7: STD | BC7: 2057 | BD7: C500 | BE7: 717 | BF7: 2 | BG7: 2026-08-04
A8: 136001 | B8: BATIMAX | C8: REMISE | D8: Remise | E8: 1 | F8: UN | G8: -178749.99 | H8: =IF(N8="USD",G8,IF(N8="MGA",G8/4600,IF(N8="EUR",G8*1.17,IF(N8="GBP",G8*1.35,"")))) -> -38.858694 | I8: =H8*E8 -> -38.858694 | J8: 38.858694 | K8: =I8*(-1) -> 38.858694 | M8: 0 | N8: MGA | O8: 46232 | P8: 2026-07-29 | Q8: E | R8: E | S8: RASAMOELINA Haritsoa Oliva | T8: 139168 | W8: DTG | X8: ELIE3 | Y8: ANDRIAMANANTSOA Elie | Z8: -214 499.99 | AA8: 20 | AB8: 4 | AD8: GELACCS | AE8: True | AF8: E218_DTG | AG8: DTG | AH8: NA | AJ8: 1 | AK8: -178 749.99 | AL8: YASMG | AN8: 2 204 583.27 | AO8: 2 645 499.93 | AQ8: 46232 | AR8: 0000-00-00 | AS8: Achat chaussures de sécurité-motards TANA | AT8: YASSIE | AU8: GALE | AV8: C500 | AW8: E218_DTG | AX8: DTG | AY8: STD | BC8: 2057 | BD8: C500 | BE8: 16 | BF8: 4 | BG8: 2026-07-31
A9: 135739 | B9: PRIMA CE SARLU | C9: REMISE | D9: Remise 7% | E9: 1 | F9: UN | G9: -290626 | H9: =IF(N9="USD",G9,IF(N9="MGA",G9/4600,IF(N9="EUR",G9*1.17,IF(N9="GBP",G9*1.35,"")))) -> -63.179565 | I9: =H9*E9 -> -63.179565 | J9: 63.179565 | K9: =I9*(-1) -> 63.179565 | M9: 0 | N9: MGA | O9: 46217 | P9: 2026-07-14 | Q9: L | R9: S | S9: RASAMOELINA Haritsoa Oliva | T9: 138981 | W9: DTG | X9: ELIE3 | Y9: ANDRIAMANANTSOA Elie | Z9: -348 751.20 | AA9: 20 | AB9: 2 | AD9: GELACCS | AE9: True | AF9: 2026-DT-022001 | AG9: DTG-PROJETS | AH9: NA | AJ9: 0 | AK9: 0.00 | AL9: YASMG | AN9: 3 861 174.00 | AO9: 4 633 408.80 | AQ9: 46217 | AR9: 0000-00-00 | AS9: TX GC FO sur VAK140 ABE ANDRAIKIBA | AT9: YASSIE | AU9: YASSIE | AV9: C500 | AW9: 2026-DT-022001 | AX9: DTG-PROJETS | AY9: STD | BC9: 2057 | BD9: C500 | BE9: 2633 | BF9: 2 | BG9: 0000-00-00
A10: 135787 | B10: COLIS EXPRESS | C10: REMISE | E10: 1 | F10: UN | G10: -327125 | H10: =IF(N10="USD",G10,IF(N10="MGA",G10/4600,IF(N10="EUR",G10*1.17,IF(N10="GBP",G10*1.35,"")))) -> -71.11413 | I10: =H10*E10 -> -71.11413 | J10: 71.11413 | K10: =I10*(-1) -> 71.11413 | M10: 0 | N10: MGA | O10: 46218 | P10: 2026-07-15 | Q10: E | R10: E | T10: 0 | W10: DCG | X10: NADIA7 | Y10: RAVONINJATOVO Nadia | Z10: -392 550.00 | AA10: 20 | AB10: 0 | AD10: GELACCS | AE10: True | AF10: E254_DCG | AG10: DRH-ADMIN | AH10: NA | AJ10: 1 | AK10: -327 125.00 | AL10: YASMG | AN10: 1 500 000.00 | AO10: 1 800 000.00 | AQ10: 46218 | AR10: 0000-00-00 | AT10: YASSIE | AU10: YASSIE | AV10: C104 | AW10: E254_DCG | AX10: DRH-ADMIN | AY10: STD | BC10: 2057 | BD10: C104 | BE10: 30 | BF10: 2 | BG10: 2026-06-29
A11: 135735 | B11: SOCIETE DE METALLURGIE DE L OCEAN INDIEN (ABC | C11: REMISE | D11: REMISE (15%*123916.67*18) | E11: 1 | F11: UN | G11: -334575.01 | H11: =IF(N11="USD",G11,IF(N11="MGA",G11/4600,IF(N11="EUR",G11*1.17,IF(N11="GBP",G11*1.35,"")))) -> -72.733698 | I11: =H11*E11 -> -72.733698 | J11: 72.733698 | K11: =I11*(-1) -> 72.733698 | M11: 0 | N11: MGA | O11: 46217 | P11: 2026-07-14 | Q11: E | R11: E | S11: RABIANOAVY Nasandratra Henintsoa | T11: 138913 | W11: DTG | X11: ELIE3 | Y11: ANDRIAMANANTSOA Elie | Z11: -401 490.01 | AA11: 20 | AB11: 0 | AD11: GELACCS | AE11: True | AF11: 2026-DT-103002 | AG11: DTG-DSTC-INTER | AH11: NA | AJ11: 1 | AK11: -334 575.01 | AL11: YASMG | AN11: 1 895 925.05 | AO11: 2 275 110.06 | AQ11: 46217 | AR11: 0000-00-00 | AS11: DSTC-SEI: Achat Urgente GOULOTTE CLIPPAGE DIRECT DLP 85X50 | AT11: YASSIE | AU11: GALE | AV11: C500 | AW11: 2026-DT-103002 | AX11: DTG-DSTC-INTER | AY11: STD | BC11: 2057 | BD11: C500 | BE11: 1 | BF11: 2 | BG11: 2026-07-15
A12: 135737 | B12: EASY NETCOM | C12: REMISE | D12: Remise 5% | E12: 1 | F12: UN | G12: -336696 | H12: =IF(N12="USD",G12,IF(N12="MGA",G12/4600,IF(N12="EUR",G12*1.17,IF(N12="GBP",G12*1.35,"")))) -> -73.194783 | I12: =H12*E12 -> -73.194783 | J12: 73.194783 | K12: =I12*(-1) -> 73.194783 | M12: 0 | N12: MGA | O12: 46217 | P12: 2026-07-14 | Q12: L | R12: S | S12: RASAMOELINA Haritsoa Oliva | T12: 138982 | W12: DTG | X12: ELIE3 | Y12: ANDRIAMANANTSOA Elie | Z12: -404 035.20 | AA12: 20 | AB12: 5 | AD12: GELACCS | AE12: True | AF12: 2026-DT-022001 | AG12: DTG-PROJETS | AH12: NA | AJ12: 0 | AK12: 0.00 | AL12: YASMG | AN12: 6 397 232.00 | AO12: 7 676 678.40 | AQ12: 46217 | AR12: 0000-00-00 | AS12: TX GC FO BOE141 Croisement Tsaratanana | AT12: YASSIE | AU12: YASSIE | AV12: C500 | AW12: 2026-DT-022001 | AX12: DTG-PROJETS | AY12: STD | BC12: 2057 | BD12: C500 | BE12: 2053 | BF12: 5 | BG12: 0000-00-00
A13: 136033 | B13: PRIMA CE SARLU | C13: REMISE | D13: Remise 7% | E13: 1 | F13: UN | G13: -431200 | H13: =IF(N13="USD",G13,IF(N13="MGA",G13/4600,IF(N13="EUR",G13*1.17,IF(N13="GBP",G13*1.35,"")))) -> -93.73913 | I13: =H13*E13 -> -93.73913 | J13: 93.73913 | K13: =I13*(-1) -> 93.73913 | M13: 0 | N13: MGA | O13: 46233 | P13: 2026-07-30 | Q13: E | R13: E | S13: RASAMOELINA Haritsoa Oliva | T13: 139245 | W13: DTG | X13: ELIE3 | Y13: ANDRIAMANANTSOA Elie | Z13: -517 440.00 | AA13: 20 | AB13: 5 | AD13: GELACCS | AE13: True | AF13: 2026-DT-022001 | AG13: DTG-PROJETS | AH13: NA | AJ13: 1 | AK13: -431 200.00 | AL13: YASMG | AN13: 5 728 800.00 | AO13: 6 874 560.00 | AQ13: 46233 | AR13: 0000-00-00 | AS13: TX GC FO AAT066 AMPOROFORO | AT13: YASSIE | AU13: YASSIE | AV13: C500 | AW13: 2026-DT-022001 | AX13: DTG-PROJETS | AY13: STD | BC13: 2057 | BD13: C500 | BE13: 2633 | BF13: 5 | BG13: 0000-00-00
A14: 135572 | B14: SOCIETE QUBETA IMPORT-EXPORT SARLU | C14: REMISE | D14: Remise | E14: 1 | F14: UN | G14: -474000 | H14: =IF(N14="USD",G14,IF(N14="MGA",G14/4600,IF(N14="EUR",G14*1.17,IF(N14="GBP",G14*1.35,"")))) -> -103.04348 | I14: =H14*E14 -> -103.04348 | J14: 103.04348 | K14: =I14*(-1) -> 103.04348 | M14: 0 | N14: MGA | O14: 46209 | P14: 2026-07-06 | Q14: E | R14: E | S14: RASAMOELINA Haritsoa Oliva | T14: 138809 | W14: DTG | X14: ELIE3 | Y14: ANDRIAMANANTSOA Elie | Z14: -568 800.00 | AA14: 20 | AB14: 3 | AD14: GELACCS | AE14: True | AF14: 2026-DT-061003 | AG14: DTG-DOM | AH14: NA | AJ14: 1 | AK14: -474 000.00 | AL14: YASMG | AN14: 4 266 000.00 | AO14: 5 119 200.00 | AP14: F | AQ14: 46209 | AR14: 0000-00-00 | AS14: Achats mobiliers de bureau-DOM BRICKAVILLE | AT14: YASSIE | AU14: GALE | AV14: C500 | AW14: 2026-DT-061003 | AX14: DTG-DOM | AY14: STD | BC14: 2057 | BD14: C500 | BE14: 3052 | BF14: 3 | BG14: 2026-07-10
A15: 135982 | B15: FITAHIA FANOMEZANTSOA NIRINA BIEN AIME | C15: REMISE | E15: 1 | F15: UN | G15: -500000 | H15: =IF(N15="USD",G15,IF(N15="MGA",G15/4600,IF(N15="EUR",G15*1.17,IF(N15="GBP",G15*1.35,"")))) -> -108.69565 | I15: =H15*E15 -> -108.69565 | J15: 108.69565 | K15: =I15*(-1) -> 108.69565 | M15: 0 | N15: MGA | O15: 46230 | P15: 2026-08-03 | Q15: E | R15: E | T15: 0 | W15: DCG | X15: FELANA13 | Y15: Felana RARIVOSON | Z15: -500 000.00 | AA15: 0 | AB15: 0 | AD15: GELACCS | AE15: True | AF15: E110_PRO_DCOM | AG15: DCG-COM | AH15: NA | AJ15: 1 | AK15: -500 000.00 | AL15: YASMG | AN15: 700 000.00 | AO15: 700 000.00 | AP15: F | AQ15: 46230 | AR15: 0000-00-00 | AS15: Couverture Photos le 11 et 18 juillet 2026 | AT15: YASSIE | AU15: YASSIE | AV15: C100 | AW15: E110_PRO_DCOM | AX15: DCG-COM | AY15: STD | BC15: 2057 | BD15: C100 | BE15: 5633 | BF15: 3 | BG15: 2026-07-31
A16: 136013 | B16: HASSANALY CHAHICK (LUXOR) | C16: REMISE | D16: Remise 15% | E16: 1 | F16: UN | G16: -556875 | H16: =IF(N16="USD",G16,IF(N16="MGA",G16/4600,IF(N16="EUR",G16*1.17,IF(N16="GBP",G16*1.35,"")))) -> -121.05978 | I16: =H16*E16 -> -121.05978 | J16: 121.05978 | K16: =I16*(-1) -> 121.05978 | M16: 0 | N16: MGA | O16: 46232 | P16: 2026-07-29 | Q16: E | R16: E | S16: RASAMOELINA Haritsoa Oliva | T16: 139223 | W16: DTG | X16: ELIE3 | Y16: ANDRIAMANANTSOA Elie | Z16: -668 250.00 | AA16: 20 | AB16: 2 | AD16: GELACCS | AE16: True | AF16: 2026-DT-061003 | AG16: DTG-DOM | AH16: NA | AJ16: 1 | AK16: -556 875.00 | AL16: YASMG | AN16: 3 155 625.00 | AO16: 3 786 750.00 | AP16: F | AQ16: 46232 | AR16: 0000-00-00 | AS16: Achat Vestiaire métal 2 étage-Fort Dauphin et les BV | AT16: YASSIE | AU16: GALE | AV16: C500 | AW16: 2026-DT-061003 | AX16: DTG-DOM | AY16: STD | BC16: 2057 | BD16: C500 | BE16: 75 | BF16: 2 | BG16: 2026-08-04
A17: 135738 | B17: PRIMA CE SARLU | C17: REMISE | D17: Remise 7% | E17: 1 | F17: UN | G17: -685510 | H17: =IF(N17="USD",G17,IF(N17="MGA",G17/4600,IF(N17="EUR",G17*1.17,IF(N17="GBP",G17*1.35,"")))) -> -149.02391 | I17: =H17*E17 -> -149.02391 | J17: 149.02391 | K17: =I17*(-1) -> 149.02391 | M17: 0 | N17: MGA | O17: 46217 | P17: 2026-07-14 | Q17: S | R17: S | S17: RASAMOELINA Haritsoa Oliva | T17: 138979 | W17: DTG | X17: ELIE3 | Y17: ANDRIAMANANTSOA Elie | Z17: -822 612.00 | AA17: 20 | AB17: 2 | AD17: GELACCS | AE17: True | AF17: 2026-DT-022001 | AG17: DTG-PROJETS | AH17: NA | AJ17: 0 | AK17: 0.00 | AL17: YASMG | AN17: 9 107 490.00 | AO17: 10 928 988.00 | AQ17: 46217 | AR17: 0000-00-00 | AS17: TX GC FO sur VAK138 VINANY | AT17: YASSIE | AU17: YASSIE | AV17: C500 | AW17: 2026-DT-022001 | AX17: DTG-PROJETS | AY17: STD | BC17: 2057 | BD17: C500 | BE17: 2633 | BF17: 2 | BG17: 0000-00-00
A18: 135918 | B18: HENRI FRAISE FILS ET CIE | C18: REMISE | D18: REMISE EXCEPTIONNELLE | E18: 1 | F18: UN | G18: -755291 | H18: =IF(N18="USD",G18,IF(N18="MGA",G18/4600,IF(N18="EUR",G18*1.17,IF(N18="GBP",G18*1.35,"")))) -> -164.1937 | I18: =H18*E18 -> -164.1937 | J18: 164.1937 | K18: =I18*(-1) -> 164.1937 | M18: 0 | N18: MGA | O18: 46225 | P18: 2026-07-22 | Q18: E | R18: E | S18: RAKOTOMALALA Tahiana Nalaina | T18: 139061 | W18: DTG | X18: ELIE3 | Y18: ANDRIAMANANTSOA Elie | Z18: -906 349.20 | AA18: 20 | AB18: 2 | AD18: GELACCS | AE18: True | AF18: 2026-DT-061005 | AG18: DTG-DOM-NRJ | AH18: NA | AJ18: 1 | AK18: -755 291.00 | AL18: YASMG | AN18: 14 350 523.00 | AO18: 17 220 627.60 | AP18: F | AQ18: 46225 | AR18: 0000-00-00 | AS18: ACHAT INVERSEUR DE SOURCE AUTOMATIQUE ATI 63A | AT18: YASSIE | AU18: GALE | AV18: C500 | AW18: 2026-DT-061005 | AX18: DTG-DOM-NRJ | AY18: STD | BC18: 2057 | BD18: C500 | BE18: 703 | BF18: 2 | BG18: 2026-07-31
A19: 135733 | B19: QUINCAILLERIE 2000 | C19: REMISE | D19: Remise 10% | E19: 1 | F19: UN | G19: -780000 | H19: =IF(N19="USD",G19,IF(N19="MGA",G19/4600,IF(N19="EUR",G19*1.17,IF(N19="GBP",G19*1.35,"")))) -> -169.56522 | I19: =H19*E19 -> -169.56522 | J19: 169.56522 | K19: =I19*(-1) -> 169.56522 | M19: 0 | N19: MGA | O19: 46217 | P19: 2026-07-14 | Q19: E | R19: E | S19: RASAMOELINA Haritsoa Oliva | T19: 138939 | W19: DTG | X19: ELIE3 | Y19: ANDRIAMANANTSOA Elie | Z19: -936 000.00 | AA19: 20 | AB19: 2 | AD19: GELACCS | AE19: True | AF19: 2026-DT-101001 | AG19: DTG-DSTC-INSTA | AH19: NA | AJ19: 1 | AK19: -780 000.00 | AL19: YASMG | AN19: 7 020 000.00 | AO19: 8 424 000.00 | AQ19: 46217 | AR19: 0000-00-00 | AS19: Achat moulure 25x16 pr les installations | AT19: YASSIE | AU19: GALE | AV19: C500 | AW19: 2026-DT-101001 | AX19: DTG-DSTC-INSTA | AY19: STD | BC19: 2057 | BD19: C500 | BE19: 1817 | BF19: 2 | BG19: 2026-07-20
A20: 135713 | B20: ICHTUS SERVICE | C20: REMISE | D20: REMISE | E20: 20 | F20: UN | G20: -44000 | H20: =IF(N20="USD",G20,IF(N20="MGA",G20/4600,IF(N20="EUR",G20*1.17,IF(N20="GBP",G20*1.35,"")))) -> -9.5652174 | I20: =H20*E20 -> -191.30435 | J20: 191.30435 | K20: =I20*(-1) -> 191.30435 | M20: 0 | N20: MGA | O20: 46216 | P20: 2026-07-13 | Q20: E | R20: E | S20: RANDRIARIMALALA Prisca | T20: 138914 | W20: DTG | X20: ELIE3 | Y20: ANDRIAMANANTSOA Elie | Z20: -880 000.00 | AA20: 0 | AB20: 0 | AD20: GELACCS | AE20: True | AF20: 2025-DT-021011 | AG20: DTG-PROJETS | AH20: NA | AJ20: 20 | AK20: -880 000.00 | AL20: YASMG | AN20: 10 920 000.00 | AO20: 10 920 000.00 | AP20: F | AQ20: 46216 | AR20: 0000-00-00 | AS20: BC ICHTUS - Confection support d'antenne STARLINK__Phoenix | AT20: YASSIE | AU20: GALE | AV20: C500 | AW20: 2025-DT-021011 | AX20: DTG-PROJETS | AY20: STD | BC20: 2057 | BD20: C500 | BE20: 6102 | BF20: 2 | BG20: 2026-07-17
A21: 136032 | B21: SOCIETE DE METALLURGIE DE L OCEAN INDIEN (ABC | C21: REMISE | D21: Remise | E21: 1 | F21: UN | G21: -1125000 | H21: =IF(N21="USD",G21,IF(N21="MGA",G21/4600,IF(N21="EUR",G21*1.17,IF(N21="GBP",G21*1.35,"")))) -> -244.56522 | I21: =H21*E21 -> -244.56522 | J21: 244.56522 | K21: =I21*(-1) -> 244.56522 | M21: 0 | N21: MGA | O21: 46233 | P21: 2026-07-30 | Q21: E | R21: E | S21: RASAMOELINA Haritsoa Oliva | T21: 139230 | W21: DTG | X21: ELIE3 | Y21: ANDRIAMANANTSOA Elie | Z21: -1 350 000.00 | AA21: 20 | AB21: 2 | AD21: GELACCS | AE21: True | AF21: 2026-DT-061003 | AG21: DTG-DOM | AH21: NA | AJ21: 1 | AK21: -1 125 000.00 | AL21: YASMG | AN21: 6 375 000.00 | AO21: 7 650 000.00 | AQ21: 46233 | AR21: 0000-00-00 | AS21: Achat Rack 19"//42U Indoor(Normalisation-Rack-DataCenter) | AT21: YASSIE | AU21: GALE | AV21: C500 | AW21: 2026-DT-061003 | AX21: DTG-DOM | AY21: STD | BC21: 2057 | BD21: C500 | BE21: 1 | BF21: 2 | BG21: 2026-08-06
A22: 136003 | B22: PRIMA CE SARLU | C22: REMISE | D22: Remise 7% | E22: 1 | F22: UN | G22: -1748985 | H22: =IF(N22="USD",G22,IF(N22="MGA",G22/4600,IF(N22="EUR",G22*1.17,IF(N22="GBP",G22*1.35,"")))) -> -380.21413 | I22: =H22*E22 -> -380.21413 | J22: 380.21413 | K22: =I22*(-1) -> 380.21413 | M22: 0 | N22: MGA | O22: 46232 | P22: 2026-07-29 | Q22: L | R22: S | S22: RASAMOELINA Haritsoa Oliva | T22: 139211 | W22: DTG | X22: ELIE3 | Y22: ANDRIAMANANTSOA Elie | Z22: -2 098 782.00 | AA22: 20 | AB22: 5 | AD22: GELACCS | AE22: True | AF22: 2026-DT-022001 | AG22: DTG-PROJETS | AH22: NA | AJ22: 0 | AK22: 0.00 | AL22: YASMG | AN22: 23 236 515.00 | AO22: 27 883 818.00 | AQ22: 46232 | AR22: 0000-00-00 | AS22: Travaux GC FO sur IHO058 AMBINANY(COHAB HELIOS) | AT22: YASSIE | AU22: YASSIE | AV22: C500 | AW22: 2026-DT-022001 | AX22: DTG-PROJETS | AY22: STD | BC22: 2057 | BD22: C500 | BE22: 2633 | BF22: 5 | BG22: 0000-00-00
A23: 135968 | B23: PRIMA CE SARLU | C23: REMISE | D23: Remise 15% | E23: 1 | F23: UN | G23: -3273900 | H23: =IF(N23="USD",G23,IF(N23="MGA",G23/4600,IF(N23="EUR",G23*1.17,IF(N23="GBP",G23*1.35,"")))) -> -711.71739 | I23: =H23*E23 -> -711.71739 | J23: 711.71739 | K23: =I23*(-1) -> 711.71739 | M23: 0 | N23: MGA | O23: 46226 | P23: 2026-07-23 | Q23: L | R23: S | S23: RASAMOELINA Haritsoa Oliva | T23: 139132 | W23: DTG | X23: ELIE3 | Y23: ANDRIAMANANTSOA Elie | Z23: -3 928 680.00 | AA23: 20 | AB23: 2 | AD23: GELACCS | AE23: True | AF23: 2026-DT-022001 | AG23: DTG-PROJETS | AH23: NA | AJ23: 0 | AK23: 0.00 | AL23: YASMG | AN23: 18 552 100.00 | AO23: 22 262 520.00 | AQ23: 46226 | AR23: 0000-00-00 | AS23: TX GC FO sur SOF225 ANALAMISONDROTRA | AT23: YASSIE | AU23: YASSIE | AV23: C500 | AW23: 2026-DT-022001 | AX23: DTG-PROJETS | AY23: STD | BC23: 2057 | BD23: C500 | BE23: 2633 | BF23: 2 | BG23: 0000-00-00
A24: 135532 | B24: SMTP | C24: REMISE | D24: REMISE | E24: 1 | F24: UN | G24: -3792000 | H24: =IF(N24="USD",G24,IF(N24="MGA",G24/4600,IF(N24="EUR",G24*1.17,IF(N24="GBP",G24*1.35,"")))) -> -824.34783 | I24: =H24*E24 -> -824.34783 | J24: 824.34783 | K24: =I24*(-1) -> 824.34783 | M24: 0 | N24: MGA | O24: 46209 | P24: 2026-07-06 | Q24: E | R24: E | S24: RASAMOELINA Haritsoa Oliva | T24: 138767 | W24: DTG | X24: ELIE3 | Y24: ANDRIAMANANTSOA Elie | Z24: -4 550 400.00 | AA24: 20 | AB24: 3 | AD24: GELACCS | AE24: True | AF24: 2026-DT-102001 | AG24: DTG-DOM | AH24: NA | AJ24: 1 | AK24: -3 792 000.00 | AL24: YASMG | AN24: 15 309 570.00 | AO24: 18 371 484.00 | AP24: F | AQ24: 46209 | AR24: 0000-00-00 | AS24: Achat de Tuyaux PEHD | AT24: YASSIE | AU24: GALE | AV24: C500 | AW24: 2026-DT-102001 | AX24: DTG-DOM | AY24: STD | BC24: 2057 | BD24: C500 | BE24: 1893 | BF24: 3 | BG24: 2026-07-06
A25: 135651 | B25: PRIMA CE SARLU | C25: REMISE | D25: Remise 12% | E25: 1 | F25: UN | G25: -4329240 | H25: =IF(N25="USD",G25,IF(N25="MGA",G25/4600,IF(N25="EUR",G25*1.17,IF(N25="GBP",G25*1.35,"")))) -> -941.13913 | I25: =H25*E25 -> -941.13913 | J25: 941.13913 | K25: =I25*(-1) -> 941.13913 | M25: 0 | N25: MGA | O25: 46211 | P25: 2026-07-08 | Q25: L | R25: S | S25: RASAMOELINA Haritsoa Oliva | T25: 138788 | W25: DTG | X25: ELIE3 | Y25: ANDRIAMANANTSOA Elie | Z25: -5 195 088.00 | AA25: 20 | AB25: 2 | AD25: GELACCS | AE25: True | AF25: 2025-DT-021010 | AG25: DTG-PROJETS | AH25: NA | AJ25: 0 | AK25: 0.00 | AL25: YASMG | AN25: 31 747 760.00 | AO25: 38 097 312.00 | AQ25: 46211 | AR25: 0000-00-00 | AS25: TX GC FO entre ANM012 Alarobia et ANM002 | AT25: YASSIE | AU25: YASSIE | AV25: C500 | AW25: 2025-DT-021010 | AX25: DTG-PROJETS | AY25: STD | BC25: 2057 | BD25: C500 | BE25: 2633 | BF25: 2 | BG25: 0000-00-00
A26: 136039 | B26: EASY NETCOM | C26: REMISE | D26: Remise 12% | E26: 1 | F26: UN | G26: -4534181 | H26: =IF(N26="USD",G26,IF(N26="MGA",G26/4600,IF(N26="EUR",G26*1.17,IF(N26="GBP",G26*1.35,"")))) -> -985.69152 | I26: =H26*E26 -> -985.69152 | J26: 985.69152 | K26: =I26*(-1) -> 985.69152 | M26: 0 | N26: MGA | O26: 46233 | P26: 2026-07-30 | Q26: E | R26: E | S26: RASAMOELINA Haritsoa Oliva | T26: 139301 | W26: DTG | X26: ELIE3 | Y26: ANDRIAMANANTSOA Elie | Z26: -5 441 017.20 | AA26: 20 | AB26: 4 | AD26: GELACCS | AE26: True | AF26: 2026-DT-022001 | AG26: DTG-PROJETS | AH26: NA | AJ26: 1 | AK26: -4 534 181.00 | AL26: YASMG | AN26: 33 250 657.00 | AO26: 39 900 788.40 | AQ26: 46233 | AR26: 0000-00-00 | AS26: TX GC FO ANO005_MARILLAC | AT26: YASSIE | AU26: YASSIE | AV26: C500 | AW26: 2026-DT-022001 | AX26: DTG-PROJETS | AY26: STD | BC26: 2057 | BD26: C500 | BE26: 2053 | BF26: 4 | BG26: 0000-00-00
A27: 135742 | B27: FRANCE PUB | C27: REMISE | D27: Remise | E27: 1 | F27: UN | G27: -5378760 | H27: =IF(N27="USD",G27,IF(N27="MGA",G27/4600,IF(N27="EUR",G27*1.17,IF(N27="GBP",G27*1.35,"")))) -> -1169.2957 | I27: =H27*E27 -> -1169.2957 | J27: 1169.2957 | K27: =I27*(-1) -> 1169.2957 | M27: 0 | N27: MGA | O27: 46217 | P27: 2026-07-14 | Q27: E | R27: E | S27: RASAMOELINA Haritsoa Oliva | T27: 139004 | W27: DTG | X27: ELIE3 | Y27: ANDRIAMANANTSOA Elie | Z27: -6 454 512.00 | AA27: 20 | AB27: 2 | AD27: GELACCS | AE27: True | AF27: 2026-DT-091006 | AG27: DTG-PROJETS | AH27: NA | AJ27: 1 | AK27: -5 378 760.00 | AL27: YASMG | AN27: 31 979 640.00 | AO27: 38 375 568.00 | AQ27: 46217 | AR27: 0000-00-00 | AS27: Lightbox Yas Campus Galaxy Andraharo | AT27: YASSIE | AU27: YASSIE | AV27: C500 | AW27: 2026-DT-091006 | AX27: DTG-PROJETS | AY27: STD | BC27: 2057 | BD27: C500 | BE27: 3678 | BF27: 2 | BG27: 2026-07-20
A28: 135745 | B28: PRIMA CE SARLU | C28: REMISE | D28: Remise 30% | E28: 1 | F28: UN | G28: -5887200 | H28: =IF(N28="USD",G28,IF(N28="MGA",G28/4600,IF(N28="EUR",G28*1.17,IF(N28="GBP",G28*1.35,"")))) -> -1279.8261 | I28: =H28*E28 -> -1279.8261 | J28: 1279.8261 | K28: =I28*(-1) -> 1279.8261 | M28: 0 | N28: MGA | O28: 46217 | P28: 2026-07-14 | Q28: L | R28: S | S28: RASAMOELINA Haritsoa Oliva | T28: 138960 | W28: DTG | X28: ELIE3 | Y28: ANDRIAMANANTSOA Elie | Z28: -7 064 640.00 | AA28: 20 | AB28: 2 | AD28: GELACCS | AE28: True | AF28: E314_DTG | AG28: DTG-DOM | AH28: NA | AJ28: 0 | AK28: 0.00 | AL28: YASMG | AN28: 13 736 800.00 | AO28: 16 484 160.00 | AP28: F | AQ28: 46217 | AR28: 0000-00-00 | AS28: TX GC BKB SOANIERANA IVONGO - MANANARA NORD | AT28: YASSIE | AU28: YASSIE | AV28: C500 | AW28: E314_DTG | AX28: DTG-DOM | AY28: STD | BC28: 2057 | BD28: C500 | BE28: 2633 | BF28: 2 | BG28: 0000-00-00
A29: 135970 | B29: EASY NETCOM | C29: REMISE | D29: Remise 15% | E29: 1 | F29: UN | G29: -6210566 | H29: =IF(N29="USD",G29,IF(N29="MGA",G29/4600,IF(N29="EUR",G29*1.17,IF(N29="GBP",G29*1.35,"")))) -> -1350.123 | I29: =H29*E29 -> -1350.123 | J29: 1350.123 | K29: =I29*(-1) -> 1350.123 | M29: 0 | N29: MGA | O29: 46226 | P29: 2026-07-23 | Q29: L | R29: S | S29: RASAMOELINA Haritsoa Oliva | T29: 139141 | W29: DTG | X29: ELIE3 | Y29: ANDRIAMANANTSOA Elie | Z29: -7 452 679.20 | AA29: 20 | AB29: 5 | AD29: GELACCS | AE29: True | AF29: 2026-DT-022001 | AG29: DTG-PROJETS | AH29: NA | AJ29: 0 | AK29: 0.00 | AL29: YASMG | AN29: 35 193 206.00 | AO29: 42 231 847.20 | AQ29: 46226 | AR29: 0000-00-00 | AS29: TX GC FO sur VAK134 ANJOMA RAMARTINA 2 | AT29: YASSIE | AU29: YASSIE | AV29: C500 | AW29: 2026-DT-022001 | AX29: DTG-PROJETS | AY29: STD | BC29: 2057 | BD29: C500 | BE29: 2053 | BF29: 5 | BG29: 0000-00-00
A30: 136011 | B30: PRIMA CE SARLU | C30: REMISE | D30: Remise 15% | E30: 1 | F30: UN | G30: -6250125 | H30: =IF(N30="USD",G30,IF(N30="MGA",G30/4600,IF(N30="EUR",G30*1.17,IF(N30="GBP",G30*1.35,"")))) -> -1358.7228 | I30: =H30*E30 -> -1358.7228 | J30: 1358.7228 | K30: =I30*(-1) -> 1358.7228 | M30: 0 | N30: MGA | O30: 46232 | P30: 2026-07-29 | Q30: L | R30: S | S30: RASAMOELINA Haritsoa Oliva | T30: 139210 | W30: DTG | X30: ELIE3 | Y30: ANDRIAMANANTSOA Elie | Z30: -7 500 150.00 | AA30: 20 | AB30: 5 | AD30: GELACCS | AE30: True | AF30: 2026-DT-022001 | AG30: DTG-PROJETS | AH30: NA | AJ30: 0 | AK30: 0.00 | AL30: YASMG | AN30: 35 417 375.00 | AO30: 42 500 850.00 | AQ30: 46232 | AR30: 0000-00-00 | AS30: TX GC FO sur SOF229 Ambodiampana | AT30: YASSIE | AU30: YASSIE | AV30: C500 | AW30: 2026-DT-022001 | AX30: DTG-PROJETS | AY30: STD | BC30: 2057 | BD30: C500 | BE30: 2633 | BF30: 5 | BG30: 0000-00-00
A31: 135575 | B31: AVRA BTP | C31: REMISE | E31: 1 | F31: UN | G31: -6555930.4 | H31: =IF(N31="USD",G31,IF(N31="MGA",G31/4600,IF(N31="EUR",G31*1.17,IF(N31="GBP",G31*1.35,"")))) -> -1425.2023 | I31: =H31*E31 -> -1425.2023 | J31: 1425.2023 | K31: =I31*(-1) -> 1425.2023 | M31: 0 | N31: MGA | O31: 46209 | P31: 2026-07-06 | Q31: E | R31: E | T31: 0 | W31: DFG | X31: NADIA7 | Y31: RAVONINJATOVO Nadia | Z31: -6 555 930.40 | AA31: 0 | AB31: 0 | AD31: GELACCS | AE31: True | AF31: 2026-CO-000001 | AG31: DFG-ADV | AH31: NA | AJ31: 1 | AK31: -6 555 930.40 | AL31: YASMG | AN31: 14 000 000.00 | AO31: 14 000 000.00 | AP31: F | AQ31: 46209 | AR31: 0000-00-00 | AT31: YASSIE | AU31: YASSIE | AV31: C700 | AW31: 2026-CO-000001 | AX31: DFG-ADV | AY31: STD | BC31: 2057 | BD31: C700 | BE31: 4038 | BF31: 2 | BG31: 2026-07-08
A32: 135700 | B32: AFRO EGYPT | C32: REMISE | D32: Remise | E32: 1 | F32: UN | G32: -11385000 | H32: =IF(N32="USD",G32,IF(N32="MGA",G32/4600,IF(N32="EUR",G32*1.17,IF(N32="GBP",G32*1.35,"")))) -> -2475 | I32: =H32*E32 -> -2475 | J32: 2475 | K32: =I32*(-1) -> 2475 | M32: 0 | N32: MGA | O32: 46216 | P32: 2026-08-05 | Q32: E | R32: E | S32: RASAMOELINA Haritsoa Oliva | T32: 138882 | W32: DTG | X32: ELIE3 | Y32: ANDRIAMANANTSOA Elie | Z32: -13 662 000.00 | AA32: 20 | AB32: 2 | AD32: GELACCS | AE32: True | AF32: 2026-DT-101001 | AG32: DTG-DSTC-INSTA | AH32: NA | AJ32: 1 | AK32: -11 385 000.00 | AL32: YASMG | AN32: 29 955 000.00 | AO32: 35 946 000.00 | AP32: F | AQ32: 46216 | AR32: 0000-00-00 | AS32: Renfort rétablissement FTTx Yas à Toamasina(13j) | AT32: YASSIE | AU32: YASSIE | AV32: C500 | AW32: 2026-DT-101001 | AX32: DTG-DSTC-INSTA | AY32: STD | BC32: 2057 | BD32: C500 | BE32: 1033 | BF32: 2 | BG32: 2026-07-16
