Workbook

Sheet DASHBOARD
A1: YTD Performance | C1: OPCOs | D1: MADAGASCAR | E1: COMOROS | F1: SENEGAL | G1: TANZANIA | H1: TOGO
C2: Target YTD
A4: Section | B4: KPI | I4: Key Highlights and Drivers
A5: Savings | B5: % of Saving after Negotiations | C5: 0.1 | D5: =SUMIF('PR-PO SLA & Contract%'!C4:C477, "MADAGASCAR", 'PR-PO SLA & Contract%'!S4:S477)/SUMIF('PR-PO SLA & Contract%'!C4:C477, "MADAGASCAR", 'PR-PO SLA & Contract%'!Q4:Q477) -> 0.1284376 | E5: =SUMIF('PR-PO SLA & Contract%'!C4:C477, "COMOROS", 'PR-PO SLA & Contract%'!S4:S477)/SUMIF('PR-PO SLA & Contract%'!C4:C477, "COMOROS", 'PR-PO SLA & Contract%'!Q4:Q477) -> #DIV/0! | F5: =SUMIF('PR-PO SLA & Contract%'!C4:C477, "Senegal", 'PR-PO SLA & Contract%'!S4:S477)/SUMIF('PR-PO SLA & Contract%'!C4:C477, "Senegal", 'PR-PO SLA & Contract%'!Q4:Q477) -> #DIV/0! | G5: =SUMIF('PR-PO SLA & Contract%'!C4:C477, "Tanzania", 'PR-PO SLA & Contract%'!S4:S477)/SUMIF('PR-PO SLA & Contract%'!C4:C477, "Tanzania", 'PR-PO SLA & Contract%'!Q4:Q477) -> #DIV/0! | H5: =SUMIF('PR-PO SLA & Contract%'!C4:C477, "Togo", 'PR-PO SLA & Contract%'!S4:S477)/SUMIF('PR-PO SLA & Contract%'!C4:C477, "Togo", 'PR-PO SLA & Contract%'!Q4:Q477) -> #DIV/0!
B6: Absolute YTD Savings ($) | D6: =SUMIFS('PR-PO SLA & Contract%'!S4:S477, 'PR-PO SLA & Contract%'!C4:C477, "MADAGASCAR",'PR-PO SLA & Contract%'!P4:P477, "Usd") -> 2179415.8 | E6: =SUMIFS('PR-PO SLA & Contract%'!S4:S477, 'PR-PO SLA & Contract%'!C4:C477, "COMOROS",'PR-PO SLA & Contract%'!P4:P477, "Usd") -> 0 | F6: =SUMIFS('PR-PO SLA & Contract%'!S4:S477, 'PR-PO SLA & Contract%'!C4:C477, "SENEGAL",'PR-PO SLA & Contract%'!P4:P477, "Usd") -> 0 | G6: =SUMIFS('PR-PO SLA & Contract%'!S4:S477, 'PR-PO SLA & Contract%'!C4:C477, "Tanzania",'PR-PO SLA & Contract%'!P4:P477, "Usd") -> 0 | H6: =SUMIFS('PR-PO SLA & Contract%'!S4:S477, 'PR-PO SLA & Contract%'!C4:C477, "Togo",'PR-PO SLA & Contract%'!P4:P477, "Usd") -> 0
A7: Purchase Request - Purchase Order | B7: TAT for PR Approval (Days) | C7: 4 | D7: =AVERAGEIF('PR-PO SLA & Contract%'!C4:C477, "MADAGASCAR", 'PR-PO SLA & Contract%'!I4:I477) -> 3.4989429 | E7: =AVERAGEIF('PR-PO SLA & Contract%'!C4:C477, "COMOROS", 'PR-PO SLA & Contract%'!I4:I477) -> #DIV/0! | F7: =AVERAGEIF('PR-PO SLA & Contract%'!C4:C477, "Senegal", 'PR-PO SLA & Contract%'!I4:I477) -> #DIV/0! | G7: =AVERAGEIF('PR-PO SLA & Contract%'!C4:C477, "Tanzania", 'PR-PO SLA & Contract%'!I4:I477) -> #DIV/0! | H7: =AVERAGEIF('PR-PO SLA & Contract%'!C4:C477, "Togo", 'PR-PO SLA & Contract%'!I4:I477) -> #DIV/0!
B8: TAT for PR Approval vs. SLA Compliance (%) | C8: 0.9 | D8: =COUNTIFS('PR-PO SLA & Contract%'!I4:I477, "<=4", 'PR-PO SLA & Contract%'!C4:C477, "MADAGASCAR")/COUNTIF('PR-PO SLA & Contract%'!C4:C477, "MADAGASCAR") -> 0.81606765 | E8: =COUNTIFS('PR-PO SLA & Contract%'!I4:I477, "<=4", 'PR-PO SLA & Contract%'!C4:C477, "COMOROS")/COUNTIF('PR-PO SLA & Contract%'!C4:C477, "COMOROS") -> #DIV/0! | F8: =COUNTIFS('PR-PO SLA & Contract%'!I4:I477, "<=4", 'PR-PO SLA & Contract%'!C4:C477, "Senegal")/COUNTIF('PR-PO SLA & Contract%'!C4:C477, "Senegal") -> #DIV/0! | G8: =COUNTIFS('PR-PO SLA & Contract%'!I4:I477, "<=4", 'PR-PO SLA & Contract%'!C4:C477, "Tanzania")/COUNTIF('PR-PO SLA & Contract%'!C4:C477, "Tanzania") -> #DIV/0! | H8: =COUNTIFS('PR-PO SLA & Contract%'!I4:I477, "<=4", 'PR-PO SLA & Contract%'!C4:C477, "Togo")/COUNTIF('PR-PO SLA & Contract%'!C4:C477, "Togo") -> #DIV/0!
B9: TAT for PR to PO SLA Conversion (Days) | C9: 4 | D9: =AVERAGEIF('PR-PO SLA & Contract%'!C4:C477, "MADAGASCAR", 'PR-PO SLA & Contract%'!K4:K477) -> 2.3255814 | E9: =AVERAGEIF('PR-PO SLA & Contract%'!C4:C477, "COMOROS", 'PR-PO SLA & Contract%'!K4:K477) -> #DIV/0! | F9: =AVERAGEIF('PR-PO SLA & Contract%'!C4:C477, "Senegal", 'PR-PO SLA & Contract%'!K4:K477) -> #DIV/0! | G9: =AVERAGEIF('PR-PO SLA & Contract%'!C4:C477, "Tanzania", 'PR-PO SLA & Contract%'!K4:K477) -> #DIV/0! | H9: =AVERAGEIF('PR-PO SLA & Contract%'!C4:C477, "Togo", 'PR-PO SLA & Contract%'!K4:K477) -> #DIV/0!
B10: TAT for PO Approval vs. SLA Compliance (%) | C10: 0.9 | D10: =COUNTIFS('PR-PO SLA & Contract%'!M4:M477, "<=4", 'PR-PO SLA & Contract%'!C4:C477, "Madagascar")/COUNTIF('PR-PO SLA & Contract%'!C4:C477, "Madagascar") -> 0.98097252 | E10: =COUNTIFS('PR-PO SLA & Contract%'!M4:M477, "<=4", 'PR-PO SLA & Contract%'!C4:C477, "COMOROS")/COUNTIF('PR-PO SLA & Contract%'!C4:C477, "COMOROS") -> #DIV/0! | F10: =COUNTIFS('PR-PO SLA & Contract%'!M4:M477, "<=4", 'PR-PO SLA & Contract%'!C4:C477, "Senegal")/COUNTIF('PR-PO SLA & Contract%'!C4:C477, "Senegal") -> #DIV/0! | G10: =COUNTIFS('PR-PO SLA & Contract%'!M4:M477, "<=4", 'PR-PO SLA & Contract%'!C4:C477, "Tanzania")/COUNTIF('PR-PO SLA & Contract%'!C4:C477, "Tanzania") -> #DIV/0! | H10: =COUNTIFS('PR-PO SLA & Contract%'!M4:M477, "<=4", 'PR-PO SLA & Contract%'!C4:C477, "Togo")/COUNTIF('PR-PO SLA & Contract%'!C4:C477, "Togo") -> #DIV/0!
A11: Custom Clearance | B11: TAT for custom clearance (AIR): SLA compliance (Days) | C11: 5 | D11: =IF( COUNTIFS(Customs_Clearance!C4:C40041,"MADAGASCAR",Customs_Clearance!I4:I40041,"AIR")=0, 0, AVERAGEIFS(Customs_Clearance!L4:L40041,Customs_Clearance!C4:C40041,"MADAGASCAR",Customs_Clearance!I4:I40041,"AIR") ) -> 4.1111111 | E11: =IF( COUNTIFS(Customs_Clearance!C4:C44,"COMOROS",Customs_Clearance!I4:I44,"AIR")=0, 0, AVERAGEIFS(Customs_Clearance!L4:L44,Customs_Clearance!C4:C44,"COMOROS",Customs_Clearance!I4:I44,"AIR") ) -> 0 | F11: =IF( COUNTIFS(Customs_Clearance!C4:C40041,"SENEGAL",Customs_Clearance!I4:I40041,"AIR")=0, 0, AVERAGEIFS(Customs_Clearance!L4:L40041,Customs_Clearance!C4:C40041,"SENEGAL",Customs_Clearance!I4:I40041,"AIR") ) -> 0 | G11: =IF( COUNTIFS(Customs_Clearance!C4:C40041,"TANZANIA",Customs_Clearance!I4:I40041,"AIR")=0, 0, AVERAGEIFS(Customs_Clearance!L4:L40041,Customs_Clearance!C4:C40041,"TANZANIA",Customs_Clearance!I4:I40041,"AIR") ) -> 0 | H11: =IF( COUNTIFS(Customs_Clearance!C4:C40041,"Togo",Customs_Clearance!I4:I40041,"AIR")=0, 0, AVERAGEIFS(Customs_Clearance!L4:L40041,Customs_Clearance!C4:C40041,"Togo",Customs_Clearance!I4:I40041,"AIR") ) -> 0
B12: TAT for custom clearance (SEA): SLA compliance (Days) | C12: 10 | D12: =IF( COUNTIFS(Customs_Clearance!C4:C40041,"MADAGASCAR",Customs_Clearance!I4:I40041,"SEA")=0, 0, AVERAGEIFS(Customs_Clearance!L4:L40041,Customs_Clearance!C4:C40041,"MADAGASCAR",Customs_Clearance!I4:I40041,"SEA") ) -> 9.6666667 | E12: =IF( COUNTIFS(Customs_Clearance!C4:C40041,"COMOROS",Customs_Clearance!I4:I40041,"SEA")=0, 0, AVERAGEIFS(Customs_Clearance!L4:L40041,Customs_Clearance!C4:C40041,"COMOROS",Customs_Clearance!I4:I40041,"SEA") ) -> 0 | F12: =IF( COUNTIFS(Customs_Clearance!C4:C40041,"SENEGAL",Customs_Clearance!I4:I40041,"SEA")=0, 0, AVERAGEIFS(Customs_Clearance!L4:L40041,Customs_Clearance!C4:C40041,"SENEGAL",Customs_Clearance!I4:I40041,"SEA") ) -> 0 | G12: =IF( COUNTIFS(Customs_Clearance!C4:C40041,"Tanzania",Customs_Clearance!I4:I40041,"SEA")=0, 0, AVERAGEIFS(Customs_Clearance!L4:L40041,Customs_Clearance!C4:C40041,"Tanzania",Customs_Clearance!I4:I40041,"SEA") ) -> 0 | H12: =IF( COUNTIFS(Customs_Clearance!C4:C40041,"Togo",Customs_Clearance!I4:I40041,"SEA")=0, 0, AVERAGEIFS(Customs_Clearance!L4:L40041,Customs_Clearance!C4:C40041,"Togo",Customs_Clearance!I4:I40041,"SEA") ) -> 0
A13: Contracts Compliance | B13: % Purchase on Contracts (Count) | C13: 0.7 | D13: =COUNTIFS('PR-PO SLA & Contract%'!E4:E477, "YES", 'PR-PO SLA & Contract%'!C4:C477, "Madagascar")/COUNTIF('PR-PO SLA & Contract%'!C4:C477, "Madagascar") -> 0.87526427 | E13: =COUNTIFS('PR-PO SLA & Contract%'!E4:E477, "YES", 'PR-PO SLA & Contract%'!C4:C477, "COMOROS")/COUNTIF('PR-PO SLA & Contract%'!C4:C477, "COMOROS") -> #DIV/0! | F13: =COUNTIFS('PR-PO SLA & Contract%'!E4:E477, "YES", 'PR-PO SLA & Contract%'!C4:C477, "Senegal")/COUNTIF('PR-PO SLA & Contract%'!C4:C477, "Senegal") -> #DIV/0! | G13: =COUNTIFS('PR-PO SLA & Contract%'!E4:E477, "YES", 'PR-PO SLA & Contract%'!C4:C477, "Tanzania")/COUNTIF('PR-PO SLA & Contract%'!C4:C477, "Tanzania") -> #DIV/0! | H13: =COUNTIFS('PR-PO SLA & Contract%'!E4:E477, "YES", 'PR-PO SLA & Contract%'!C4:C477, "Togo")/COUNTIF('PR-PO SLA & Contract%'!C4:C477, "Togo") -> #DIV/0!
B14: % Purchase on Contracts (Value) | C14: 0.7 | D14: =IFERROR(SUMIFS('PR-PO SLA & Contract%'!$R:$R,'PR-PO SLA & Contract%'!$E:$E,"Yes",'PR-PO SLA & Contract%'!$C:$C,DASHBOARD!D$1)/SUMIFS('PR-PO SLA & Contract%'!$R:$R,'PR-PO SLA & Contract%'!$C:$C,DASHBOARD!D$1),0) -> 0.97785958 | E14: =IFERROR(SUMIFS('PR-PO SLA & Contract%'!$R:$R,'PR-PO SLA & Contract%'!$E:$E,"Yes",'PR-PO SLA & Contract%'!$C:$C,DASHBOARD!E$1)/SUMIFS('PR-PO SLA & Contract%'!$R:$R,'PR-PO SLA & Contract%'!$C:$C,DASHBOARD!E$1),0) -> 0 | F14: =IFERROR(SUMIFS('PR-PO SLA & Contract%'!$R:$R,'PR-PO SLA & Contract%'!$E:$E,"Yes",'PR-PO SLA & Contract%'!$C:$C,DASHBOARD!F$1)/SUMIFS('PR-PO SLA & Contract%'!$R:$R,'PR-PO SLA & Contract%'!$C:$C,DASHBOARD!F$1),0) -> 0 | G14: =IFERROR(SUMIFS('PR-PO SLA & Contract%'!$R:$R,'PR-PO SLA & Contract%'!$E:$E,"Yes",'PR-PO SLA & Contract%'!$C:$C,DASHBOARD!G$1)/SUMIFS('PR-PO SLA & Contract%'!$R:$R,'PR-PO SLA & Contract%'!$C:$C,DASHBOARD!G$1),0) -> 0 | H14: =IFERROR(SUMIFS('PR-PO SLA & Contract%'!$R:$R,'PR-PO SLA & Contract%'!$E:$E,"Yes",'PR-PO SLA & Contract%'!$C:$C,DASHBOARD!H$1)/SUMIFS('PR-PO SLA & Contract%'!$R:$R,'PR-PO SLA & Contract%'!$C:$C,DASHBOARD!H$1),0) -> 0
A15: Payment | B15: PPOT (% Due invoices paid) | C15: 0.7 | D15: =IF(COUNTIF(PPOT!C4:C876,"Madagascar")=0, 0, COUNTIFS(PPOT!O4:O876,"YES",PPOT!C4:C876,"Madagascar") / COUNTIF(PPOT!C4:C876,"Madagascar") ) -> 0.7293578 | E15: =IF(COUNTIF(PPOT!C4:C876,"COMOROS")=0, 0, COUNTIFS(PPOT!O4:O876,"YES",PPOT!C4:C876,"COMOROS") / COUNTIF(PPOT!C4:C876,"COMOROS") ) -> 0 | F15: =IF(COUNTIF(PPOT!C4:C876,"Senegal")=0, 0, COUNTIFS(PPOT!O4:O876,"YES",PPOT!C4:C876,"Senegal") / COUNTIF(PPOT!C4:C876,"Senegal") ) -> 0 | G15: =IF(COUNTIF(PPOT!C4:C876,"Tanzania")=0, 0, COUNTIFS(PPOT!O4:O876,"YES",PPOT!C4:C876,"Tanzania") / COUNTIF(PPOT!C4:C876,"Tanzania") ) -> 0 | H15: =IF(COUNTIF(PPOT!C4:C876,"Togo")=0, 0, COUNTIFS(PPOT!O4:O876,"YES",PPOT!C4:C876,"Togo") / COUNTIF(PPOT!C4:C876,"Togo") ) -> 0
B16: Ranking | D16: =RANK(D31,$D$31:$H$31,0) -> #DIV/0! | E16: =RANK(E31,$D$31:$H$31,0) -> #DIV/0! | F16: =RANK(F31,$D$31:$H$31,0) -> #DIV/0! | G16: =RANK(G31,$D$31:$H$31,0) -> #DIV/0! | H16: =RANK(H31,$D$31:$H$31,0) -> #DIV/0!
B18: The section below is to aid in normalizing scores, weighting them for ranking purposes.
C20: Weighting | D20: MADAGASCAR | E20: COMOROS | F20: SENEGAL | G20: TANZANIA | H20: TOGO
B21: =CONCATENATE("Normalized"," ",B5) -> Normalized % of Saving after Negotiations | C21: 0.15 | D21: =(D5-MIN($D$5:$H$5))/(MAX($D$5:$H$5)-MIN($D$5:$H$5)) -> #DIV/0! | E21: =(E5-MIN($D$5:$H$5))/(MAX($D$5:$H$5)-MIN($D$5:$H$5)) -> #DIV/0! | F21: =(F5-MIN($D$5:$H$5))/(MAX($D$5:$H$5)-MIN($D$5:$H$5)) -> #DIV/0! | G21: =(G5-MIN($D$5:$H$5))/(MAX($D$5:$H$5)-MIN($D$5:$H$5)) -> #DIV/0! | H21: =(H5-MIN($D$5:$H$5))/(MAX($D$5:$H$5)-MIN($D$5:$H$5)) -> #DIV/0!
B22: =CONCATENATE("Normalized"," ",B6) -> Normalized Absolute YTD Savings ($) | C22: 0.05 | D22: =(D6-MIN($D$6:$H$6))/(MAX($D$6:$H$6)-MIN($D$6:$H$6)) -> 1 | E22: =(E6-MIN($D$6:$H$6))/(MAX($D$6:$H$6)-MIN($D$6:$H$6)) -> 0 | F22: =(F6-MIN($D$6:$H$6))/(MAX($D$6:$H$6)-MIN($D$6:$H$6)) -> 0 | G22: =(G6-MIN($D$6:$H$6))/(MAX($D$6:$H$6)-MIN($D$6:$H$6)) -> 0 | H22: =(H6-MIN($D$6:$H$6))/(MAX($D$6:$H$6)-MIN($D$6:$H$6)) -> 0
B23: =CONCATENATE("Normalized"," ",B7) -> Normalized TAT for PR Approval (Days) | C23: 0.1 | D23: =(MAX($D$7:$H$7)-D7)/(MAX($D$7:$H$7)-MIN($D$7:$H$7)) -> #DIV/0! | E23: =(MAX($D$7:$H$7)-E7)/(MAX($D$7:$H$7)-MIN($D$7:$H$7)) -> #DIV/0! | F23: =(MAX($D$7:$H$7)-F7)/(MAX($D$7:$H$7)-MIN($D$7:$H$7)) -> #DIV/0! | G23: =(MAX($D$7:$H$7)-G7)/(MAX($D$7:$H$7)-MIN($D$7:$H$7)) -> #DIV/0! | H23: =(MAX($D$7:$H$7)-H7)/(MAX($D$7:$H$7)-MIN($D$7:$H$7)) -> #DIV/0!
B24: =CONCATENATE("Normalized"," ",B8) -> Normalized TAT for PR Approval vs. SLA Compliance (%) | C24: 0.1 | D24: =(D8-MIN($D$8:$H$8))/(MAX($D$8:$H$8)-MIN($D$8:$H$8)) -> #DIV/0! | E24: =(E8-MIN($D$8:$H$8))/(MAX($D$8:$H$8)-MIN($D$8:$H$8)) -> #DIV/0! | F24: =(F8-MIN($D$8:$H$8))/(MAX($D$8:$H$8)-MIN($D$8:$H$8)) -> #DIV/0! | G24: =(G8-MIN($D$8:$H$8))/(MAX($D$8:$H$8)-MIN($D$8:$H$8)) -> #DIV/0! | H24: =(H8-MIN($D$8:$H$8))/(MAX($D$8:$H$8)-MIN($D$8:$H$8)) -> #DIV/0!
B25: =CONCATENATE("Normalized"," ",B9) -> Normalized TAT for PR to PO SLA Conversion (Days) | C25: 0.1 | D25: =(MAX($D$9:$H$9)-D9)/(MAX($D$9:$H$9)-MIN($D$9:$H$9)) -> #DIV/0! | E25: =(MAX($D$9:$H$9)-E9)/(MAX($D$9:$H$9)-MIN($D$9:$H$9)) -> #DIV/0! | F25: =(MAX($D$9:$H$9)-F9)/(MAX($D$9:$H$9)-MIN($D$9:$H$9)) -> #DIV/0! | G25: =(MAX($D$9:$H$9)-G9)/(MAX($D$9:$H$9)-MIN($D$9:$H$9)) -> #DIV/0! | H25: =(MAX($D$9:$H$9)-H9)/(MAX($D$9:$H$9)-MIN($D$9:$H$9)) -> #DIV/0!
B26: Normalized TAT for PO Approval vs. SLA Compliance (%) | C26: 0.05 | D26: =(D10-MIN($D$10:$H$10))/(MAX($D$10:$H$10)-MIN($D$10:$H$10)) -> #DIV/0! | E26: =(E10-MIN($D$10:$H$10))/(MAX($D$10:$H$10)-MIN($D$10:$H$10)) -> #DIV/0! | F26: =(F10-MIN($D$10:$H$10))/(MAX($D$10:$H$10)-MIN($D$10:$H$10)) -> #DIV/0! | G26: =(G10-MIN($D$10:$H$10))/(MAX($D$10:$H$10)-MIN($D$10:$H$10)) -> #DIV/0! | H26: =(H10-MIN($D$10:$H$10))/(MAX($D$10:$H$10)-MIN($D$10:$H$10)) -> #DIV/0!
B27: =CONCATENATE("Normalized"," ",B11) -> Normalized TAT for custom clearance (AIR): SLA compliance (Days) | C27: 0.05 | D27: =(MAX($D$11:$H$11)-D11)/(MAX($D$11:$H$11)-MIN($D$11:$H$11)) -> 0 | E27: =(MAX($D$11:$H$11)-E11)/(MAX($D$11:$H$11)-MIN($D$11:$H$11)) -> 1 | F27: =(MAX($D$11:$H$11)-F11)/(MAX($D$11:$H$11)-MIN($D$11:$H$11)) -> 1 | G27: =(MAX($D$11:$H$11)-G11)/(MAX($D$11:$H$11)-MIN($D$11:$H$11)) -> 1 | H27: =(MAX($D$11:$H$11)-H11)/(MAX($D$11:$H$11)-MIN($D$11:$H$11)) -> 1
B28: =CONCATENATE("Normalized"," ",B12) -> Normalized TAT for custom clearance (SEA): SLA compliance (Days) | C28: 0.05 | D28: =(MAX($D$12:$H$12)-D12)/(MAX($D$12:$H$12)-MIN($D$12:$H$12)) -> 0 | E28: =(MAX($D$12:$H$12)-E12)/(MAX($D$12:$H$12)-MIN($D$12:$H$12)) -> 1 | F28: =(MAX($D$12:$H$12)-F12)/(MAX($D$12:$H$12)-MIN($D$12:$H$12)) -> 1 | G28: =(MAX($D$12:$H$12)-G12)/(MAX($D$12:$H$12)-MIN($D$12:$H$12)) -> 1 | H28: =(MAX($D$12:$H$12)-H12)/(MAX($D$12:$H$12)-MIN($D$12:$H$12)) -> 1
B29: =CONCATENATE("Normalized"," ",B13) -> Normalized % Purchase on Contracts (Count) | C29: 0.2 | D29: =(D13-MIN($D$13:$H$13))/(MAX($D$13:$H$13)-MIN($D$13:$H$13)) -> #DIV/0! | E29: =(E13-MIN($D$13:$H$13))/(MAX($D$13:$H$13)-MIN($D$13:$H$13)) -> #DIV/0! | F29: =(F13-MIN($D$13:$H$13))/(MAX($D$13:$H$13)-MIN($D$13:$H$13)) -> #DIV/0! | G29: =(G13-MIN($D$13:$H$13))/(MAX($D$13:$H$13)-MIN($D$13:$H$13)) -> #DIV/0! | H29: =(H13-MIN($D$13:$H$13))/(MAX($D$13:$H$13)-MIN($D$13:$H$13)) -> #DIV/0!
B30: =CONCATENATE("Normalized"," ",B15) -> Normalized PPOT (% Due invoices paid) | C30: 0.15 | D30: =(D15-MIN($D$15:$H$15))/(MAX($D$15:$H$15)-MIN($D$15:$H$15)) -> 1 | E30: =(E15-MIN($D$15:$H$15))/(MAX($D$15:$H$15)-MIN($D$15:$H$15)) -> 0 | F30: =(F15-MIN($D$15:$H$15))/(MAX($D$15:$H$15)-MIN($D$15:$H$15)) -> 0 | G30: =(G15-MIN($D$15:$H$15))/(MAX($D$15:$H$15)-MIN($D$15:$H$15)) -> 0 | H30: =(H15-MIN($D$15:$H$15))/(MAX($D$15:$H$15)-MIN($D$15:$H$15)) -> 0
B31: Global Weighted Score | D31: =D21*$C$21+D22*$C$22+D23*$C$23+D24*$C$24+D25*$C$25+D26*$C$26+D27*$C$27+D28*$C$28+D29*$C$29+D30*$C$30 -> #DIV/0! | E31: =E21*$C$21+E22*$C$22+E23*$C$23+E24*$C$24+E25*$C$25+E26*$C$26+E27*$C$27+E28*$C$28+E29*$C$29+E30*$C$30 -> #DIV/0! | F31: =F21*$C$21+F22*$C$22+F23*$C$23+F24*$C$24+F25*$C$25+F26*$C$26+F27*$C$27+F28*$C$28+F29*$C$29+F30*$C$30 -> #DIV/0! | G31: =G21*$C$21+G22*$C$22+G23*$C$23+G24*$C$24+G25*$C$25+G26*$C$26+G27*$C$27+G28*$C$28+G29*$C$29+G30*$C$30 -> #DIV/0! | H31: =H21*$C$21+H22*$C$22+H23*$C$23+H24*$C$24+H25*$C$25+H26*$C$26+H27*$C$27+H28*$C$28+H29*$C$29+H30*$C$30 -> #DIV/0!
A32: Month Over Month Progress | C32: OPCOs | D32: MADAGASCAR | E32: COMOROS | F32: SENEGAL | G32: TANZANIA | H32: TOGO
C33: Target YTD
A35: Section | B35: KPI
A36: Savings | B36: % of Saving after Negotiations (bps) | C36: 0.1 | D36: =(D5-'M-1 YTD performance'!D5)*10000 -> 802.66307 | E36: =(E5-'M-1 YTD performance'!E5)*10000 -> #DIV/0! | F36: =(F5-'M-1 YTD performance'!F5)*10000 -> #DIV/0! | G36: =(G5-'M-1 YTD performance'!G5)*10000 -> #DIV/0! | H36: =(H5-'M-1 YTD performance'!H5)*10000 -> #DIV/0!
B37: Absolute YTD Savings ($) | D37: =D6-'M-1 YTD performance'!D6 -> -134165.16 | E37: =E6-'M-1 YTD performance'!E6 -> -1405117.3 | F37: =F6-'M-1 YTD performance'!F6 -> -2944643 | G37: =G6-'M-1 YTD performance'!G6 -> -5911843.3 | H37: =H6-'M-1 YTD performance'!H6 -> -4057811.9
A38: Purchase Request - Purchase Order | B38: TAT for PR Approval (Days) | C38: 4 | D38: =D7-'M-1 YTD performance'!D7 -> 0.81897838 | E38: =E7-'M-1 YTD performance'!E7 -> #DIV/0! | F38: =F7-'M-1 YTD performance'!F7 -> #DIV/0! | G38: =G7-'M-1 YTD performance'!G7 -> #DIV/0! | H38: =H7-'M-1 YTD performance'!H7 -> #DIV/0!
B39: TAT for PR Approval vs. SLA Compliance (bps) | C39: 0.9 | D39: =(D8-'M-1 YTD performance'!D8)*10000 -> -45.588243 | E39: =(E8-'M-1 YTD performance'!E8)*10000 -> #DIV/0! | F39: =(F8-'M-1 YTD performance'!F8)*10000 -> #DIV/0! | G39: =(G8-'M-1 YTD performance'!G8)*10000 -> #DIV/0! | H39: =(H8-'M-1 YTD performance'!H8)*10000 -> #DIV/0!
B40: TAT for PR to PO SLA Conversion (Days) | C40: 4 | D40: =D9-'M-1 YTD performance'!D9 -> -1.653142 | E40: =E9-'M-1 YTD performance'!E9 -> #DIV/0! | F40: =F9-'M-1 YTD performance'!F9 -> #DIV/0! | G40: =G9-'M-1 YTD performance'!G9 -> #DIV/0! | H40: =H9-'M-1 YTD performance'!H9 -> #DIV/0!
B41: TAT for PO Approval vs. SLA Compliance (bps) | C41: 0.9 | D41: =(D10-'M-1 YTD performance'!D10)*10000 -> 152.51476 | E41: =(E10-'M-1 YTD performance'!E10)*10000 -> #DIV/0! | F41: =(F10-'M-1 YTD performance'!F10)*10000 -> #DIV/0! | G41: =(G10-'M-1 YTD performance'!G10)*10000 -> #DIV/0! | H41: =(H10-'M-1 YTD performance'!H10)*10000 -> #DIV/0!
A42: Custom Clearance | B42: TAT for custom clearance (AIR): SLA compliance (Days) | C42: 5 | D42: =D11-'M-1 YTD performance'!D11 -> -0.68434343 | E42: =E11-'M-1 YTD performance'!E11 -> -8.75 | F42: =F11-'M-1 YTD performance'!F11 -> -5.7115385 | G42: =G11-'M-1 YTD performance'!G11 -> -5.9318182 | H42: =H11-'M-1 YTD performance'!H11 -> -8.7857143
B43: TAT for custom clearance (SEA): SLA compliance (Days) | C43: 10 | D43: =D12-'M-1 YTD performance'!D12 -> 0.84313725 | E43: =E12-'M-1 YTD performance'!E12 -> -12 | F43: =F12-'M-1 YTD performance'!F12 -> -6.9333333 | G43: =G12-'M-1 YTD performance'!G12 -> -17.166667 | H43: =H12-'M-1 YTD performance'!H12 -> -11.384615
A44: Contracts Compliance | B44: % Purchase on Contracts (Count - bps) | C44: 0.7 | D44: =(D13-'M-1 YTD performance'!D13)*10000 -> 2440.586 | E44: =(E13-'M-1 YTD performance'!E13)*10000 -> #DIV/0! | F44: =(F13-'M-1 YTD performance'!F13)*10000 -> #DIV/0! | G44: =(G13-'M-1 YTD performance'!G13)*10000 -> #DIV/0! | H44: =(H13-'M-1 YTD performance'!H13)*10000 -> #DIV/0!
...

Sheet PR-PO SLA & Contract%
B1: OPCOS MONTHLY DETAILS TRACKER
C2: same OpCo spelling as in the Dashboard | F2: =LEFT('[1]PR-PO SLA & Contract%'!G5,10) -> 30/01/2026 | G2: Date in MM/DD/YYYY format | H2: Date in MM/DD/YYYY format | I2: Automatic Formula | J2: Date in MM/DD/YYYY format | K2: Automatic Formula | L2: Date in MM/DD/YYYY format | M2: Automatic Formula | P2: exchange to USD | S2: Automatic Formula | T2: indicate the saving from OpCo nego effort (USD) | U2: indicate the saving from Group nego effort (USD) | W2: Automatic Formula
F3: =RIGHT(LEFT('[1]PR-PO SLA & Contract%'!G5,8),4) -> 1/20
B4: N° | C4: OPCO | D4: PO reference | E4: Under contract (Yes or No) | F4: PR Number | G4: PR Created Date | H4: PR Approved Date | I4: PR Approval TAT | J4: PO Created Date | K4: Approved PR - PO TAT | L4: PO Approved Date | M4: PO Approval TAT | N4: Designation | O4: Partner | P4: Currency usd | Q4: Amount before Negotiation | R4: Amount after Negotiation | S4: Saving | T4: OpCo saving | U4: Group saving | V4: Target Savings | W4: % Savings
B5: 1 | C5: Madagascar | D5: 136497 | E5: Yes | F5: 138888 | G5: 46211 | H5: 2026-07-13 | I5: =IF(OR(H5="", G5=""), "", NETWORKDAYS(G5, H5)) -> 4 | J5: 46229 | K5: =IF(OR(H5="", J5=""), "", NETWORKDAYS(H5, J5)) -> 10 | L5: 46230 | M5: =IF(OR(J5="", L5=""), "", NETWORKDAYS(J5, L5)) -> 1 | N5: Badge sans puce | O5: TECHNOALARME | P5: USD | Q5: 391.30435 | R5: 391.30435 | S5: =Q5-R5 -> 0 | V5: =IF(Q5="", "", Q5*10%) -> 39.130435 | W5: =IF(OR(Q5="", R5=""), "", (Q5- R5)/Q5) -> 0
B6: 2 | C6: Madagascar | D6: 136157 | E6: Yes | F6: 138949 | G6: 46231 | H6: 2026-07-31 | I6: =IF(OR(H6="", G6=""), "", NETWORKDAYS(G6, H6)) -> 4 | J6: 46237 | K6: =IF(OR(H6="", J6=""), "", NETWORKDAYS(H6, J6)) -> 2 | L6: 2026-08-03 | M6: =IF(OR(J6="", L6=""), "", NETWORKDAYS(J6, L6)) -> 1 | N6: Prestation intérimaire: PERDIEM Suivi routier - Eudes, Aldo, Tolotra mars au juillet 26# FACTURE PROFORMA N°335-A/FP/TELMA/2026 DU 10/07/2026 | O6: LCS CONSULTING | P6: USD | Q6: 2419.8913 | R6: 2419.8913 | S6: =Q6-R6 -> 0 | V6: =IF(Q6="", "", Q6*10%) -> 241.98913 | W6: =IF(OR(Q6="", R6=""), "", (Q6- R6)/Q6) -> 0
B7: 3 | C7: Madagascar | D7: 136158 | E7: Yes | F7: 138947 | G7: 46231 | H7: 2026-07-31 | I7: =IF(OR(H7="", G7=""), "", NETWORKDAYS(G7, H7)) -> 4 | J7: 46237 | K7: =IF(OR(H7="", J7=""), "", NETWORKDAYS(H7, J7)) -> 2 | L7: 2026-08-03 | M7: =IF(OR(J7="", L7=""), "", NETWORKDAYS(J7, L7)) -> 1 | N7: Prestation intérimaire: PERDIEM Suivi routier - Eric juillet 26# FACTURE PROFORMA N°333-A/FP/TELMA/2026 DU 10/07/2026 | O7: LCS CONSULTING | P7: USD | Q7: 341.95652 | R7: 341.95652 | S7: =Q7-R7 -> 0 | V7: =IF(Q7="", "", Q7*10%) -> 34.195652 | W7: =IF(OR(Q7="", R7=""), "", (Q7- R7)/Q7) -> 0
B8: 4 | C8: Madagascar | D8: 136159 | E8: Yes | F8: 138931 | G8: 46231 | H8: 2026-07-31 | I8: =IF(OR(H8="", G8=""), "", NETWORKDAYS(G8, H8)) -> 4 | J8: 46237 | K8: =IF(OR(H8="", J8=""), "", NETWORKDAYS(H8, J8)) -> 2 | L8: 2026-08-03 | M8: =IF(OR(J8="", L8=""), "", NETWORKDAYS(J8, L8)) -> 1 | N8: Prestation intérimaire: PERDIEM mission - 01 Formateur Commercial du 130726 au 040826# FACTURE PROFORMA N°332-A/FP/TELMA/2026 DU 09/07/2026 | O8: LCS CONSULTING | P8: USD | Q8: 336.95652 | R8: 336.95652 | S8: =Q8-R8 -> 0 | V8: =IF(Q8="", "", Q8*10%) -> 33.695652 | W8: =IF(OR(Q8="", R8=""), "", (Q8- R8)/Q8) -> 0
B9: 5 | C9: Madagascar | D9: 136160 | E9: Yes | F9: 138945 | G9: 46231 | H9: 2026-07-31 | I9: =IF(OR(H9="", G9=""), "", NETWORKDAYS(G9, H9)) -> 4 | J9: 46237 | K9: =IF(OR(H9="", J9=""), "", NETWORKDAYS(H9, J9)) -> 2 | L9: 2026-08-03 | M9: =IF(OR(J9="", L9=""), "", NETWORKDAYS(J9, L9)) -> 1 | N9: Prestation intérimaire: PERDIEM Mission - Moïbe, Bernard, Haja, Hilaire,Chistien avril au juillet 26# FACTURE PROFORMA N°334-A/FP/TELMA/2026 DU 10/07/2026 | O9: LCS CONSULTING | P9: USD | Q9: 674.13043 | R9: 674.13043 | S9: =Q9-R9 -> 0 | V9: =IF(Q9="", "", Q9*10%) -> 67.413043 | W9: =IF(OR(Q9="", R9=""), "", (Q9- R9)/Q9) -> 0
B10: 6 | C10: Madagascar | D10: 136156 | E10: Yes | F10: 139005 | G10: 46221 | H10: 2026-07-31 | I10: =IF(OR(H10="", G10=""), "", NETWORKDAYS(G10, H10)) -> 10 | J10: 46237 | K10: =IF(OR(H10="", J10=""), "", NETWORKDAYS(H10, J10)) -> 2 | L10: 2026-08-03 | M10: =IF(OR(J10="", L10=""), "", NETWORKDAYS(J10, L10)) -> 1 | N10: Prestation intérimaire: PERDIEM Suivi routier - Tsiry, Niriana, Thierry, Tahiry mai au juillet 26# FACTURE PROFORMA N°336-A/FP/TELMA/2026 DU 13/07/2026 | O10: LCS CONSULTING | P10: USD | Q10: 2769.087 | R10: 2769.087 | S10: =Q10-R10 -> 0 | V10: =IF(Q10="", "", Q10*10%) -> 276.9087 | W10: =IF(OR(Q10="", R10=""), "", (Q10- R10)/Q10) -> 0
B11: 7 | C11: Madagascar | D11: 136155 | E11: Yes | F11: 139038 | G11: 46219 | H11: 2026-07-31 | I11: =IF(OR(H11="", G11=""), "", NETWORKDAYS(G11, H11)) -> 12 | J11: 46237 | K11: =IF(OR(H11="", J11=""), "", NETWORKDAYS(H11, J11)) -> 2 | L11: 2026-08-03 | M11: =IF(OR(J11="", L11=""), "", NETWORKDAYS(J11, L11)) -> 1 | N11: Transport bagages SAMBATRA suite rapatriement# DEVIS N° 058 DU 13/06/2026 | O11: RAHANTAMALALA FANJANIRINA SYLVIENE | P11: USD | Q11: 326.08696 | R11: 326.08696 | S11: =Q11-R11 -> 0 | V11: =IF(Q11="", "", Q11*10%) -> 32.608696 | W11: =IF(OR(Q11="", R11=""), "", (Q11- R11)/Q11) -> 0
B12: 8 | C12: Madagascar | D12: 136154 | E12: Yes | F12: 139090 | G12: 46220 | H12: 2026-07-31 | I12: =IF(OR(H12="", G12=""), "", NETWORKDAYS(G12, H12)) -> 11 | J12: 46237 | K12: =IF(OR(H12="", J12=""), "", NETWORKDAYS(H12, J12)) -> 2 | L12: 2026-08-03 | M12: =IF(OR(J12="", L12=""), "", NETWORKDAYS(J12, L12)) -> 1 | N12: RSE - Page RSE Yas dans le magazine EcoAustral | O12: EDITIONS AUSTRALES INTERNATIONALES LTD | P12: USD | Q12: 1408.6957 | R12: 1408.6957 | S12: =Q12-R12 -> 0 | V12: =IF(Q12="", "", Q12*10%) -> 140.86957 | W12: =IF(OR(Q12="", R12=""), "", (Q12- R12)/Q12) -> 0
B13: 9 | C13: Madagascar | D13: 136202 | E13: Yes | F13: 139078 | G13: 46221 | H13: 2026-08-05 | I13: =IF(OR(H13="", G13=""), "", NETWORKDAYS(G13, H13)) -> 13 | J13: 46240 | K13: =IF(OR(H13="", J13=""), "", NETWORKDAYS(H13, J13)) -> 2 | L13: 2026-08-06 | M13: =IF(OR(J13="", L13=""), "", NETWORKDAYS(J13, L13)) -> 1 | N13: DAET 13748 | O13: EASY NETCOM | P13: USD | Q13: 2591.3043 | R13: 2591.3043 | S13: =Q13-R13 -> 0 | V13: =IF(Q13="", "", Q13*10%) -> 259.13043 | W13: =IF(OR(Q13="", R13=""), "", (Q13- R13)/Q13) -> 0
B14: 10 | C14: Madagascar | D14: 136211 | E14: Yes | F14: 139076 | G14: 46234 | H14: 2026-08-05 | I14: =IF(OR(H14="", G14=""), "", NETWORKDAYS(G14, H14)) -> 4 | J14: 46240 | K14: =IF(OR(H14="", J14=""), "", NETWORKDAYS(H14, J14)) -> 2 | L14: 2026-08-06 | M14: =IF(OR(J14="", L14=""), "", NETWORKDAYS(J14, L14)) -> 1 | N14: DAET 13731/13730/13746/13751/13802/13747/13752/13803 | O14: EASY NETCOM | P14: USD | Q14: 2893.4783 | R14: 2893.4783 | S14: =Q14-R14 -> 0 | V14: =IF(Q14="", "", Q14*10%) -> 289.34783 | W14: =IF(OR(Q14="", R14=""), "", (Q14- R14)/Q14) -> 0
B15: 11 | C15: Madagascar | D15: 136212 | E15: Yes | F15: 139077 | G15: 46234 | H15: 2026-08-05 | I15: =IF(OR(H15="", G15=""), "", NETWORKDAYS(G15, H15)) -> 4 | J15: 46240 | K15: =IF(OR(H15="", J15=""), "", NETWORKDAYS(H15, J15)) -> 2 | L15: 2026-08-06 | M15: =IF(OR(J15="", L15=""), "", NETWORKDAYS(J15, L15)) -> 1 | N15: DAET 13732 | O15: EASY NETCOM | P15: USD | Q15: 1629.4783 | R15: 1629.4783 | S15: =Q15-R15 -> 0 | V15: =IF(Q15="", "", Q15*10%) -> 162.94783 | W15: =IF(OR(Q15="", R15=""), "", (Q15- R15)/Q15) -> 0
B16: 12 | C16: Madagascar | D16: 136213 | E16: Yes | F16: 139081 | G16: 46234 | H16: 2026-08-05 | I16: =IF(OR(H16="", G16=""), "", NETWORKDAYS(G16, H16)) -> 4 | J16: 46240 | K16: =IF(OR(H16="", J16=""), "", NETWORKDAYS(H16, J16)) -> 2 | L16: 2026-08-06 | M16: =IF(OR(J16="", L16=""), "", NETWORKDAYS(J16, L16)) -> 1 | N16: DAET 13749/13750/13754 | O16: EASY NETCOM | P16: USD | Q16: 1748.6957 | R16: 1748.6957 | S16: =Q16-R16 -> 0 | V16: =IF(Q16="", "", Q16*10%) -> 174.86957 | W16: =IF(OR(Q16="", R16=""), "", (Q16- R16)/Q16) -> 0
B17: 13 | C17: Madagascar | D17: 136214 | E17: Yes | F17: 139079 | G17: 46234 | H17: 2026-08-05 | I17: =IF(OR(H17="", G17=""), "", NETWORKDAYS(G17, H17)) -> 4 | J17: 46240 | K17: =IF(OR(H17="", J17=""), "", NETWORKDAYS(H17, J17)) -> 2 | L17: 2026-08-06 | M17: =IF(OR(J17="", L17=""), "", NETWORKDAYS(J17, L17)) -> 1 | N17: DAET 13731/13730/13746/13751/13802/13747/13752/13803 | O17: EASY NETCOM | P17: USD | Q17: 2802.587 | R17: 2802.587 | S17: =Q17-R17 -> 0 | V17: =IF(Q17="", "", Q17*10%) -> 280.2587 | W17: =IF(OR(Q17="", R17=""), "", (Q17- R17)/Q17) -> 0
... B20: 16 | C20: Madagascar | D20: 136221 | E20: No | F20: 139102 | G20: 46234 | H20: 2026-08-05 | I20: =IF(OR(H20="", G20=""), "", NETWORKDAYS(G20, H20)) -> 4 | J20: 46241 | K20: =IF(OR(H20="", J20=""), "", NETWORKDAYS(H20, J20)) -> 3 | L20: 2026-08-07 | M20: =IF(OR(J20="", L20=""), "", NETWORKDAYS(J20, L20)) -> 1 | N20: DAET 13738/13757 | O20: PRIMA CE SARLU | P20: USD | Q20: 1928.1304 | R20: 1928.1304 | S20: =Q20-R20 -> 0 | V20: =IF(Q20="", "", Q20*10%) -> 192.81304 | W20: =IF(OR(Q20="", R20=""), "", (Q20- R20)/Q20) -> 0
B21: 17 | C21: Madagascar | D21: 136508 | E21: Yes | F21: 139093 | G21: 46220 | H21: 2026-07-20 | I21: =IF(OR(H21="", G21=""), "", NETWORKDAYS(G21, H21)) -> 2 | J21: 46230 | K21: =IF(OR(H21="", J21=""), "", NETWORKDAYS(H21, J21)) -> 6 | L21: 46234 | M21: =IF(OR(J21="", L21=""), "", NETWORKDAYS(J21, L21)) -> 5 | N21: Gant de manutention | O21: ALL TRADE SARLU | P21: USD | Q21: 91.304348 | R21: 91.304348 | S21: =Q21-R21 -> 0 | V21: =IF(Q21="", "", Q21*10%) -> 9.1304348 | W21: =IF(OR(Q21="", R21=""), "", (Q21- R21)/Q21) -> 0
B22: 18 | C22: Madagascar | D22: 136284 | E22: Yes | F22: 139125 | G22: 46234 | H22: 2026-08-13 | I22: =IF(OR(H22="", G22=""), "", NETWORKDAYS(G22, H22)) -> 10 | J22: 46247 | K22: =IF(OR(H22="", J22=""), "", NETWORKDAYS(H22, J22)) -> 1 | L22: 2026-08-13 | M22: =IF(OR(J22="", L22=""), "", NETWORKDAYS(J22, L22)) -> 1 | N22: RSE - Vérification technique avant travaux MDN Antsirabe | O22: SOCOTEC MADAGASCAR | P22: USD | Q22: 2510.8696 | R22: 2510.8696 | S22: =Q22-R22 -> 0 | V22: =IF(Q22="", "", Q22*10%) -> 251.08696 | W22: =IF(OR(Q22="", R22=""), "", (Q22- R22)/Q22) -> 0
B23: 19 | C23: Madagascar | D23: 136131 | E23: Yes | F23: 139161 | G23: 46224 | H23: 2026-07-30 | I23: =IF(OR(H23="", G23=""), "", NETWORKDAYS(G23, H23)) -> 8 | J23: 46237 | K23: =IF(OR(H23="", J23=""), "", NETWORKDAYS(H23, J23)) -> 3 | L23: 2026-08-03 | M23: =IF(OR(J23="", L23=""), "", NETWORKDAYS(J23, L23)) -> 1 | N23: Agents Intérimaires KYC | O23: LCS CONSULTING | P23: USD | Q23: 2287.0435 | R23: 2287.0435 | S23: =Q23-R23 -> 0 | V23: =IF(Q23="", "", Q23*10%) -> 228.70435 | W23: =IF(OR(Q23="", R23=""), "", (Q23- R23)/Q23) -> 0
B24: 20 | C24: Madagascar | D24: 136153 | E24: Yes | F24: 139145 | G24: 46224 | H24: 2026-07-31 | I24: =IF(OR(H24="", G24=""), "", NETWORKDAYS(G24, H24)) -> 9 | J24: 46237 | K24: =IF(OR(H24="", J24=""), "", NETWORKDAYS(H24, J24)) -> 2 | L24: 2026-08-03 | M24: =IF(OR(J24="", L24=""), "", NETWORKDAYS(J24, L24)) -> 1 | N24: Prestation intérimaire: 01 NOC Spécialist HC pour 4 mois (annulation BC n°135794)# DEVIS N°2873 | O24: MADAJOB | P24: USD | Q24: 573.28261 | R24: 573.28261 | S24: =Q24-R24 -> 0 | V24: =IF(Q24="", "", Q24*10%) -> 57.328261 | W24: =IF(OR(Q24="", R24=""), "", (Q24- R24)/Q24) -> 0
B25: 21 | C25: Madagascar | D25: 136506 | E25: Yes | F25: 139143 | G25: 46224 | H25: 2026-07-21 | I25: =IF(OR(H25="", G25=""), "", NETWORKDAYS(G25, H25)) -> 1 | J25: 46230 | K25: =IF(OR(H25="", J25=""), "", NETWORKDAYS(H25, J25)) -> 5 | L25: 46230 | M25: =IF(OR(J25="", L25=""), "", NETWORKDAYS(J25, L25)) -> 1 | N25: Calibration équipements de mesure HSE | O25: BCL (BUREAU DE CONTROLE LABOTECH) | P25: USD | Q25: 2760.8696 | R25: 2760.8696 | S25: =Q25-R25 -> 0 | V25: =IF(Q25="", "", Q25*10%) -> 276.08696 | W25: =IF(OR(Q25="", R25=""), "", (Q25- R25)/Q25) -> 0
B26: 22 | C26: Madagascar | D26: 136258 | E26: Yes | F26: 139202 | G26: 46225 | H26: 2026-07-23 | I26: =IF(OR(H26="", G26=""), "", NETWORKDAYS(G26, H26)) -> 2 | J26: 46241 | K26: =IF(OR(H26="", J26=""), "", NETWORKDAYS(H26, J26)) -> 12 | L26: 2026-08-10 | M26: =IF(OR(J26="", L26=""), "", NETWORKDAYS(J26, L26)) -> 2 | N26: Accompagnement 5S des dépôt AGL et ADV | O26: SUSTAINABLE MANAGEMENT SYSTEMS CONSULTING | P26: USD | Q26: 3710.9301 | R26: 3695.6522 | S26: =Q26-R26 -> 15.277899 | V26: =IF(Q26="", "", Q26*10%) -> 371.09301 | W26: =IF(OR(Q26="", R26=""), "", (Q26- R26)/Q26) -> 0.004117
B27: 23 | C27: Madagascar | D27: 136081 | E27: Yes | F27: 139174 | G27: 46225 | H27: 2026-07-31 | I27: =IF(OR(H27="", G27=""), "", NETWORKDAYS(G27, H27)) -> 8 | J27: 46237 | K27: =IF(OR(H27="", J27=""), "", NETWORKDAYS(H27, J27)) -> 2 | L27: 2026-08-03 | M27: =IF(OR(J27="", L27=""), "", NETWORKDAYS(J27, L27)) -> 1 | N27: Prestation intérimaire: 582 AR Terrain en Axe Régions pour 2 mois# FACTURE PROFORMA N°356-A/FP/TELMA /2026 DU 17/07/2026 | O27: LCS CONSULTING | P27: USD | Q27: 102153.65 | R27: 102153.65 | S27: =Q27-R27 -> 0 | V27: =IF(Q27="", "", Q27*10%) -> 10215.365 | W27: =IF(OR(Q27="", R27=""), "", (Q27- R27)/Q27) -> 0
B28: 24 | C28: Madagascar | D28: 136082 | E28: No | F28: 139206 | G28: 46225 | H28: 2026-07-30 | I28: =IF(OR(H28="", G28=""), "", NETWORKDAYS(G28, H28)) -> 7 | J28: 46237 | K28: =IF(OR(H28="", J28=""), "", NETWORKDAYS(H28, J28)) -> 3 | L28: 2026-08-03 | M28: =IF(OR(J28="", L28=""), "", NETWORKDAYS(J28, L28)) -> 1 | N28: REMBOURSEMENT IM AR & FRAIS COLIS & IM ADV | O28: LCS CONSULTING | P28: USD | Q28: 2027.2989 | R28: 2027.2989 | S28: =Q28-R28 -> 0 | V28: =IF(Q28="", "", Q28*10%) -> 202.72989 | W28: =IF(OR(Q28="", R28=""), "", (Q28- R28)/Q28) -> 0
B29: 25 | C29: Madagascar | D29: 136083 | E29: Yes | F29: 139190 | G29: 46225 | H29: 2026-07-31 | I29: =IF(OR(H29="", G29=""), "", NETWORKDAYS(G29, H29)) -> 8 | J29: 46237 | K29: =IF(OR(H29="", J29=""), "", NETWORKDAYS(H29, J29)) -> 2 | L29: 2026-08-03 | M29: =IF(OR(J29="", L29=""), "", NETWORKDAYS(J29, L29)) -> 1 | N29: Prestation intérimaire: 01 Analyste Fonctionnel VE pour 2 mois# FACTURE PROFORMA N°366-A/FP/TELMA/2026 DU 17/07/2026 | O29: LCS CONSULTING | P29: USD | Q29: 488.65217 | R29: 488.65217 | S29: =Q29-R29 -> 0 | V29: =IF(Q29="", "", Q29*10%) -> 48.865217 | W29: =IF(OR(Q29="", R29=""), "", (Q29- R29)/Q29) -> 0
B30: 26 | C30: Madagascar | D30: 136084 | E30: Yes | F30: 139173 | G30: 46225 | H30: 2026-07-31 | I30: =IF(OR(H30="", G30=""), "", NETWORKDAYS(G30, H30)) -> 8 | J30: 46237 | K30: =IF(OR(H30="", J30=""), "", NETWORKDAYS(H30, J30)) -> 2 | L30: 2026-08-03 | M30: =IF(OR(J30="", L30=""), "", NETWORKDAYS(J30, L30)) -> 1 | N30: Prestation intérimaire: 75 AR Roadshow pour 2 mois# FACTURE PROFORMA N°355-A/FP/TELMA /2026 DU 17/07/2026 | O30: LCS CONSULTING | P30: USD | Q30: 13164.13 | R30: 13164.13 | S30: =Q30-R30 -> 0 | V30: =IF(Q30="", "", Q30*10%) -> 1316.413 | W30: =IF(OR(Q30="", R30=""), "", (Q30- R30)/Q30) -> 0
B31: 27 | C31: Madagascar | D31: 136085 | E31: No | F31: 139200 | G31: 46225 | H31: 2026-07-28 | I31: =IF(OR(H31="", G31=""), "", NETWORKDAYS(G31, H31)) -> 5 | J31: 46237 | K31: =IF(OR(H31="", J31=""), "", NETWORKDAYS(H31, J31)) -> 5 | L31: 2026-08-03 | M31: =IF(OR(J31="", L31=""), "", NETWORKDAYS(J31, L31)) -> 1 | N31: COLLATION LE 24/07/2026 | O31: SOCIETE DE GESTION ET EXPLOITATION DE M/CAR | P31: USD | Q31: 26.086957 | R31: 26.086957 | S31: =Q31-R31 -> 0 | V31: =IF(Q31="", "", Q31*10%) -> 2.6086957 | W31: =IF(OR(Q31="", R31=""), "", (Q31- R31)/Q31) -> 0
B32: 28 | C32: Madagascar | D32: 136132 | E32: Yes | F32: 139194 | G32: 46231 | H32: 2026-07-31 | I32: =IF(OR(H32="", G32=""), "", NETWORKDAYS(G32, H32)) -> 4 | J32: 46237 | K32: =IF(OR(H32="", J32=""), "", NETWORKDAYS(H32, J32)) -> 2 | L32: 2026-08-03 | M32: =IF(OR(J32="", L32=""), "", NETWORKDAYS(J32, L32)) -> 1 | N32: Prestation intérimaire: IM 66 AR Terrain en Siège pour 2 mois# FACTURE PROFORMA N° 376-A/FP/TELMA /2026 du 17/07/2026 | O32: LCS CONSULTING | P32: USD | Q32: 5229.7826 | R32: 5229.7826 | S32: =Q32-R32 -> 0 | V32: =IF(Q32="", "", Q32*10%) -> 522.97826 | W32: =IF(OR(Q32="", R32=""), "", (Q32- R32)/Q32) -> 0
B33: 29 | C33: Madagascar | D33: 136133 | E33: Yes | F33: 139193 | G33: 46231 | H33: 2026-07-31 | I33: =IF(OR(H33="", G33=""), "", NETWORKDAYS(G33, H33)) -> 4 | J33: 46237 | K33: =IF(OR(H33="", J33=""), "", NETWORKDAYS(H33, J33)) -> 2 | L33: 2026-08-03 | M33: =IF(OR(J33="", L33=""), "", NETWORKDAYS(J33, L33)) -> 1 | N33: Prestation intérimaire: IM 37 CT Tanà et Régions pour 2 mois# FACTURE PROFORMA N° 375-A/FP/TELMA /2026 DU 17/07/2026 | O33: LCS CONSULTING | P33: USD | Q33: 7721.7391 | R33: 7721.7391 | S33: =Q33-R33 -> 0 | V33: =IF(Q33="", "", Q33*10%) -> 772.17391 | W33: =IF(OR(Q33="", R33=""), "", (Q33- R33)/Q33) -> 0
B34: 30 | C34: Madagascar | D34: 136134 | E34: Yes | F34: 139192 | G34: 46231 | H34: 2026-07-31 | I34: =IF(OR(H34="", G34=""), "", NETWORKDAYS(G34, H34)) -> 4 | J34: 46237 | K34: =IF(OR(H34="", J34=""), "", NETWORKDAYS(H34, J34)) -> 2 | L34: 2026-08-03 | M34: =IF(OR(J34="", L34=""), "", NETWORKDAYS(J34, L34)) -> 1 | N34: Prestation intérimaire: IM 75 AR Roadshow Régions pour 2 mois# FACTURE PROFORMA N°374-A/FP/TELMA/2026 DU 17/07/2026 | O34: LCS CONSULTING | P34: USD | Q34: 11885.87 | R34: 11885.87 | S34: =Q34-R34 -> 0 | V34: =IF(Q34="", "", Q34*10%) -> 1188.587 | W34: =IF(OR(Q34="", R34=""), "", (Q34- R34)/Q34) -> 0
B35: 31 | C35: Madagascar | D35: 136135 | E35: Yes | F35: 139191 | G35: 46231 | H35: 2026-07-31 | I35: =IF(OR(H35="", G35=""), "", NETWORKDAYS(G35, H35)) -> 4 | J35: 46237 | K35: =IF(OR(H35="", J35=""), "", NETWORKDAYS(H35, J35)) -> 2 | L35: 2026-08-03 | M35: =IF(OR(J35="", L35=""), "", NETWORKDAYS(J35, L35)) -> 1 | N35: Prestation intérimaire: IM 05 AR Micro Régions pour 2 mois# FACTURE PROFORMA N°373-A/FP/TELMA /2026 DU 17/07/2026 | O35: LCS CONSULTING | P35: USD | Q35: 792.3913 | R35: 792.3913 | S35: =Q35-R35 -> 0 | V35: =IF(Q35="", "", Q35*10%) -> 79.23913 | W35: =IF(OR(Q35="", R35=""), "", (Q35- R35)/Q35) -> 0
B36: 32 | C36: Madagascar | D36: 136136 | E36: Yes | F36: 139189 | G36: 46231 | H36: 2026-07-31 | I36: =IF(OR(H36="", G36=""), "", NETWORKDAYS(G36, H36)) -> 4 | J36: 46237 | K36: =IF(OR(H36="", J36=""), "", NETWORKDAYS(H36, J36)) -> 2 | L36: 2026-08-03 | M36: =IF(OR(J36="", L36=""), "", NETWORKDAYS(J36, L36)) -> 1 | N36: Prestation intérimaire: Logement 22 Tech Pol pour 2 mois# FACTURE PROFORMA N°372-A/FP/TELMA/2026 DU 17/07/2026 | O36: LCS CONSULTING | P36: USD | Q36: 827 | R36: 827 | S36: =Q36-R36 -> 0 | V36: =IF(Q36="", "", Q36*10%) -> 82.7 | W36: =IF(OR(Q36="", R36=""), "", (Q36- R36)/Q36) -> 0
B37: 33 | C37: Madagascar | D37: 136137 | E37: Yes | F37: 139188 | G37: 46231 | H37: 2026-07-31 | I37: =IF(OR(H37="", G37=""), "", NETWORKDAYS(G37, H37)) -> 4 | J37: 46237 | K37: =IF(OR(H37="", J37=""), "", NETWORKDAYS(H37, J37)) -> 2 | L37: 2026-08-03 | M37: =IF(OR(J37="", L37=""), "", NETWORKDAYS(J37, L37)) -> 1 | N37: Prestation intérimaire: 23 Tech Pol pour 2 mois# FACTURE PROFORMA N°371-A/FP/TELMA/2026 du 17/07/2026 | O37: LCS CONSULTING | P37: USD | Q37: 10944 | R37: 10944 | S37: =Q37-R37 -> 0 | V37: =IF(Q37="", "", Q37*10%) -> 1094.4 | W37: =IF(OR(Q37="", R37=""), "", (Q37- R37)/Q37) -> 0
... B132: 130 | C132: Madagascar | D132: 136271 | E132: Yes | F132: 139327 | G132: 46233 | H132: 2026-08-05 | I132: =IF(OR(H132="", G132=""), "", NETWORKDAYS(G132, H132)) -> 5 | J132: 46245 | K132: =IF(OR(H132="", J132=""), "", NETWORKDAYS(H132, J132)) -> 5 | L132: 2026-08-11 | M132: =IF(OR(J132="", L132=""), "", NETWORKDAYS(J132, L132)) -> 1 | N132: Transport et Manut 50 Poteaux ANTALAHA vers SAMBAVA | O132: LUCKKY COMPANY | P132: USD | Q132: 652.17391 | R132: 652.17391 | S132: =Q132-R132 -> 0 | V132: =IF(Q132="", "", Q132*10%) -> 65.217391 | W132: =IF(OR(Q132="", R132=""), "", (Q132- R132)/Q132) -> 0
B133: 131 | C133: Madagascar | D133: 136545 | E133: Yes | F133: 139332 | G133: 46233 | H133: 2026-08-05 | I133: =IF(OR(H133="", G133=""), "", NETWORKDAYS(G133, H133)) -> 5 | J133: 46242 | K133: =IF(OR(H133="", J133=""), "", NETWORKDAYS(H133, J133)) -> 3 | L133: 46244 | M133: =IF(OR(J133="", L133=""), "", NETWORKDAYS(J133, L133)) -> 1 | N133: BLACK BOX COMPLEMENTAIRE BC135734 | O133: BLACK BOX | P133: USD | Q133: 1743.3 | R133: 1743.3 | S133: =Q133-R133 -> 0 | V133: =IF(Q133="", "", Q133*10%) -> 174.33 | W133: =IF(OR(Q133="", R133=""), "", (Q133- R133)/Q133) -> 0
B134: 132 | C134: Madagascar | D134: 136078 | E134: Yes | F134: 139362 | G134: 46234 | H134: 2026-08-03 | I134: =IF(OR(H134="", G134=""), "", NETWORKDAYS(G134, H134)) -> 2 | J134: 46237 | K134: =IF(OR(H134="", J134=""), "", NETWORKDAYS(H134, J134)) -> 1 | L134: 2026-08-03 | M134: =IF(OR(J134="", L134=""), "", NETWORKDAYS(J134, L134)) -> 1 | N134: Location LCD-Mission Tafita à Mahanoro 05 au 12 Août 2026 | O134: LOXEA MADAGASCAR | P134: USD | Q134: 573.91304 | R134: 552.17391 | S134: =Q134-R134 -> 21.73913 | V134: =IF(Q134="", "", Q134*10%) -> 57.391304 | W134: =IF(OR(Q134="", R134=""), "", (Q134- R134)/Q134) -> 0.037878788
B135: 133 | C135: Madagascar | D135: 136079 | E135: Yes | F135: 139295 | G135: 46234 | H135: 2026-08-03 | I135: =IF(OR(H135="", G135=""), "", NETWORKDAYS(G135, H135)) -> 2 | J135: 46237 | K135: =IF(OR(H135="", J135=""), "", NETWORKDAYS(H135, J135)) -> 1 | L135: 2026-08-03 | M135: =IF(OR(J135="", L135=""), "", NETWORKDAYS(J135, L135)) -> 1 | N135: Achat 15000 Enveloppes GM En tête pour facturation | O135: MEGAPRINT | P135: USD | Q135: 465.34526 | R135: 398.97698 | S135: =Q135-R135 -> 66.368283 | V135: =IF(Q135="", "", Q135*10%) -> 46.534526 | W135: =IF(OR(Q135="", R135=""), "", (Q135- R135)/Q135) -> 0.14262159
B136: 134 | C136: Madagascar | D136: 136089 | E136: No | F136: 139357 | G136: 46234 | H136: 2026-07-31 | I136: =IF(OR(H136="", G136=""), "", NETWORKDAYS(G136, H136)) -> 1 | J136: 46237 | K136: =IF(OR(H136="", J136=""), "", NETWORKDAYS(H136, J136)) -> 2 | L136: 2026-08-03 | M136: =IF(OR(J136="", L136=""), "", NETWORKDAYS(J136, L136)) -> 1 | N136: HOUSSE CHAPITEAU | O136: MORA MARKET | P136: USD | Q136: 1762.5 | R136: 1762.5 | S136: =Q136-R136 -> 0 | V136: =IF(Q136="", "", Q136*10%) -> 176.25 | W136: =IF(OR(Q136="", R136=""), "", (Q136- R136)/Q136) -> 0
...

Sheet Customs_Clearance
B1: OPCOS MONTHLY CUSTOMS CLEARANCE TRACKER
C2: use same OpCo spelling as in the Dashboard | I2: SEA/AIR fromat only | J2: Date in MM/DD/YYYY format | K2: Date in MM/DD/YYYY format | L2: Automatic Formula
B4: N° | C4: OPCO | D4: PO reference | E4: Designation | F4: Vendor | G4: Incoterm | H4: Custom Clearance Partner | I4: SEA/AIR | J4: Date of Arrival in Country | K4: Date of Warehouse Delivery | L4: GRN (TAT) | M4: Agreed SLA days
B5: 1 | C5: Madagascar | D5: 134118 | E5: 128 K LTE SIM | F5: VALID | I5: SEA | J5: 46241 | K5: 46254 | L5: =IF(OR(J5="", K5=""), "", NETWORKDAYS(J5,K5)) -> 10 | M5: =IF(I5="SEA", 10, IF(I5="AIR", 5, "")) -> 10
B6: 2 | C6: Madagascar | D6: 134287 | E6: FIRE EMERGENCY LIGHT | F6: TRIDENT | I6: AIR | J6: 46233 | K6: 46238 | L6: =IF(OR(J6="", K6=""), "", NETWORKDAYS(J6,K6)) -> 4 | M6: =IF(I6="SEA", 10, IF(I6="AIR", 5, "")) -> 5
B7: 3 | C7: Madagascar | D7: 1333222 | E7: DIRECTIONAL ANTENNA | F7: PROJET PHOENIX HUAWEI | I7: SEA | J7: 46248 | K7: 46260 | L7: =IF(OR(J7="", K7=""), "", NETWORKDAYS(J7,K7)) -> 9 | M7: =IF(I7="SEA", 10, IF(I7="AIR", 5, "")) -> 10
B8: 4 | C8: Madagascar | D8: 134142 | E8: POINT ACCES ROCKET | F8: NF TECH | I8: AIR | J8: 46245 | K8: 46251 | L8: =IF(OR(J8="", K8=""), "", NETWORKDAYS(J8,K8)) -> 5 | M8: =IF(I8="SEA", 10, IF(I8="AIR", 5, "")) -> 5
B9: 5 | C9: Madagascar | D9: 134610 | E9: OPTICAL TRANSCEIVER | F9: HUAWEI | I9: AIR | J9: 46245 | K9: 46248 | L9: =IF(OR(J9="", K9=""), "", NETWORKDAYS(J9,K9)) -> 4 | M9: =IF(I9="SEA", 10, IF(I9="AIR", 5, "")) -> 5
B10: 7 | C10: Madagascar | D10: 134379 | E10: KIT DROP CABLE | F10: GEKA | I10: AIR | J10: 46245 | K10: 46248 | L10: =IF(OR(J10="", K10=""), "", NETWORKDAYS(J10,K10)) -> 4 | M10: =IF(I10="SEA", 10, IF(I10="AIR", 5, "")) -> 5
B11: 8 | C11: Madagascar | D11: 135045 | E11: DECLENCHEUR GODOX | F11: OBJECTIF BASTILLE | I11: AIR | J11: 46248 | K11: 46252 | L11: =IF(OR(J11="", K11=""), "", NETWORKDAYS(J11,K11)) -> 3 | M11: =IF(I11="SEA", 10, IF(I11="AIR", 5, "")) -> 5
B12: 9 | C12: Madagascar | D12: 136002 | E12: ETIQUETEUSE | F12: GEKA | I12: AIR | J12: 46248 | K12: 46254 | L12: =IF(OR(J12="", K12=""), "", NETWORKDAYS(J12,K12)) -> 5 | M12: =IF(I12="SEA", 10, IF(I12="AIR", 5, "")) -> 5
B13: 12 | C13: Madagascar | D13: 135080 | E13: LASER TRANCEIVER | F13: HUAWEI | I13: AIR | J13: 46258 | K13: 46262 | L13: =IF(OR(J13="", K13=""), "", NETWORKDAYS(J13,K13)) -> 5 | M13: =IF(I13="SEA", 10, IF(I13="AIR", 5, "")) -> 5
B14: 13 | C14: Madagascar | D14: 135180 | E14: PEHD 27/32 + 34/40 | F14: SAGEMCOM | I14: SEA | J14: 46258 | K14: 46270 | L14: =IF(OR(J14="", K14=""), "", NETWORKDAYS(J14,K14)) -> 10 | M14: =IF(I14="SEA", 10, IF(I14="AIR", 5, "")) -> 10
B15: 14 | C15: Madagascar | D15: 134378 | E15: PBO T2 PRECO | F15: GEKA | I15: AIR | J15: 46256 | K15: 46259 | L15: =IF(OR(J15="", K15=""), "", NETWORKDAYS(J15,K15)) -> 2 | M15: =IF(I15="SEA", 10, IF(I15="AIR", 5, "")) -> 5
B16: 15 | C16: Madagascar | D16: 136318 | E16: VEVOR ANEMOMETRE | F16: GEKA | I16: AIR | J16: 46259 | K16: 46265 | L16: =IF(OR(J16="", K16=""), "", NETWORKDAYS(J16,K16)) -> 5 | M16: =IF(I16="SEA", 10, IF(I16="AIR", 5, "")) -> 5
B17: 17 | L17: =IF(OR(J17="", K17=""), "", NETWORKDAYS(J17,K17)) | M17: =IF(I17="SEA", 10, IF(I17="AIR", 5, ""))
B18: 18 | L18: =IF(OR(J18="", K18=""), "", NETWORKDAYS(J18,K18)) | M18: =IF(I18="SEA", 10, IF(I18="AIR", 5, ""))
B19: 19 | L19: =IF(OR(J19="", K19=""), "", NETWORKDAYS(J19,K19)) | M19: =IF(I19="SEA", 10, IF(I19="AIR", 5, ""))
B20: 20 | L20: =IF(OR(J20="", K20=""), "", NETWORKDAYS(J20,K20)) | M20: =IF(I20="SEA", 10, IF(I20="AIR", 5, ""))
B21: 21 | L21: =IF(OR(J21="", K21=""), "", NETWORKDAYS(J21,K21)) | M21: =IF(I21="SEA", 10, IF(I21="AIR", 5, ""))
B22: 22 | L22: =IF(OR(J22="", K22=""), "", NETWORKDAYS(J22,K22)) | M22: =IF(I22="SEA", 10, IF(I22="AIR", 5, ""))
B23: 23 | L23: =IF(OR(J23="", K23=""), "", NETWORKDAYS(J23,K23)) | M23: =IF(I23="SEA", 10, IF(I23="AIR", 5, ""))
B24: 24 | L24: =IF(OR(J24="", K24=""), "", NETWORKDAYS(J24,K24)) | M24: =IF(I24="SEA", 10, IF(I24="AIR", 5, ""))
B25: 25 | L25: =IF(OR(J25="", K25=""), "", NETWORKDAYS(J25,K25)) | M25: =IF(I25="SEA", 10, IF(I25="AIR", 5, ""))
B26: 26 | L26: =IF(OR(J26="", K26=""), "", NETWORKDAYS(J26,K26)) | M26: =IF(I26="SEA", 10, IF(I26="AIR", 5, ""))
B27: 27 | L27: =IF(OR(J27="", K27=""), "", NETWORKDAYS(J27,K27)) | M27: =IF(I27="SEA", 10, IF(I27="AIR", 5, ""))
B28: 28 | L28: =IF(OR(J28="", K28=""), "", NETWORKDAYS(J28,K28)) | M28: =IF(I28="SEA", 10, IF(I28="AIR", 5, ""))
... B702: 704 | L702: =IF(OR(J702="", K702=""), "", NETWORKDAYS(J702,K702)) | M702: =IF(I702="SEA", 10, IF(I702="AIR", 5, ""))

Sheet Open Projects
A1: Entity Initiator | B1: OpCo | C1: Category | D1: Project | E1: Overall Status | F1: Project description | G1: Business Owner | H1: Number of suppliers contacted | I1: RFP Received | J1: RFP Issuance | K1: RFP Offer date | L1: Status | M1: Action Owner | N1: Selected supplier | O1: Initial price | P1: Final price | Q1: SAVING | R1: Contract start date | S1: Contract signature target date | T1: Actual Contract signature date | U1: Tender target closing date | V1: Buyer | W1: Supplier 1 | X1: Supplier 2 | Y1: Supplier 3 | Z1: Supplier 4 | AA1: Supplier 5 | AB1: Supplier 6 | AC1: Supplier 7 | AD1: Supplier 8 | AE1: Supplier 9 | AF1: Supplier 10 | AG1: Supplier 11
A2: Yas Comores | B2: COMOROS | C2: TELECOM | D2: Civil engineering works and installation of 5GE on sites | E2: OFFER | F2: Civil engineering works and installation of 5GE on sites. | G2: Ando | H2: 6 | I2: 45988 | J2: 45989 | K2: 45994 | L2: Purchase request submitted today, 19/02/2026. | M2: Chimba Nghemning Henri | N2: Entreprise OBT | O2: 119833.84 | P2: 103057.1 | Q2: =O2-P2 -> 16776.74 | V2: Issoufi Djamal-Edine | W2: Entreprise OBT | X2: ELM construction | Y2: Societé Nahouza | Z2: STE Beta | AA2: Bundo construct | AB2: Sec Daniel
A3: Yas Comores | B3: COMOROS | C3: TELECOM | D3: Fiber-optic connection works for El Maarouf Hospital | E3: OFFER | F3: Fiber-optic connection works for El Maarouf Hospital. | G3: Sidi Aman Ahmed | H3: 4 | I3: 46020 | J3: 46021 | K3: 46027 | L3: Work in Progress | M3: Sidi Aman Ahmed | N3: ELM construction | O3: 30516.44 | P3: 28018.52 | Q3: =O3-P3 -> 2497.92 | R3: 46049 | S3: No contrat | T3: No contrat | U3: 46027 | V3: Issoufi Djamal-Edine | W3: ELM construction | X3: Entreprise OBT | Y3: STE Beta | Z3: Bundo construct
A4: Yas Comores | B4: COMOROS | C4: TELECOM | D4: MPox prevention (hydroalcoholic gels) | E4: CLOSED | F4: Hydroalcoholic gels for Mpox prevention. | G4: Raymane Ali Matoir | H4: 2 | I4: 46041 | J4: 46043 | K4: 46046 | L4: Closed. | N4: Ocopharma | O4: 4749 | P4: 4749 | Q4: =O4-P4 -> 0 | R4: 46058 | S4: No contrat | T4: No contrat | U4: 46046 | V4: Issoufi Djamal-Edine | W4: Ocopharma | X4: Ligapharma
A5: Yas Comores | B5: COMOROS | C5: TELECOM | D5: Laptop acquisition | E5: EVALUATION | F5: The project consists of assigning laptops based on actual needs: standard models are intended for roles with simple tasks, while high-end laptops are reserved for employees using tools or software requiring higher performance. | G5: Ahmed Mohamed | H5: 4 | I5: 46028 | J5: 46042 | K5: 46050 | L5: Waiting for validation of the 2026 Facilities IT budget to confirm, together with Olivier (financial controller), the extent to which purchases can be committed. This validation is essential to determine the exact acquisition volume based on supplier prices. | M5: Nazlye/ Olivier | Q5: =O5-P5 -> 0 | V5: Issoufi Djamal-Edine | W5: Fan pro services | X5: Hakimi multimedia | Y5: Pateterie des Comores | Z5: Mak technoligie
A6: Yas Comores | B6: COMOROS | C6: TELECOM | D6: FTTX equipment acquisition | E6: RFI | F6: Equipment for FTTX installations. | G6: Karim Attoumani Mohamed | H6: 6 | I6: 46035 | J6: 46036 | K6: 46048 | L6: A supplier consultation was launched locally for the acquisition of this equipment. However, since it is not available in the country, it must be ordered from abroad, with a delivery lead time of 15–20 days. We are currently awaiting technical offers; once received and a supplier is selected, we will issue the purchase order. | M6: Irchad Radjabou | Q6: =O6-P6 -> 0 | V6: Issoufi Djamal-Edine | W6: Comores multiservices | X6: Hakimi multimedia | Y6: Fan pro services | Z6: Magasin said Hassane Fils | AA6: Rehamani SARL | AB6: Photo soleil
A7: Yas Comores | B7: COMOROS | C7: TELECOM | D7: Ubiquiti equipment purchase | E7: OFFER | F7: Ubiquiti stock order | G7: Karim Attoumani Mohamed | H7: 4 | I7: 46035 | J7: 46037 | K7: 46042 | L7: The purchase order has been sent to the supplier. Part of the goods has been received, and we are awaiting the remaining items. | M7: Supplier | N7: Fan pro services/ Hakimi multimedia/ Comores multiservices | O7: =26213.93+71213.34+92722.3 -> 190149.57 | P7: =28835.33+64056.74+83058.29 -> 175950.36 | Q7: =O7-P7 -> 14199.21 | R7: 46056 | S7: No contrat for supplier 1&3. in Progress for 2 | T7: No contrat for supplier 1&3. in Progress for 2 | V7: Issoufi Djamal-Edine | W7: Fan pro services | X7: Hakimi multimedia | Y7: Comores multiservices | Z7: Pateterie des Comores
A8: Yas Comores | B8: COMOROS | C8: TELECOM | D8: store Djivani concrete floor renovation works | E8: OFFER | F8: This project concerns concrete floor refurbishment works around the Djivani Store. | G8: Chenaz Abdallah | H8: 3 | I8: 46037 | J8: 46059 | K8: 46071 | L8: PO under processing by Procurement | M8: Bachir Houamadi | N8: NLN | O8: 14246.7 | P8: 14246.7 | Q8: =O8-P8 -> 0 | V8: Issoufi Djamal-Edine | W8: NLN | X8: STC
A9: Yas Comores | B9: COMOROS | C9: TELECOM | D9: Purchase of 12 KVA generator | E9: CLOSED | F9: 12 KVA generator for the Mitsamihouli shop due to frequent power outages, which risk slowing down or interrupting commercial activities. | G9: Chimba Nghemning Henri | H9: 1 | I9: 46066 | J9: 46066 | K9: 46068 | L9: Closed. | N9: Electro foid | O9: 5876.76 | P9: 5283.15 | Q9: =O9-P9 -> 593.61 | R9: 46058 | S9: No contrat | T9: No contrat | U9: 46052 | V9: Issoufi Djamal-Edine | W9: Electro froid

Sheet Open Projects Pivot
A1: Overall Status | B1: (Multiple Items)
A3: Count of Project | B3: Column Labels
A4: Row Labels | B4: COMOROS | C4: Grand Total
A5: TELECOM | B5: 6 | C5: 6
A6: Grand Total | B6: 6 | C6: 6
A9: Category | B9: (All)
A11: Count of Project | B11: Column Labels
A12: Row Labels | B12: COMOROS | C12: Grand Total
A13: CLOSED | B13: 2 | C13: 2
A14: EVALUATION | B14: 1 | C14: 1
A15: OFFER | B15: 4 | C15: 4
A16: RFI | B16: 1 | C16: 1
A17: Grand Total | B17: 8 | C17: 8
A18: Overall Status | B18: (Multiple Items)
A20: Sum of SAVING | B20: Column Labels
A21: Row Labels | B21: COMOROS | C21: Grand Total
A22: TELECOM | B22: 33473.87 | C22: 33473.87
A23: Grand Total | B23: 33473.87 | C23: 33473.87

Sheet List
A1: Category | C1: Global Status
A2: Commercial D&S | C2: CANCELLED
A3: Communication | C3: CLOSED
A4: CONSULTING | C4: COMINVEST
A5: DEVICE | C5: CONTRACT
A6: GROUP | C6: EVALUATION
A7: HR | C7: NEEDS
A8: IT | C8: NEGO
A9: OTHERS | C9: OFFER
A10: OTHERS / SERVICES CONSULTANCY | C10: RFI
A11: SIM | C11: RFP
A12: TELECOM | C12: STAND BY
A13: VEHICLE | C13: (vide)

Sheet PPOT
B1: OPCOS MONTHLY PPOT TRACKER
C2: use same OpCo spelling as in the Dashboard | J2: 421.75 | K2: Date in MM/DD/YYYY format | L2: agreed paypment term with Supplier | M2: Date in MM/DD/YYYY format | N2: Automatic Formula | O2: Automatic Formula
B4: N° | C4: OPCO | D4: Invoice Ref | E4: PO Ref | F4: Designation | G4: Partner | I4: Invoice Amount | J4: Currency usd | K4: Invoice Receipt Date | L4: Agreed Payment Days/Jours (Terms) | M4: Invoice Payment Date | N4: Invoice Payment (TAT) | O4: PPOT (Yes/No)
B5: 1 | C5: Madagascar | D5: INV/2026/00032 | E5: 134706 | F5: Titre de Sponsor Gold | G5: OKALOU EVENT | I5: 2125 | J5: USD | K5: 46220 | L5: 30 | M5: 46247 | N5: =IF(OR(M5="", K5=""),"", M5- K5) -> 27 | O5: =IF(OR(M5="", K5="", L5=""), "", IF((M5 - K5) > L5, "No", "Yes")) -> Yes
B6: 2 | C6: Madagascar | D6: LN/00159/26 | E6: 133475 | F6: LES NOUVELLES/Publicité JNAV 2026 | G6: ULTIMA MEDIA | I6: 1704.886 | J6: USD | K6: 46210 | L6: 30 | M6: 46235 | N6: =IF(OR(M6="", K6=""),"", M6- K6) -> 25 | O6: =IF(OR(M6="", K6="", L6=""), "", IF((M6 - K6) > L6, "No", "Yes")) -> Yes
B7: 3 | C7: Madagascar | D7: TR/00098/26 | E7: 133475 | F7: TARATRA MARS 2026 | G7: ULTIMA MEDIA | I7: 1788.1095 | J7: USD | K7: 46210 | L7: 30 | M7: 46246 | N7: =IF(OR(M7="", K7=""),"", M7- K7) -> 36 | O7: =IF(OR(M7="", K7="", L7=""), "", IF((M7 - K7) > L7, "No", "Yes")) -> No
B8: 4 | C8: Madagascar | D8: LN/00494/26 | E8: 133475 | F8: LES NOUVELLES/Publicité mois de mars 2026 | G8: ULTIMA MEDIA | I8: 1788.1095 | J8: USD | K8: 46210 | L8: 30 | M8: 46247 | N8: =IF(OR(M8="", K8=""),"", M8- K8) -> 37 | O8: =IF(OR(M8="", K8="", L8=""), "", IF((M8 - K8) > L8, "No", "Yes")) -> No
B9: 5 | C9: Madagascar | D9: 226/2026 | E9: 134858 | F9: JTVM MARS 2026 | G9: KOLO TV (SMPC) | I9: 1100 | J9: USD | K9: 46177 | L9: 30 | M9: 46206 | N9: =IF(OR(M9="", K9=""),"", M9- K9) -> 29 | O9: =IF(OR(M9="", K9="", L9=""), "", IF((M9 - K9) > L9, "No", "Yes")) -> Yes
B10: 6 | C10: Madagascar | D10: 414/2026 | E10: 134858 | F10: JVTM MOIS DE MAI 2026 | G10: KOLO TV (SMPC) | I10: 1100 | J10: USD | K10: 46177 | L10: 30 | M10: 46205 | N10: =IF(OR(M10="", K10=""),"", M10- K10) -> 28 | O10: =IF(OR(M10="", K10="", L10=""), "", IF((M10 - K10) > L10, "No", "Yes")) -> Yes
B11: 7 | C11: Madagascar | D11: 330/2026 | E11: 134858 | F11: PACK PARRAINAGE AVRIL 2026 | G11: KOLO TV (SMPC) | I11: 1100 | J11: USD | K11: 46177 | L11: 30 | M11: 46213 | N11: =IF(OR(M11="", K11=""),"", M11- K11) -> 36 | O11: =IF(OR(M11="", K11="", L11=""), "", IF((M11 - K11) > L11, "No", "Yes")) -> No
B12: 8 | C12: Madagascar | D12: FAC/OT/2026/8511 | E12: 134643 | F12: RALLONGE D'UTILISATION NEW DUSTER 53044WWT - | G12: OCEAN TRADE CO | I12: 1717.5 | J12: USD | K12: 46177 | L12: 30 | M12: 46212 | N12: =IF(OR(M12="", K12=""),"", M12- K12) -> 35 | O12: =IF(OR(M12="", K12="", L12=""), "", IF((M12 - K12) > L12, "No", "Yes")) -> No
B13: 9 | C13: Madagascar | D13: FAC/OT/2026/8512 | E13: 134638 | F13: REPARATION AVEC PIECES DE RECHANGES | G13: OCEAN TRADE CO | I13: 1804.18 | J13: USD | K13: 46177 | L13: 30 | M13: 46205 | N13: =IF(OR(M13="", K13=""),"", M13- K13) -> 28 | O13: =IF(OR(M13="", K13="", L13=""), "", IF((M13 - K13) > L13, "No", "Yes")) -> Yes
B14: 10 | C14: Madagascar | D14: FAC/OT/2026/8514 | E14: 133870 | F14: RALLONGE D'UTILISATION - 56887WWT | G14: OCEAN TRADE CO | I14: 1495 | J14: USD | K14: 46177 | L14: 30 | M14: 46202 | N14: =IF(OR(M14="", K14=""),"", M14- K14) -> 25 | O14: =IF(OR(M14="", K14="", L14=""), "", IF((M14 - K14) > L14, "No", "Yes")) -> Yes
B15: 11 | C15: Madagascar | D15: FAC/OT/2026/9287 | E15: 134956 | F15: RALLONGE D'UTILISATION | G15: OCEAN TRADE CO | I15: 496.16665 | J15: USD | K15: 46190 | L15: 30 | M15: 46216 | N15: =IF(OR(M15="", K15=""),"", M15- K15) -> 26 | O15: =IF(OR(M15="", K15="", L15=""), "", IF((M15 - K15) > L15, "No", "Yes")) -> Yes
B16: 12 | C16: Madagascar | D16: 0215/MOTO/2026 | E16: 135154 | F16: COFI 2026 - MOTO GRS IMPROVE EVOLUTION | G16: MADAGASCAR AUTOMOBILE | I16: 6414.5837 | J16: USD | K16: 46197 | L16: 30 | M16: 46222 | N16: =IF(OR(M16="", K16=""),"", M16- K16) -> 25 | O16: =IF(OR(M16="", K16="", L16=""), "", IF((M16 - K16) > L16, "No", "Yes")) -> Yes
... B18: 14 | C18: Madagascar | D18: 0217/MOTO/2026 | E18: 135331 | F18: COFI 2026 - MOTO GRS ADR MOBILE | G18: MADAGASCAR AUTOMOBILE | I18: 1135.4168 | J18: USD | K18: 46198 | L18: 30 | M18: 46235 | N18: =IF(OR(M18="", K18=""),"", M18- K18) -> 37 | O18: =IF(OR(M18="", K18="", L18=""), "", IF((M18 - K18) > L18, "No", "Yes")) -> No
B19: 15 | C19: Madagascar | D19: 134962 | E19: 134962 | F19: Séminaire RAS 2026 - Ambanja | G19: BAR HERMES | I19: 496.875 | J19: USD | K19: 46196 | L19: 30 | M19: 46227 | N19: =IF(OR(M19="", K19=""),"", M19- K19) -> 31 | O19: =IF(OR(M19="", K19="", L19=""), "", IF((M19 - K19) > L19, "No", "Yes")) -> No
B20: 16 | C20: Madagascar | D20: 001/06/2026 | E20: 135446 | F20: Sponsoring Body Perfect 2026 | G20: FEDERATION MALAGASY DE BODYBUILDING | I20: 1041.6667 | J20: USD | K20: 46204 | L20: 30 | M20: 46236 | N20: =IF(OR(M20="", K20=""),"", M20- K20) -> 32 | O20: =IF(OR(M20="", K20="", L20=""), "", IF((M20 - K20) > L20, "No", "Yes")) -> No
B21: 17 | C21: Madagascar | D21: 22/2026/F | E21: 135531 | F21: Séminaire RAS_RC Bongolava | G21: RAFARASOA SUZANNE (HORIZON) | I21: 381.25 | J21: USD | K21: 46259 | L21: 30 | M21: 46262 | N21: =IF(OR(M21="", K21=""),"", M21- K21) -> 3 | O21: =IF(OR(M21="", K21="", L21=""), "", IF((M21 - K21) > L21, "No", "Yes")) -> Yes
B22: 18 | C22: Madagascar | D22: sn | E22: 135805 | F22: SFM1_135805_135805_Partenariat Commune Moramanga | G22: Association SFM | I22: 2604.1667 | J22: USD | K22: 46216 | L22: 30 | M22: 46239 | N22: =IF(OR(M22="", K22=""),"", M22- K22) -> 23 | O22: =IF(OR(M22="", K22="", L22=""), "", IF((M22 - K22) > L22, "No", "Yes")) -> Yes
B23: 19 | C23: Madagascar | D23: CN-00863 | E23: 135260 | F23: MADAJOB1_AVOIR Frais de transport JUIN 2026_FA N°CN-00863_BC 135260 | G23: MADAJOB | I23: -71.875 | J23: USD | K23: 46209 | L23: 30 | M23: 46238 | N23: =IF(OR(M23="", K23=""),"", M23- K23) -> 29 | O23: =IF(OR(M23="", K23="", L23=""), "", IF((M23 - K23) > L23, "No", "Yes")) -> Yes
B24: 20 | C24: Madagascar | D24: SN | E24: 136051 | F24: LESDELICES1_Location salle de réunion à Manakara du 27-07-26 au 31-07-26_BC 136051 | G24: LES DELICES MANAKARA | I24: 156.25 | J24: USD | K24: 46237 | L24: 30 | M24: 46238 | N24: =IF(OR(M24="", K24=""),"", M24- K24) -> 1 | O24: =IF(OR(M24="", K24="", L24=""), "", IF((M24 - K24) > L24, "No", "Yes")) -> Yes
B25: 21 | C25: Madagascar | D25: 006/TELMA/FMBB/2026 | E25: 135894 | F25: FMBB1_Consommation Internet et Flotte Mois de Juin 2026 _006/TELMA/FMBB/2026_135894 | G25: FEDERATION MALAGASY DE BASKET BALL | I25: 1085.2522 | J25: USD | K25: 46188 | L25: 30 | M25: 46223 | N25: =IF(OR(M25="", K25=""),"", M25- K25) -> 35 | O25: =IF(OR(M25="", K25="", L25=""), "", IF((M25 - K25) > L25, "No", "Yes")) -> No
B26: 22 | C26: Madagascar | D26: sn | E26: 135885 | F26: Paiement Jeton de présence Avantages Asdministrateur YAS Mr Tahiry Trimosoa RABENANAHARY pour l'année 2026 | G26: RABENANAHARY Tahiry Trimosoa | I26: 1250 | J26: USD | K26: 46216 | L26: 30 | M26: 46240 | N26: =IF(OR(M26="", K26=""),"", M26- K26) -> 24 | O26: =IF(OR(M26="", K26="", L26=""), "", IF((M26 - K26) > L26, "No", "Yes")) -> Yes
B27: 23 | C27: Madagascar | D27: 18072025/BC129775/NSB | E27: 129775 | F27: Transport et implantation poteau en bois-Client Nosy BE-9è vague | G27: ASSOMANY ASSANY | I27: 729.16667 | J27: USD | K27: 46180 | L27: 30 | M27: 46215 | N27: =IF(OR(M27="", K27=""),"", M27- K27) -> 35 | O27: =IF(OR(M27="", K27="", L27=""), "", IF((M27 - K27) > L27, "No", "Yes")) -> No
